Workbook

Sheet Start here
B1: DPDP Act 2023 & DPDP Rules 2025 - Readiness Checklist
B2: By John Bommeraveni Joseph | linkedin.com/in/john-bj | Free every weekday: GRC Made Simple Daily
B5: What this is
B6: A working checklist for India's Digital Personal Data Protection Act, 2023 and the Digital Personal Data Protection Rules, 2025 (notified 13 November 2025). Every row cites the section of the Act and/or rule it comes from, says who the duty falls on, and when it comes into force under the phased commencement. Built for privacy, GRC and security teams in India and for companies outside India that serve people in India.
B7: Important
B8: This template is not legal advice. It supports, and does not replace, the official text of the Act and Rules or advice from qualified counsel. Requirement summaries are in our own words; where wording matters, read the Gazette text linked on the Sources tab. Other Indian laws and sector rules (for example CERT-In directions or a sector regulator's requirements) may impose separate obligations and shorter timelines - they are not covered here. Penalty amounts are maximums from the Act's Schedule. Not affiliated with MeitY or the Data Protection Board.
B9: How to use it (about half a day for a first pass)
B10: 1. Applicability Screen: answer the 13 questions. Your answers switch rows on or off in the Checklist ('Applies (from screen)' column).
B11: 2. Timeline: check the date the phased deadlines are counted from. The default is the Gazette date, 13 November 2025. Change it only if your counsel advises a different reading - every 'In force from' date follows it.
B12: 3. Checklist: for each row set Status, record where the evidence lives, name an owner, describe the gap, set a priority and a target date. Mark rows that do not apply 'Not applicable' and say why in the Gap column.
B13: 4. Read the Flags column: it warns about rows your screen says do not apply, duties already in force, target dates later than the date the duty applies, High priority rows with no owner, and 'Done' rows with no evidence.
B14: 5. Dashboard: readiness % by area, open High priority gaps, overdue items and days left to each deadline - the summary for your steering committee or board.
... B21: Version 1.0 - 27 October 2026. Texts checked against the official Gazette PDFs on 27 October 2026. Free to use and share with this credit kept.

Sheet Dashboard
B1: DPDP Readiness Dashboard
B2: By John Bommeraveni Joseph | linkedin.com/in/john-bj | Free every weekday: GRC Made Simple Daily
B5: Headline | C5: Value
B6: Days until Phase 2 (Consent Managers) | C6: =MAX(0,Timeline!$C$9-TODAY()) -> 17
B7: Days until Phase 3 (main obligations) | C7: =MAX(0,Timeline!$C$10-TODAY()) -> 198
B8: Overall readiness (Done / in scope) | C8: =I32 -> 0.01010101
B9: Open High priority gaps | C9: =COUNTIFS(Checklist!$A$6:$A$119,"<>",Checklist!$N$6:$N$119,"High",Checklist!$J$6:$J$119,"<>Done",Checklist!$J$6:$J$119,"<>Not applicable") -> 2
B10: Overdue items | C10: =COUNTIF(Checklist!$P$6:$P$119,"OVERDUE") -> 1
B11: Rows with a target date after the duty applies | C11: =COUNTIF(Checklist!$Q$6:$Q$119,"*Target date is after*") -> 0
B12: Rows marked Done with no evidence location | C12: =COUNTIF(Checklist!$Q$6:$Q$119,"*Done but no evidence*") -> 1
B13: Rows your screen says are not triggered (not yet N/A) | C13: =COUNTIF(Checklist!$Q$6:$Q$119,"*Screen says not triggered*") -> 0
B15: Area | C15: Requirements | D15: Not applicable | E15: In scope | F15: Done | G15: In progress | H15: Not started | I15: Readiness % | J15: Open High gaps | K15: Overdue
B16: Applicability and roles | C16: =COUNTIFS(Checklist!$B$6:$B$119,$B16,Checklist!$A$6:$A$119,"<>")+COUNTIFS(Checklist!$B$6:$B$119,$B16,Checklist!$A$6:$A$119,"",Checklist!$D$6:$D$119,"<>") -> 9 | D16: =COUNTIFS(Checklist!$B$6:$B$119,$B16,Checklist!$J$6:$J$119,"Not applicable") -> 0 | E16: =C16-D16 -> 9 | F16: =COUNTIFS(Checklist!$B$6:$B$119,$B16,Checklist!$J$6:$J$119,"Done") -> 0 | G16: =COUNTIFS(Checklist!$B$6:$B$119,$B16,Checklist!$J$6:$J$119,"In progress") -> 0 | H16: =E16-F16-G16 -> 9 | I16: =IF(E16=0,"",F16/E16) -> 0 | J16: =COUNTIFS(Checklist!$B$6:$B$119,$B16,Checklist!$N$6:$N$119,"High",Checklist!$J$6:$J$119,"<>Done",Checklist!$J$6:$J$119,"<>Not applicable") -> 0 | K16: =COUNTIFS(Checklist!$B$6:$B$119,$B16,Checklist!$P$6:$P$119,"OVERDUE") -> 0
B17: Notice | C17: =COUNTIFS(Checklist!$B$6:$B$119,$B17,Checklist!$A$6:$A$119,"<>")+COUNTIFS(Checklist!$B$6:$B$119,$B17,Checklist!$A$6:$A$119,"",Checklist!$D$6:$D$119,"<>") -> 6 | D17: =COUNTIFS(Checklist!$B$6:$B$119,$B17,Checklist!$J$6:$J$119,"Not applicable") -> 0 | E17: =C17-D17 -> 6 | F17: =COUNTIFS(Checklist!$B$6:$B$119,$B17,Checklist!$J$6:$J$119,"Done") -> 0 | G17: =COUNTIFS(Checklist!$B$6:$B$119,$B17,Checklist!$J$6:$J$119,"In progress") -> 1 | H17: =E17-F17-G17 -> 5 | I17: =IF(E17=0,"",F17/E17) -> 0 | J17: =COUNTIFS(Checklist!$B$6:$B$119,$B17,Checklist!$N$6:$N$119,"High",Checklist!$J$6:$J$119,"<>Done",Checklist!$J$6:$J$119,"<>Not applicable") -> 1 | K17: =COUNTIFS(Checklist!$B$6:$B$119,$B17,Checklist!$P$6:$P$119,"OVERDUE") -> 0
B18: Consent and withdrawal | C18: =COUNTIFS(Checklist!$B$6:$B$119,$B18,Checklist!$A$6:$A$119,"<>")+COUNTIFS(Checklist!$B$6:$B$119,$B18,Checklist!$A$6:$A$119,"",Checklist!$D$6:$D$119,"<>") -> 8 | D18: =COUNTIFS(Checklist!$B$6:$B$119,$B18,Checklist!$J$6:$J$119,"Not applicable") -> 0 | E18: =C18-D18 -> 8 | F18: =COUNTIFS(Checklist!$B$6:$B$119,$B18,Checklist!$J$6:$J$119,"Done") -> 0 | G18: =COUNTIFS(Checklist!$B$6:$B$119,$B18,Checklist!$J$6:$J$119,"In progress") -> 0 | H18: =E18-F18-G18 -> 8 | I18: =IF(E18=0,"",F18/E18) -> 0 | J18: =COUNTIFS(Checklist!$B$6:$B$119,$B18,Checklist!$N$6:$N$119,"High",Checklist!$J$6:$J$119,"<>Done",Checklist!$J$6:$J$119,"<>Not applicable") -> 0 | K18: =COUNTIFS(Checklist!$B$6:$B$119,$B18,Checklist!$P$6:$P$119,"OVERDUE") -> 0
B19: Legitimate uses | C19: =COUNTIFS(Checklist!$B$6:$B$119,$B19,Checklist!$A$6:$A$119,"<>")+COUNTIFS(Checklist!$B$6:$B$119,$B19,Checklist!$A$6:$A$119,"",Checklist!$D$6:$D$119,"<>") -> 5 | D19: =COUNTIFS(Checklist!$B$6:$B$119,$B19,Checklist!$J$6:$J$119,"Not applicable") -> 0 | E19: =C19-D19 -> 5 | F19: =COUNTIFS(Checklist!$B$6:$B$119,$B19,Checklist!$J$6:$J$119,"Done") -> 0 | G19: =COUNTIFS(Checklist!$B$6:$B$119,$B19,Checklist!$J$6:$J$119,"In progress") -> 0 | H19: =E19-F19-G19 -> 5 | I19: =IF(E19=0,"",F19/E19) -> 0 | J19: =COUNTIFS(Checklist!$B$6:$B$119,$B19,Checklist!$N$6:$N$119,"High",Checklist!$J$6:$J$119,"<>Done",Checklist!$J$6:$J$119,"<>Not applicable") -> 0 | K19: =COUNTIFS(Checklist!$B$6:$B$119,$B19,Checklist!$P$6:$P$119,"OVERDUE") -> 0
B20: Governance and data accuracy | C20: =COUNTIFS(Checklist!$B$6:$B$119,$B20,Checklist!$A$6:$A$119,"<>")+COUNTIFS(Checklist!$B$6:$B$119,$B20,Checklist!$A$6:$A$119,"",Checklist!$D$6:$D$119,"<>") -> 4 | D20: =COUNTIFS(Checklist!$B$6:$B$119,$B20,Checklist!$J$6:$J$119,"Not applicable") -> 0 | E20: =C20-D20 -> 4 | F20: =COUNTIFS(Checklist!$B$6:$B$119,$B20,Checklist!$J$6:$J$119,"Done") -> 0 | G20: =COUNTIFS(Checklist!$B$6:$B$119,$B20,Checklist!$J$6:$J$119,"In progress") -> 0 | H20: =E20-F20-G20 -> 4 | I20: =IF(E20=0,"",F20/E20) -> 0 | J20: =COUNTIFS(Checklist!$B$6:$B$119,$B20,Checklist!$N$6:$N$119,"High",Checklist!$J$6:$J$119,"<>Done",Checklist!$J$6:$J$119,"<>Not applicable") -> 0 | K20: =COUNTIFS(Checklist!$B$6:$B$119,$B20,Checklist!$P$6:$P$119,"OVERDUE") -> 0
B21: Security safeguards | C21: =COUNTIFS(Checklist!$B$6:$B$119,$B21,Checklist!$A$6:$A$119,"<>")+COUNTIFS(Checklist!$B$6:$B$119,$B21,Checklist!$A$6:$A$119,"",Checklist!$D$6:$D$119,"<>") -> 7 | D21: =COUNTIFS(Checklist!$B$6:$B$119,$B21,Checklist!$J$6:$J$119,"Not applicable") -> 0 | E21: =C21-D21 -> 7 | F21: =COUNTIFS(Checklist!$B$6:$B$119,$B21,Checklist!$J$6:$J$119,"Done") -> 0 | G21: =COUNTIFS(Checklist!$B$6:$B$119,$B21,Checklist!$J$6:$J$119,"In progress") -> 0 | H21: =E21-F21-G21 -> 7 | I21: =IF(E21=0,"",F21/E21) -> 0 | J21: =COUNTIFS(Checklist!$B$6:$B$119,$B21,Checklist!$N$6:$N$119,"High",Checklist!$J$6:$J$119,"<>Done",Checklist!$J$6:$J$119,"<>Not applicable") -> 0 | K21: =COUNTIFS(Checklist!$B$6:$B$119,$B21,Checklist!$P$6:$P$119,"OVERDUE") -> 0
B22: Breach intimation | C22: =COUNTIFS(Checklist!$B$6:$B$119,$B22,Checklist!$A$6:$A$119,"<>")+COUNTIFS(Checklist!$B$6:$B$119,$B22,Checklist!$A$6:$A$119,"",Checklist!$D$6:$D$119,"<>") -> 6 | D22: =COUNTIFS(Checklist!$B$6:$B$119,$B22,Checklist!$J$6:$J$119,"Not applicable") -> 0 | E22: =C22-D22 -> 6 | F22: =COUNTIFS(Checklist!$B$6:$B$119,$B22,Checklist!$J$6:$J$119,"Done") -> 0 | G22: =COUNTIFS(Checklist!$B$6:$B$119,$B22,Checklist!$J$6:$J$119,"In progress") -> 0 | H22: =E22-F22-G22 -> 6 | I22: =IF(E22=0,"",F22/E22) -> 0 | J22: =COUNTIFS(Checklist!$B$6:$B$119,$B22,Checklist!$N$6:$N$119,"High",Checklist!$J$6:$J$119,"<>Done",Checklist!$J$6:$J$119,"<>Not applicable") -> 1 | K22: =COUNTIFS(Checklist!$B$6:$B$119,$B22,Checklist!$P$6:$P$119,"OVERDUE") -> 1
B23: Retention and erasure | C23: =COUNTIFS(Checklist!$B$6:$B$119,$B23,Checklist!$A$6:$A$119,"<>")+COUNTIFS(Checklist!$B$6:$B$119,$B23,Checklist!$A$6:$A$119,"",Checklist!$D$6:$D$119,"<>") -> 6 | D23: =COUNTIFS(Checklist!$B$6:$B$119,$B23,Checklist!$J$6:$J$119,"Not applicable") -> 0 | E23: =C23-D23 -> 6 | F23: =COUNTIFS(Checklist!$B$6:$B$119,$B23,Checklist!$J$6:$J$119,"Done") -> 0 | G23: =COUNTIFS(Checklist!$B$6:$B$119,$B23,Checklist!$J$6:$J$119,"In progress") -> 0 | H23: =E23-F23-G23 -> 6 | I23: =IF(E23=0,"",F23/E23) -> 0 | J23: =COUNTIFS(Checklist!$B$6:$B$119,$B23,Checklist!$N$6:$N$119,"High",Checklist!$J$6:$J$119,"<>Done",Checklist!$J$6:$J$119,"<>Not applicable") -> 0 | K23: =COUNTIFS(Checklist!$B$6:$B$119,$B23,Checklist!$P$6:$P$119,"OVERDUE") -> 0
B24: Contact and grievance | C24: =COUNTIFS(Checklist!$B$6:$B$119,$B24,Checklist!$A$6:$A$119,"<>")+COUNTIFS(Checklist!$B$6:$B$119,$B24,Checklist!$A$6:$A$119,"",Checklist!$D$6:$D$119,"<>") -> 5 | D24: =COUNTIFS(Checklist!$B$6:$B$119,$B24,Checklist!$J$6:$J$119,"Not applicable") -> 0 | E24: =C24-D24 -> 5 | F24: =COUNTIFS(Checklist!$B$6:$B$119,$B24,Checklist!$J$6:$J$119,"Done") -> 1 | G24: =COUNTIFS(Checklist!$B$6:$B$119,$B24,Checklist!$J$6:$J$119,"In progress") -> 0 | H24: =E24-F24-G24 -> 4 | I24: =IF(E24=0,"",F24/E24) -> 0.2 | J24: =COUNTIFS(Checklist!$B$6:$B$119,$B24,Checklist!$N$6:$N$119,"High",Checklist!$J$6:$J$119,"<>Done",Checklist!$J$6:$J$119,"<>Not applicable") -> 0 | K24: =COUNTIFS(Checklist!$B$6:$B$119,$B24,Checklist!$P$6:$P$119,"OVERDUE") -> 0
B25: Data Processors and contracts | C25: =COUNTIFS(Checklist!$B$6:$B$119,$B25,Checklist!$A$6:$A$119,"<>")+COUNTIFS(Checklist!$B$6:$B$119,$B25,Checklist!$A$6:$A$119,"",Checklist!$D$6:$D$119,"<>") -> 6 | D25: =COUNTIFS(Checklist!$B$6:$B$119,$B25,Checklist!$J$6:$J$119,"Not applicable") -> 0 | E25: =C25-D25 -> 6 | F25: =COUNTIFS(Checklist!$B$6:$B$119,$B25,Checklist!$J$6:$J$119,"Done") -> 0 | G25: =COUNTIFS(Checklist!$B$6:$B$119,$B25,Checklist!$J$6:$J$119,"In progress") -> 0 | H25: =E25-F25-G25 -> 6 | I25: =IF(E25=0,"",F25/E25) -> 0 | J25: =COUNTIFS(Checklist!$B$6:$B$119,$B25,Checklist!$N$6:$N$119,"High",Checklist!$J$6:$J$119,"<>Done",Checklist!$J$6:$J$119,"<>Not applicable") -> 0 | K25: =COUNTIFS(Checklist!$B$6:$B$119,$B25,Checklist!$P$6:$P$119,"OVERDUE") -> 0
B26: Children and persons with disability | C26: =COUNTIFS(Checklist!$B$6:$B$119,$B26,Checklist!$A$6:$A$119,"<>")+COUNTIFS(Checklist!$B$6:$B$119,$B26,Checklist!$A$6:$A$119,"",Checklist!$D$6:$D$119,"<>") -> 7 | D26: =COUNTIFS(Checklist!$B$6:$B$119,$B26,Checklist!$J$6:$J$119,"Not applicable") -> 0 | E26: =C26-D26 -> 7 | F26: =COUNTIFS(Checklist!$B$6:$B$119,$B26,Checklist!$J$6:$J$119,"Done") -> 0 | G26: =COUNTIFS(Checklist!$B$6:$B$119,$B26,Checklist!$J$6:$J$119,"In progress") -> 0 | H26: =E26-F26-G26 -> 7 | I26: =IF(E26=0,"",F26/E26) -> 0 | J26: =COUNTIFS(Checklist!$B$6:$B$119,$B26,Checklist!$N$6:$N$119,"High",Checklist!$J$6:$J$119,"<>Done",Checklist!$J$6:$J$119,"<>Not applicable") -> 0 | K26: =COUNTIFS(Checklist!$B$6:$B$119,$B26,Checklist!$P$6:$P$119,"OVERDUE") -> 0
B27: Significant Data Fiduciary | C27: =COUNTIFS(Checklist!$B$6:$B$119,$B27,Checklist!$A$6:$A$119,"<>")+COUNTIFS(Checklist!$B$6:$B$119,$B27,Checklist!$A$6:$A$119,"",Checklist!$D$6:$D$119,"<>") -> 7 | D27: =COUNTIFS(Checklist!$B$6:$B$119,$B27,Checklist!$J$6:$J$119,"Not applicable") -> 0 | E27: =C27-D27 -> 7 | F27: =COUNTIFS(Checklist!$B$6:$B$119,$B27,Checklist!$J$6:$J$119,"Done") -> 0 | G27: =COUNTIFS(Checklist!$B$6:$B$119,$B27,Checklist!$J$6:$J$119,"In progress") -> 0 | H27: =E27-F27-G27 -> 7 | I27: =IF(E27=0,"",F27/E27) -> 0 | J27: =COUNTIFS(Checklist!$B$6:$B$119,$B27,Checklist!$N$6:$N$119,"High",Checklist!$J$6:$J$119,"<>Done",Checklist!$J$6:$J$119,"<>Not applicable") -> 0 | K27: =COUNTIFS(Checklist!$B$6:$B$119,$B27,Checklist!$P$6:$P$119,"OVERDUE") -> 0
... B31: Records and information requests | C31: =COUNTIFS(Checklist!$B$6:$B$119,$B31,Checklist!$A$6:$A$119,"<>")+COUNTIFS(Checklist!$B$6:$B$119,$B31,Checklist!$A$6:$A$119,"",Checklist!$D$6:$D$119,"<>") -> 3 | D31: =COUNTIFS(Checklist!$B$6:$B$119,$B31,Checklist!$J$6:$J$119,"Not applicable") -> 0 | E31: =C31-D31 -> 3 | F31: =COUNTIFS(Checklist!$B$6:$B$119,$B31,Checklist!$J$6:$J$119,"Done") -> 0 | G31: =COUNTIFS(Checklist!$B$6:$B$119,$B31,Checklist!$J$6:$J$119,"In progress") -> 0 | H31: =E31-F31-G31 -> 3 | I31: =IF(E31=0,"",F31/E31) -> 0 | J31: =COUNTIFS(Checklist!$B$6:$B$119,$B31,Checklist!$N$6:$N$119,"High",Checklist!$J$6:$J$119,"<>Done",Checklist!$J$6:$J$119,"<>Not applicable") -> 0 | K31: =COUNTIFS(Checklist!$B$6:$B$119,$B31,Checklist!$P$6:$P$119,"OVERDUE") -> 0
B32: Total | C32: =SUM(C16:C31) -> 99 | D32: =SUM(D16:D31) -> 0 | E32: =SUM(E16:E31) -> 99 | F32: =SUM(F16:F31) -> 1 | G32: =SUM(G16:G31) -> 1 | H32: =SUM(H16:H31) -> 97 | I32: =IF(E32=0,"",F32/E32) -> 0.01010101 | J32: =SUM(J16:J31) -> 2 | K32: =SUM(K16:K31) -> 1
B34: First 10 open High priority gaps (in Checklist order)
B35: # | C35: ID | D35: Area | F35: Owner | H35: Target date | J35: Overdue?
B36: 1 | C36: =IFERROR(INDEX(Checklist!$A$6:$A$119,MATCH(1,Checklist!$R$6:$R$119,0)),"") -> NOT-01 | D36: =IFERROR(INDEX(Checklist!$B$6:$B$119,MATCH(1,Checklist!$R$6:$R$119,0)),"") -> Notice | F36: =IFERROR(IF(INDEX(Checklist!$L$6:$L$119,MATCH(1,Checklist!$R$6:$R$119,0))="","(no owner)",INDEX(Checklist!$L$6:$L$119,MATCH(1,Checklist!$R$6:$R$119,0))),"") -> Head of Privacy | H36: =IFERROR(IF(INDEX(Checklist!$O$6:$O$119,MATCH(1,Checklist!$R$6:$R$119,0))="","",INDEX(Checklist!$O$6:$O$119,MATCH(1,Checklist!$R$6:$R$119,0))),"") -> 46418 | J36: =IFERROR(INDEX(Checklist!$P$6:$P$119,MATCH(1,Checklist!$R$6:$R$119,0)),"")
B37: 2 | C37: =IFERROR(INDEX(Checklist!$A$6:$A$119,MATCH(2,Checklist!$R$6:$R$119,0)),"") -> BRE-05 | D37: =IFERROR(INDEX(Checklist!$B$6:$B$119,MATCH(2,Checklist!$R$6:$R$119,0)),"") -> Breach intimation | F37: =IFERROR(IF(INDEX(Checklist!$L$6:$L$119,MATCH(2,Checklist!$R$6:$R$119,0))="","(no owner)",INDEX(Checklist!$L$6:$L$119,MATCH(2,Checklist!$R$6:$R$119,0))),"") -> (no owner) | H37: =IFERROR(IF(INDEX(Checklist!$O$6:$O$119,MATCH(2,Checklist!$R$6:$R$119,0))="","",INDEX(Checklist!$O$6:$O$119,MATCH(2,Checklist!$R$6:$R$119,0))),"") -> 46295 | J37: =IFERROR(INDEX(Checklist!$P$6:$P$119,MATCH(2,Checklist!$R$6:$R$119,0)),"") -> OVERDUE
B38: 3 | C38: =IFERROR(INDEX(Checklist!$A$6:$A$119,MATCH(3,Checklist!$R$6:$R$119,0)),"") | D38: =IFERROR(INDEX(Checklist!$B$6:$B$119,MATCH(3,Checklist!$R$6:$R$119,0)),"") | F38: =IFERROR(IF(INDEX(Checklist!$L$6:$L$119,MATCH(3,Checklist!$R$6:$R$119,0))="","(no owner)",INDEX(Checklist!$L$6:$L$119,MATCH(3,Checklist!$R$6:$R$119,0))),"") | H38: =IFERROR(IF(INDEX(Checklist!$O$6:$O$119,MATCH(3,Checklist!$R$6:$R$119,0))="","",INDEX(Checklist!$O$6:$O$119,MATCH(3,Checklist!$R$6:$R$119,0))),"") | J38: =IFERROR(INDEX(Checklist!$P$6:$P$119,MATCH(3,Checklist!$R$6:$R$119,0)),"")
B39: 4 | C39: =IFERROR(INDEX(Checklist!$A$6:$A$119,MATCH(4,Checklist!$R$6:$R$119,0)),"") | D39: =IFERROR(INDEX(Checklist!$B$6:$B$119,MATCH(4,Checklist!$R$6:$R$119,0)),"") | F39: =IFERROR(IF(INDEX(Checklist!$L$6:$L$119,MATCH(4,Checklist!$R$6:$R$119,0))="","(no owner)",INDEX(Checklist!$L$6:$L$119,MATCH(4,Checklist!$R$6:$R$119,0))),"") | H39: =IFERROR(IF(INDEX(Checklist!$O$6:$O$119,MATCH(4,Checklist!$R$6:$R$119,0))="","",INDEX(Checklist!$O$6:$O$119,MATCH(4,Checklist!$R$6:$R$119,0))),"") | J39: =IFERROR(INDEX(Checklist!$P$6:$P$119,MATCH(4,Checklist!$R$6:$R$119,0)),"")
B40: 5 | C40: =IFERROR(INDEX(Checklist!$A$6:$A$119,MATCH(5,Checklist!$R$6:$R$119,0)),"") | D40: =IFERROR(INDEX(Checklist!$B$6:$B$119,MATCH(5,Checklist!$R$6:$R$119,0)),"") | F40: =IFERROR(IF(INDEX(Checklist!$L$6:$L$119,MATCH(5,Checklist!$R$6:$R$119,0))="","(no owner)",INDEX(Checklist!$L$6:$L$119,MATCH(5,Checklist!$R$6:$R$119,0))),"") | H40: =IFERROR(IF(INDEX(Checklist!$O$6:$O$119,MATCH(5,Checklist!$R$6:$R$119,0))="","",INDEX(Checklist!$O$6:$O$119,MATCH(5,Checklist!$R$6:$R$119,0))),"") | J40: =IFERROR(INDEX(Checklist!$P$6:$P$119,MATCH(5,Checklist!$R$6:$R$119,0)),"")
B41: 6 | C41: =IFERROR(INDEX(Checklist!$A$6:$A$119,MATCH(6,Checklist!$R$6:$R$119,0)),"") | D41: =IFERROR(INDEX(Checklist!$B$6:$B$119,MATCH(6,Checklist!$R$6:$R$119,0)),"") | F41: =IFERROR(IF(INDEX(Checklist!$L$6:$L$119,MATCH(6,Checklist!$R$6:$R$119,0))="","(no owner)",INDEX(Checklist!$L$6:$L$119,MATCH(6,Checklist!$R$6:$R$119,0))),"") | H41: =IFERROR(IF(INDEX(Checklist!$O$6:$O$119,MATCH(6,Checklist!$R$6:$R$119,0))="","",INDEX(Checklist!$O$6:$O$119,MATCH(6,Checklist!$R$6:$R$119,0))),"") | J41: =IFERROR(INDEX(Checklist!$P$6:$P$119,MATCH(6,Checklist!$R$6:$R$119,0)),"")
B42: 7 | C42: =IFERROR(INDEX(Checklist!$A$6:$A$119,MATCH(7,Checklist!$R$6:$R$119,0)),"") | D42: =IFERROR(INDEX(Checklist!$B$6:$B$119,MATCH(7,Checklist!$R$6:$R$119,0)),"") | F42: =IFERROR(IF(INDEX(Checklist!$L$6:$L$119,MATCH(7,Checklist!$R$6:$R$119,0))="","(no owner)",INDEX(Checklist!$L$6:$L$119,MATCH(7,Checklist!$R$6:$R$119,0))),"") | H42: =IFERROR(IF(INDEX(Checklist!$O$6:$O$119,MATCH(7,Checklist!$R$6:$R$119,0))="","",INDEX(Checklist!$O$6:$O$119,MATCH(7,Checklist!$R$6:$R$119,0))),"") | J42: =IFERROR(INDEX(Checklist!$P$6:$P$119,MATCH(7,Checklist!$R$6:$R$119,0)),"")
B43: 8 | C43: =IFERROR(INDEX(Checklist!$A$6:$A$119,MATCH(8,Checklist!$R$6:$R$119,0)),"") | D43: =IFERROR(INDEX(Checklist!$B$6:$B$119,MATCH(8,Checklist!$R$6:$R$119,0)),"") | F43: =IFERROR(IF(INDEX(Checklist!$L$6:$L$119,MATCH(8,Checklist!$R$6:$R$119,0))="","(no owner)",INDEX(Checklist!$L$6:$L$119,MATCH(8,Checklist!$R$6:$R$119,0))),"") | H43: =IFERROR(IF(INDEX(Checklist!$O$6:$O$119,MATCH(8,Checklist!$R$6:$R$119,0))="","",INDEX(Checklist!$O$6:$O$119,MATCH(8,Checklist!$R$6:$R$119,0))),"") | J43: =IFERROR(INDEX(Checklist!$P$6:$P$119,MATCH(8,Checklist!$R$6:$R$119,0)),"")
B44: 9 | C44: =IFERROR(INDEX(Checklist!$A$6:$A$119,MATCH(9,Checklist!$R$6:$R$119,0)),"") | D44: =IFERROR(INDEX(Checklist!$B$6:$B$119,MATCH(9,Checklist!$R$6:$R$119,0)),"") | F44: =IFERROR(IF(INDEX(Checklist!$L$6:$L$119,MATCH(9,Checklist!$R$6:$R$119,0))="","(no owner)",INDEX(Checklist!$L$6:$L$119,MATCH(9,Checklist!$R$6:$R$119,0))),"") | H44: =IFERROR(IF(INDEX(Checklist!$O$6:$O$119,MATCH(9,Checklist!$R$6:$R$119,0))="","",INDEX(Checklist!$O$6:$O$119,MATCH(9,Checklist!$R$6:$R$119,0))),"") | J44: =IFERROR(INDEX(Checklist!$P$6:$P$119,MATCH(9,Checklist!$R$6:$R$119,0)),"")
B45: 10 | C45: =IFERROR(INDEX(Checklist!$A$6:$A$119,MATCH(10,Checklist!$R$6:$R$119,0)),"") | D45: =IFERROR(INDEX(Checklist!$B$6:$B$119,MATCH(10,Checklist!$R$6:$R$119,0)),"") | F45: =IFERROR(IF(INDEX(Checklist!$L$6:$L$119,MATCH(10,Checklist!$R$6:$R$119,0))="","(no owner)",INDEX(Checklist!$L$6:$L$119,MATCH(10,Checklist!$R$6:$R$119,0))),"") | H45: =IFERROR(IF(INDEX(Checklist!$O$6:$O$119,MATCH(10,Checklist!$R$6:$R$119,0))="","",INDEX(Checklist!$O$6:$O$119,MATCH(10,Checklist!$R$6:$R$119,0))),"") | J45: =IFERROR(INDEX(Checklist!$P$6:$P$119,MATCH(10,Checklist!$R$6:$R$119,0)),"")
B47: Red = needs action. Readiness % = Done / (requirements - Not applicable); blank status counts as Not started. The worked examples on NOT-01, BRE-05 and CGR-01 are counted until you clear them.

Sheet Applicability Screen
B1: Applicability Screen
B2: By John Bommeraveni Joseph | linkedin.com/in/john-bj | Free every weekday: GRC Made Simple Daily
C5: Overall result | F5: =IF(COUNTA(E8:E20)<13,"Answer all 13 questions",IF(E10="Yes","Likely excluded under s.3(c)(i) - record your reasoning",IF(OR(E8<>"No",E9<>"No"),"In scope - work through the Checklist","Likely out of scope - record your reasoning and re-check yearly"))) -> Answer all 13 questions
B7: No. | C7: Question | D7: Reference | E7: Your answer | F7: What it means | G7: Key
B8: 1 | C8: Do you process personal data in digital form in India - collected digitally, or collected on paper and digitised later? | D8: s.3(a) | F8: =IF(E8="","Answer this question",IF(E8="Yes","In scope under s.3(a).",IF(E8="No","Not in scope through s.3(a) - check the next question.","Not sure - treat as Yes until confirmed."))) -> Answer this question | G8: IN_INDIA
B9: 2 | C9: Do you process digital personal data outside India in connection with offering goods or services to people in India? | D9: s.3(b) | F9: =IF(E9="","Answer this question",IF(E9="Yes","In scope under s.3(b), even though processing happens outside India.",IF(E9="No","Not in scope through s.3(b).","Not sure - treat as Yes until confirmed."))) -> Answer this question | G9: OUTSIDE
B10: 3 | C10: Is ALL of your processing done by an individual for purely personal or domestic purposes? | D10: s.3(c)(i) | F10: =IF(E10="","Answer this question",IF(E10="Yes","Likely excluded - record your reasoning.",IF(E10="No","The personal / domestic exclusion does not help you.","Not sure - treat as Yes until confirmed."))) -> Answer this question | G10: DOMESTIC
B11: 4 | C11: Do you decide, alone or with others, why and how personal data is processed (Data Fiduciary)? | D11: s.2(i) | F11: =IF(E11="","Answer this question",IF(E11="Yes","You are a Data Fiduciary - most rows apply to you.",IF(E11="No","Rows marked DF will show as not triggered - confirm before marking N/A.","Not sure - treat as Yes until confirmed."))) -> Answer this question | G11: DF
B12: 5 | C12: Do you process personal data on behalf of another organisation (Data Processor)? | D12: s.2(k), s.8(2) | F12: =IF(E12="","Answer this question",IF(E12="Yes","Expect your customers to pass DPDP duties to you by contract.",IF(E12="No","Processor-only rows not triggered.","Not sure - treat as Yes until confirmed."))) -> Answer this question | G12: PROC
B13: 6 | C13: Has the Central Government notified you, or a class you belong to, as a Significant Data Fiduciary? | D13: s.10(1) | F13: =IF(E13="","Answer this question",IF(E13="Yes","Significant Data Fiduciary rows apply.",IF(E13="No","SDF rows not triggered - keep watching the Gazette.","Not sure - treat as Yes until confirmed."))) -> Answer this question | G13: SDF
B14: 7 | C14: Do you process personal data of children (individuals under 18)? | D14: s.2(f), s.9 | F14: =IF(E14="","Answer this question",IF(E14="Yes","Children rows apply.",IF(E14="No","Children rows not triggered - check how you know users are adults.","Not sure - treat as Yes until confirmed."))) -> Answer this question | G14: CHILD
B15: 8 | C15: Do you process personal data of persons with disability who have a lawful guardian? | D15: s.9(1), r.11 | F15: =IF(E15="","Answer this question",IF(E15="Yes","Lawful-guardian consent rows apply.",IF(E15="No","Guardian row not triggered.","Not sure - treat as Yes until confirmed."))) -> Answer this question | G15: PWD
B16: 9 | C16: Are you an e-commerce entity with 2 crore+ registered users in India, an online gaming intermediary with 50 lakh+, or a social media intermediary with 2 crore+? | D16: r.8(1), Third Schedule | F16: =IF(E16="","Answer this question",IF(E16="Yes","Fixed three-year inactivity erasure and 48-hour warning apply.",IF(E16="No","Third Schedule erasure rows not triggered.","Not sure - treat as Yes until confirmed."))) -> Answer this question | G16: THIRD
B17: 10 | C17: Do you transfer personal data outside India, including cloud hosting, offshore support or vendor access? | D17: s.16, r.15 | F17: =IF(E17="","Answer this question",IF(E17="Yes","Cross-border rows apply.",IF(E17="No","Cross-border rows not triggered - check vendor and cloud regions first.","Not sure - treat as Yes until confirmed."))) -> Answer this question | G17: XB
B18: 11 | C18: Do you operate, or plan to operate, as a Consent Manager registered with the Board? | D18: s.6(9), r.4 | F18: =IF(E18="","Answer this question",IF(E18="Yes","Consent Manager rows apply (in force earlier than most rows).",IF(E18="No","Consent Manager rows not triggered.","Not sure - treat as Yes until confirmed."))) -> Answer this question | G18: CM
B19: 12 | C19: Do you rely on an exemption under s.17 or a Government notification under s.17(3) or s.17(5)? | D19: s.17 | F19: =IF(E19="","Answer this question",IF(E19="Yes","Document the exemption, its scope and evidence.",IF(E19="No","No exemption relied on.","Not sure - treat as Yes until confirmed."))) -> Answer this question | G19: EXEMPT
B20: 13 | C20: Are you the State or an instrumentality of the State processing for subsidies, benefits, services, certificates, licences or permits? | D20: s.7(b), r.5 | F20: =IF(E20="","Answer this question",IF(E20="Yes","State legitimate-use row applies.",IF(E20="No","State row not triggered.","Not sure - treat as Yes until confirmed."))) -> Answer this question | G20: STATE
C22: 'Not sure' counts as Yes for scope. The Key column links each answer to Checklist rows.

Sheet Checklist
B1: DPDP Readiness Checklist
B2: By John Bommeraveni Joseph | linkedin.com/in/john-bj | Free every weekday: GRC Made Simple Daily
A5: ID | B5: Area | C5: Reference (Act s. / Rule r.) | D5: Requirement (our summary - read the official text) | E5: Applies to | F5: Phase | G5: In force from | H5: Screen key | I5: Applies (from screen) | J5: Status | K5: Evidence location | L5: Owner | M5: Gap / notes | N5: Priority | O5: Target date | P5: Overdue? | Q5: Flags | R5: Open High #
A6: APP-01 | B6: Applicability and roles | C6: s.3(a), s.3(b) | D6: Confirm and record whether the Act applies to you: digital personal data processed in India (collected digitally, or collected in non-digital form and digitised later), or processed outside India in connection with offering goods or services to Data Principals in India. | E6: Any person processing digital personal data | F6: 3 | G6: =IF(F6="","",INDEX(Timeline!$C$8:$C$10,F6)) -> 46520 | H6: ALL | I6: =IF(H6="","",IF(H6="ALL","Yes",IF(IFERROR(INDEX('Applicability Screen'!$E$8:$E$20,MATCH(H6,'Applicability Screen'!$G$8:$G$20,0)),"")="","Answer screen",INDEX('Applicability Screen'!$E$8:$E$20,MATCH(H6,'Applicability Screen'!$G$8:$G$20,0))))) -> Yes | P6: =IF(OR(O6="",J6="Done",J6="Not applicable"),"",IF(O6<TODAY(),"OVERDUE","")) | Q6: =IF(AND(A6="",D6=""),"",IF(AND(I6="No",J6<>"Not applicable"),"Screen says not triggered - confirm or mark Not applicable. ","")&IF(AND(G6<>"",J6<>"Done",J6<>"Not applicable",G6<=TODAY()),"Duty already in force. ","")&IF(AND(O6<>"",G6<>"",J6<>"Done",J6<>"Not applicable",O6>G6),"Target date is after the duty applies. ","")&IF(AND(N6="High",L6="",J6<>"Done",J6<>"Not applicable"),"High priority with no owner. ","")&IF(AND(J6="Done",K6=""),"Done but no evidence location. ","")&IF(AND(J6="Not applicable",M6=""),"Say why it is not applicable. ","")) | R6: =IF(AND(A6<>"",N6="High",J6<>"Done",J6<>"Not applicable"),COUNTIFS($A$6:A6,"<>",$N$6:N6,"High",$J$6:J6,"<>Done",$J$6:J6,"<>Not applicable"),"")
A7: APP-02 | B7: Applicability and roles | C7: s.3(c) | D7: If you rely on an exclusion, record which and keep the evidence: processing by an individual for a personal or domestic purpose; or personal data made publicly available by the Data Principal herself, or by a person obliged under Indian law to publish it. | E7: Any person processing digital personal data | F7: 3 | G7: =IF(F7="","",INDEX(Timeline!$C$8:$C$10,F7)) -> 46520 | H7: ALL | I7: =IF(H7="","",IF(H7="ALL","Yes",IF(IFERROR(INDEX('Applicability Screen'!$E$8:$E$20,MATCH(H7,'Applicability Screen'!$G$8:$G$20,0)),"")="","Answer screen",INDEX('Applicability Screen'!$E$8:$E$20,MATCH(H7,'Applicability Screen'!$G$8:$G$20,0))))) -> Yes | P7: =IF(OR(O7="",J7="Done",J7="Not applicable"),"",IF(O7<TODAY(),"OVERDUE","")) | Q7: =IF(AND(A7="",D7=""),"",IF(AND(I7="No",J7<>"Not applicable"),"Screen says not triggered - confirm or mark Not applicable. ","")&IF(AND(G7<>"",J7<>"Done",J7<>"Not applicable",G7<=TODAY()),"Duty already in force. ","")&IF(AND(O7<>"",G7<>"",J7<>"Done",J7<>"Not applicable",O7>G7),"Target date is after the duty applies. ","")&IF(AND(N7="High",L7="",J7<>"Done",J7<>"Not applicable"),"High priority with no owner. ","")&IF(AND(J7="Done",K7=""),"Done but no evidence location. ","")&IF(AND(J7="Not applicable",M7=""),"Say why it is not applicable. ","")) | R7: =IF(AND(A7<>"",N7="High",J7<>"Done",J7<>"Not applicable"),COUNTIFS($A$6:A7,"<>",$N$6:N7,"High",$J$6:J7,"<>Done",$J$6:J7,"<>Not applicable"),"")
A8: APP-03 | B8: Applicability and roles | C8: s.2(i), s.2(k) | D8: For each processing activity, record your role: Data Fiduciary (you alone or with others decide the purpose and means) or Data Processor (you process on behalf of a Data Fiduciary). | E8: Any person processing digital personal data | F8: 1 | G8: =IF(F8="","",INDEX(Timeline!$C$8:$C$10,F8)) -> 45974 | H8: ALL | I8: =IF(H8="","",IF(H8="ALL","Yes",IF(IFERROR(INDEX('Applicability Screen'!$E$8:$E$20,MATCH(H8,'Applicability Screen'!$G$8:$G$20,0)),"")="","Answer screen",INDEX('Applicability Screen'!$E$8:$E$20,MATCH(H8,'Applicability Screen'!$G$8:$G$20,0))))) -> Yes | P8: =IF(OR(O8="",J8="Done",J8="Not applicable"),"",IF(O8<TODAY(),"OVERDUE","")) | Q8: =IF(AND(A8="",D8=""),"",IF(AND(I8="No",J8<>"Not applicable"),"Screen says not triggered - confirm or mark Not applicable. ","")&IF(AND(G8<>"",J8<>"Done",J8<>"Not applicable",G8<=TODAY()),"Duty already in force. ","")&IF(AND(O8<>"",G8<>"",J8<>"Done",J8<>"Not applicable",O8>G8),"Target date is after the duty applies. ","")&IF(AND(N8="High",L8="",J8<>"Done",J8<>"Not applicable"),"High priority with no owner. ","")&IF(AND(J8="Done",K8=""),"Done but no evidence location. ","")&IF(AND(J8="Not applicable",M8=""),"Say why it is not applicable. ","")) -> Duty already in force. | R8: =IF(AND(A8<>"",N8="High",J8<>"Done",J8<>"Not applicable"),COUNTIFS($A$6:A8,"<>",$N$6:N8,"High",$J$6:J8,"<>Done",$J$6:J8,"<>Not applicable"),"")
A9: APP-04 | B9: Applicability and roles | C9: s.4(1), s.4(2) | D9: For each processing activity, record the ground relied on - consent, or one of the 'certain legitimate uses' in s.7 - and confirm the purpose is lawful (not expressly forbidden by law). | E9: Data Fiduciary | F9: 3 | G9: =IF(F9="","",INDEX(Timeline!$C$8:$C$10,F9)) -> 46520 | H9: DF | I9: =IF(H9="","",IF(H9="ALL","Yes",IF(IFERROR(INDEX('Applicability Screen'!$E$8:$E$20,MATCH(H9,'Applicability Screen'!$G$8:$G$20,0)),"")="","Answer screen",INDEX('Applicability Screen'!$E$8:$E$20,MATCH(H9,'Applicability Screen'!$G$8:$G$20,0))))) -> Answer screen | P9: =IF(OR(O9="",J9="Done",J9="Not applicable"),"",IF(O9<TODAY(),"OVERDUE","")) | Q9: =IF(AND(A9="",D9=""),"",IF(AND(I9="No",J9<>"Not applicable"),"Screen says not triggered - confirm or mark Not applicable. ","")&IF(AND(G9<>"",J9<>"Done",J9<>"Not applicable",G9<=TODAY()),"Duty already in force. ","")&IF(AND(O9<>"",G9<>"",J9<>"Done",J9<>"Not applicable",O9>G9),"Target date is after the duty applies. ","")&IF(AND(N9="High",L9="",J9<>"Done",J9<>"Not applicable"),"High priority with no owner. ","")&IF(AND(J9="Done",K9=""),"Done but no evidence location. ","")&IF(AND(J9="Not applicable",M9=""),"Say why it is not applicable. ","")) | R9: =IF(AND(A9<>"",N9="High",J9<>"Done",J9<>"Not applicable"),COUNTIFS($A$6:A9,"<>",$N$6:N9,"High",$J$6:J9,"<>Done",$J$6:J9,"<>Not applicable"),"")
A10: APP-05 | B10: Applicability and roles | C10: s.17(1) | D10: If you rely on a s.17(1) exemption (enforcing a legal right or claim; judicial, quasi-judicial, regulatory or supervisory bodies; offences and contraventions; personal data of people outside India processed under a contract with a person outside India; court-approved mergers, demergers and similar schemes; financial information of a loan defaulter), document which one and why. Chapter II except s.8(1) and s.8(5), Chapter III and s.16 do not apply to that processing - accountability and security safeguards still do. | E10: Data Fiduciary | F10: 3 | G10: =IF(F10="","",INDEX(Timeline!$C$8:$C$10,F10)) -> 46520 | H10: EXEMPT | I10: =IF(H10="","",IF(H10="ALL","Yes",IF(IFERROR(INDEX('Applicability Screen'!$E$8:$E$20,MATCH(H10,'Applicability Screen'!$G$8:$G$20,0)),"")="","Answer screen",INDEX('Applicability Screen'!$E$8:$E$20,MATCH(H10,'Applicability Screen'!$G$8:$G$20,0))))) -> Answer screen | P10: =IF(OR(O10="",J10="Done",J10="Not applicable"),"",IF(O10<TODAY(),"OVERDUE","")) | Q10: =IF(AND(A10="",D10=""),"",IF(AND(I10="No",J10<>"Not applicable"),"Screen says not triggered - confirm or mark Not applicable. ","")&IF(AND(G10<>"",J10<>"Done",J10<>"Not applicable",G10<=TODAY()),"Duty already in force. ","")&IF(AND(O10<>"",G10<>"",J10<>"Done",J10<>"Not applicable",O10>G10),"Target date is after the duty applies. ","")&IF(AND(N10="High",L10="",J10<>"Done",J10<>"Not applicable"),"High priority with no owner. ","")&IF(AND(J10="Done",K10=""),"Done but no evidence location. ","")&IF(AND(J10="Not applicable",M10=""),"Say why it is not applicable. ","")) | R10: =IF(AND(A10<>"",N10="High",J10<>"Done",J10<>"Not applicable"),COUNTIFS($A$6:A10,"<>",$N$6:N10,"High",$J$6:J10,"<>Done",$J$6:J10,"<>Not applicable"),"")
A11: APP-06 | B11: Applicability and roles | C11: s.17(2)(b), r.16, Second Schedule | D11: Processing necessary for research, archiving or statistical purposes falls outside the Act only if the data is not used to take a decision specific to a Data Principal and the processing follows the Second Schedule standards (lawful; limited to the purpose and to necessary data; reasonable efforts on accuracy; retention limited; reasonable security safeguards; accountability). Document conformance if you rely on it. | E11: Data Fiduciary | F11: 3 | G11: =IF(F11="","",INDEX(Timeline!$C$8:$C$10,F11)) -> 46520 | H11: EXEMPT | I11: =IF(H11="","",IF(H11="ALL","Yes",IF(IFERROR(INDEX('Applicability Screen'!$E$8:$E$20,MATCH(H11,'Applicability Screen'!$G$8:$G$20,0)),"")="","Answer screen",INDEX('Applicability Screen'!$E$8:$E$20,MATCH(H11,'Applicability Screen'!$G$8:$G$20,0))))) -> Answer screen | P11: =IF(OR(O11="",J11="Done",J11="Not applicable"),"",IF(O11<TODAY(),"OVERDUE","")) | Q11: =IF(AND(A11="",D11=""),"",IF(AND(I11="No",J11<>"Not applicable"),"Screen says not triggered - confirm or mark Not applicable. ","")&IF(AND(G11<>"",J11<>"Done",J11<>"Not applicable",G11<=TODAY()),"Duty already in force. ","")&IF(AND(O11<>"",G11<>"",J11<>"Done",J11<>"Not applicable",O11>G11),"Target date is after the duty applies. ","")&IF(AND(N11="High",L11="",J11<>"Done",J11<>"Not applicable"),"High priority with no owner. ","")&IF(AND(J11="Done",K11=""),"Done but no evidence location. ","")&IF(AND(J11="Not applicable",M11=""),"Say why it is not applicable. ","")) | R11: =IF(AND(A11<>"",N11="High",J11<>"Done",J11<>"Not applicable"),COUNTIFS($A$6:A11,"<>",$N$6:N11,"High",$J$6:J11,"<>Done",$J$6:J11,"<>Not applicable"),"")
A12: APP-07 | B12: Applicability and roles | C12: s.17(3) | D12: Check whether the Central Government has notified you or your class (which may include startups) as a Data Fiduciary to whom s.5, s.8(3), s.8(7), s.10 and s.11 do not apply. Do not assume this exemption until a notification covers your class. | E12: Data Fiduciary | F12: 3 | G12: =IF(F12="","",INDEX(Timeline!$C$8:$C$10,F12)) -> 46520 | H12: DF | I12: =IF(H12="","",IF(H12="ALL","Yes",IF(IFERROR(INDEX('Applicability Screen'!$E$8:$E$20,MATCH(H12,'Applicability Screen'!$G$8:$G$20,0)),"")="","Answer screen",INDEX('Applicability Screen'!$E$8:$E$20,MATCH(H12,'Applicability Screen'!$G$8:$G$20,0))))) -> Answer screen | P12: =IF(OR(O12="",J12="Done",J12="Not applicable"),"",IF(O12<TODAY(),"OVERDUE","")) | Q12: =IF(AND(A12="",D12=""),"",IF(AND(I12="No",J12<>"Not applicable"),"Screen says not triggered - confirm or mark Not applicable. ","")&IF(AND(G12<>"",J12<>"Done",J12<>"Not applicable",G12<=TODAY()),"Duty already in force. ","")&IF(AND(O12<>"",G12<>"",J12<>"Done",J12<>"Not applicable",O12>G12),"Target date is after the duty applies. ","")&IF(AND(N12="High",L12="",J12<>"Done",J12<>"Not applicable"),"High priority with no owner. ","")&IF(AND(J12="Done",K12=""),"Done but no evidence location. ","")&IF(AND(J12="Not applicable",M12=""),"Say why it is not applicable. ","")) | R12: =IF(AND(A12<>"",N12="High",J12<>"Done",J12<>"Not applicable"),COUNTIFS($A$6:A12,"<>",$N$6:N12,"High",$J$6:J12,"<>Done",$J$6:J12,"<>Not applicable"),"")
A13: APP-08 | B13: Applicability and roles | C13: s.10(1) | D13: Check whether the Central Government has notified you or your class as a Significant Data Fiduciary. Factors it may assess include volume and sensitivity of personal data, risk to Data Principals' rights, sovereignty and integrity of India, risk to electoral democracy, security of the State and public order. Monitor the Gazette. | E13: Data Fiduciary | F13: 3 | G13: =IF(F13="","",INDEX(Timeline!$C$8:$C$10,F13)) -> 46520 | H13: DF | I13: =IF(H13="","",IF(H13="ALL","Yes",IF(IFERROR(INDEX('Applicability Screen'!$E$8:$E$20,MATCH(H13,'Applicability Screen'!$G$8:$G$20,0)),"")="","Answer screen",INDEX('Applicability Screen'!$E$8:$E$20,MATCH(H13,'Applicability Screen'!$G$8:$G$20,0))))) -> Answer screen | P13: =IF(OR(O13="",J13="Done",J13="Not applicable"),"",IF(O13<TODAY(),"OVERDUE","")) | Q13: =IF(AND(A13="",D13=""),"",IF(AND(I13="No",J13<>"Not applicable"),"Screen says not triggered - confirm or mark Not applicable. ","")&IF(AND(G13<>"",J13<>"Done",J13<>"Not applicable",G13<=TODAY()),"Duty already in force. ","")&IF(AND(O13<>"",G13<>"",J13<>"Done",J13<>"Not applicable",O13>G13),"Target date is after the duty applies. ","")&IF(AND(N13="High",L13="",J13<>"Done",J13<>"Not applicable"),"High priority with no owner. ","")&IF(AND(J13="Done",K13=""),"Done but no evidence location. ","")&IF(AND(J13="Not applicable",M13=""),"Say why it is not applicable. ","")) | R13: =IF(AND(A13<>"",N13="High",J13<>"Done",J13<>"Not applicable"),COUNTIFS($A$6:A13,"<>",$N$6:N13,"High",$J$6:J13,"<>Done",$J$6:J13,"<>Not applicable"),"")
A14: APP-09 | B14: Applicability and roles | C14: r.8(1), Third Schedule | D14: Check whether you are in a Third Schedule class: e-commerce entity with at least two crore registered users in India; online gaming intermediary with at least fifty lakh registered users in India; social media intermediary with at least two crore registered users in India. These classes have a fixed inactivity-based erasure rule (RET-03, RET-04). | E14: Data Fiduciary | F14: 3 | G14: =IF(F14="","",INDEX(Timeline!$C$8:$C$10,F14)) -> 46520 | H14: DF | I14: =IF(H14="","",IF(H14="ALL","Yes",IF(IFERROR(INDEX('Applicability Screen'!$E$8:$E$20,MATCH(H14,'Applicability Screen'!$G$8:$G$20,0)),"")="","Answer screen",INDEX('Applicability Screen'!$E$8:$E$20,MATCH(H14,'Applicability Screen'!$G$8:$G$20,0))))) -> Answer screen | P14: =IF(OR(O14="",J14="Done",J14="Not applicable"),"",IF(O14<TODAY(),"OVERDUE","")) | Q14: =IF(AND(A14="",D14=""),"",IF(AND(I14="No",J14<>"Not applicable"),"Screen says not triggered - confirm or mark Not applicable. ","")&IF(AND(G14<>"",J14<>"Done",J14<>"Not applicable",G14<=TODAY()),"Duty already in force. ","")&IF(AND(O14<>"",G14<>"",J14<>"Done",J14<>"Not applicable",O14>G14),"Target date is after the duty applies. ","")&IF(AND(N14="High",L14="",J14<>"Done",J14<>"Not applicable"),"High priority with no owner. ","")&IF(AND(J14="Done",K14=""),"Done but no evidence location. ","")&IF(AND(J14="Not applicable",M14=""),"Say why it is not applicable. ","")) | R14: =IF(AND(A14<>"",N14="High",J14<>"Done",J14<>"Not applicable"),COUNTIFS($A$6:A14,"<>",$N$6:N14,"High",$J$6:J14,"<>Done",$J$6:J14,"<>Not applicable"),"")
A15: NOT-01 | B15: Notice | C15: s.5(1), r.3 | D15: Give a notice with, or before, every request for consent. | E15: Data Fiduciary | F15: 3 | G15: =IF(F15="","",INDEX(Timeline!$C$8:$C$10,F15)) -> 46520 | H15: DF | I15: =IF(H15="","",IF(H15="ALL","Yes",IF(IFERROR(INDEX('Applicability Screen'!$E$8:$E$20,MATCH(H15,'Applicability Screen'!$G$8:$G$20,0)),"")="","Answer screen",INDEX('Applicability Screen'!$E$8:$E$20,MATCH(H15,'Applicability Screen'!$G$8:$G$20,0))))) -> Answer screen | J15: In progress | K15: Example: Legal SharePoint > DPDP > Notices > v0.3 | L15: Head of Privacy | M15: Example: app sign-up flow asks for consent before showing the notice | N15: High | O15: 46418 | P15: =IF(OR(O15="",J15="Done",J15="Not applicable"),"",IF(O15<TODAY(),"OVERDUE","")) | Q15: =IF(AND(A15="",D15=""),"",IF(AND(I15="No",J15<>"Not applicable"),"Screen says not triggered - confirm or mark Not applicable. ","")&IF(AND(G15<>"",J15<>"Done",J15<>"Not applicable",G15<=TODAY()),"Duty already in force. ","")&IF(AND(O15<>"",G15<>"",J15<>"Done",J15<>"Not applicable",O15>G15),"Target date is after the duty applies. ","")&IF(AND(N15="High",L15="",J15<>"Done",J15<>"Not applicable"),"High priority with no owner. ","")&IF(AND(J15="Done",K15=""),"Done but no evidence location. ","")&IF(AND(J15="Not applicable",M15=""),"Say why it is not applicable. ","")) | R15: =IF(AND(A15<>"",N15="High",J15<>"Done",J15<>"Not applicable"),COUNTIFS($A$6:A15,"<>",$N$6:N15,"High",$J$6:J15,"<>Done",$J$6:J15,"<>Not applicable"),"") -> 1
A16: NOT-02 | B16: Notice | C16: r.3(a) | D16: Make the notice understandable on its own - independently of any other information you have made, make or may make available (for example terms of service or a general privacy policy). | E16: Data Fiduciary | F16: 3 | G16: =IF(F16="","",INDEX(Timeline!$C$8:$C$10,F16)) -> 46520 | H16: DF | I16: =IF(H16="","",IF(H16="ALL","Yes",IF(IFERROR(INDEX('Applicability Screen'!$E$8:$E$20,MATCH(H16,'Applicability Screen'!$G$8:$G$20,0)),"")="","Answer screen",INDEX('Applicability Screen'!$E$8:$E$20,MATCH(H16,'Applicability Screen'!$G$8:$G$20,0))))) -> Answer screen | P16: =IF(OR(O16="",J16="Done",J16="Not applicable"),"",IF(O16<TODAY(),"OVERDUE","")) | Q16: =IF(AND(A16="",D16=""),"",IF(AND(I16="No",J16<>"Not applicable"),"Screen says not triggered - confirm or mark Not applicable. ","")&IF(AND(G16<>"",J16<>"Done",J16<>"Not applicable",G16<=TODAY()),"Duty already in force. ","")&IF(AND(O16<>"",G16<>"",J16<>"Done",J16<>"Not applicable",O16>G16),"Target date is after the duty applies. ","")&IF(AND(N16="High",L16="",J16<>"Done",J16<>"Not applicable"),"High priority with no owner. ","")&IF(AND(J16="Done",K16=""),"Done but no evidence location. ","")&IF(AND(J16="Not applicable",M16=""),"Say why it is not applicable. ","")) | R16: =IF(AND(A16<>"",N16="High",J16<>"Done",J16<>"Not applicable"),COUNTIFS($A$6:A16,"<>",$N$6:N16,"High",$J$6:J16,"<>Done",$J$6:J16,"<>Not applicable"),"")
A17: NOT-03 | B17: Notice | C17: s.5(1)(i), r.3(b) | D17: In clear and plain language, give a fair account that lets the Data Principal give specific and informed consent. At the minimum: an itemised description of the personal data; and the specified purpose(s), with a specific description of the goods or services provided, or uses enabled, by the processing. | E17: Data Fiduciary | F17: 3 | G17: =IF(F17="","",INDEX(Timeline!$C$8:$C$10,F17)) -> 46520 | H17: DF | I17: =IF(H17="","",IF(H17="ALL","Yes",IF(IFERROR(INDEX('Applicability Screen'!$E$8:$E$20,MATCH(H17,'Applicability Screen'!$G$8:$G$20,0)),"")="","Answer screen",INDEX('Applicability Screen'!$E$8:$E$20,MATCH(H17,'Applicability Screen'!$G$8:$G$20,0))))) -> Answer screen | P17: =IF(OR(O17="",J17="Done",J17="Not applicable"),"",IF(O17<TODAY(),"OVERDUE","")) | Q17: =IF(AND(A17="",D17=""),"",IF(AND(I17="No",J17<>"Not applicable"),"Screen says not triggered - confirm or mark Not applicable. ","")&IF(AND(G17<>"",J17<>"Done",J17<>"Not applicable",G17<=TODAY()),"Duty already in force. ","")&IF(AND(O17<>"",G17<>"",J17<>"Done",J17<>"Not applicable",O17>G17),"Target date is after the duty applies. ","")&IF(AND(N17="High",L17="",J17<>"Done",J17<>"Not applicable"),"High priority with no owner. ","")&IF(AND(J17="Done",K17=""),"Done but no evidence location. ","")&IF(AND(J17="Not applicable",M17=""),"Say why it is not applicable. ","")) | R17: =IF(AND(A17<>"",N17="High",J17<>"Done",J17<>"Not applicable"),COUNTIFS($A$6:A17,"<>",$N$6:N17,"High",$J$6:J17,"<>Done",$J$6:J17,"<>Not applicable"),"")
A18: NOT-04 | B18: Notice | C18: s.5(1)(ii)-(iii), r.3(c) | D18: Tell the Data Principal how to withdraw consent, exercise her rights under the Act and complain to the Board: give the particular link to your website or app (or both), and describe any other means available. Withdrawal must be comparable in ease to giving consent. | E18: Data Fiduciary | F18: 3 | G18: =IF(F18="","",INDEX(Timeline!$C$8:$C$10,F18)) -> 46520 | H18: DF | I18: =IF(H18="","",IF(H18="ALL","Yes",IF(IFERROR(INDEX('Applicability Screen'!$E$8:$E$20,MATCH(H18,'Applicability Screen'!$G$8:$G$20,0)),"")="","Answer screen",INDEX('Applicability Screen'!$E$8:$E$20,MATCH(H18,'Applicability Screen'!$G$8:$G$20,0))))) -> Answer screen | P18: =IF(OR(O18="",J18="Done",J18="Not applicable"),"",IF(O18<TODAY(),"OVERDUE","")) | Q18: =IF(AND(A18="",D18=""),"",IF(AND(I18="No",J18<>"Not applicable"),"Screen says not triggered - confirm or mark Not applicable. ","")&IF(AND(G18<>"",J18<>"Done",J18<>"Not applicable",G18<=TODAY()),"Duty already in force. ","")&IF(AND(O18<>"",G18<>"",J18<>"Done",J18<>"Not applicable",O18>G18),"Target date is after the duty applies. ","")&IF(AND(N18="High",L18="",J18<>"Done",J18<>"Not applicable"),"High priority with no owner. ","")&IF(AND(J18="Done",K18=""),"Done but no evidence location. ","")&IF(AND(J18="Not applicable",M18=""),"Say why it is not applicable. ","")) | R18: =IF(AND(A18<>"",N18="High",J18<>"Done",J18<>"Not applicable"),COUNTIFS($A$6:A18,"<>",$N$6:N18,"High",$J$6:J18,"<>Done",$J$6:J18,"<>Not applicable"),"")
A19: NOT-05 | B19: Notice | C19: s.5(3) | D19: Give the Data Principal the option to access the notice in English or any language specified in the Eighth Schedule to the Constitution. Decide and document which languages you offer and why - take advice on this point. | E19: Data Fiduciary | F19: 3 | G19: =IF(F19="","",INDEX(Timeline!$C$8:$C$10,F19)) -> 46520 | H19: DF | I19: =IF(H19="","",IF(H19="ALL","Yes",IF(IFERROR(INDEX('Applicability Screen'!$E$8:$E$20,MATCH(H19,'Applicability Screen'!$G$8:$G$20,0)),"")="","Answer screen",INDEX('Applicability Screen'!$E$8:$E$20,MATCH(H19,'Applicability Screen'!$G$8:$G$20,0))))) -> Answer screen | P19: =IF(OR(O19="",J19="Done",J19="Not applicable"),"",IF(O19<TODAY(),"OVERDUE","")) | Q19: =IF(AND(A19="",D19=""),"",IF(AND(I19="No",J19<>"Not applicable"),"Screen says not triggered - confirm or mark Not applicable. ","")&IF(AND(G19<>"",J19<>"Done",J19<>"Not applicable",G19<=TODAY()),"Duty already in force. ","")&IF(AND(O19<>"",G19<>"",J19<>"Done",J19<>"Not applicable",O19>G19),"Target date is after the duty applies. ","")&IF(AND(N19="High",L19="",J19<>"Done",J19<>"Not applicable"),"High priority with no owner. ","")&IF(AND(J19="Done",K19=""),"Done but no evidence location. ","")&IF(AND(J19="Not applicable",M19=""),"Say why it is not applicable. ","")) | R19: =IF(AND(A19<>"",N19="High",J19<>"Done",J19<>"Not applicable"),COUNTIFS($A$6:A19,"<>",$N$6:N19,"High",$J$6:J19,"<>Done",$J$6:J19,"<>Not applicable"),"")
A20: NOT-06 | B20: Notice | C20: s.5(2) | D20: Where consent was given before this provision commenced: as soon as reasonably practicable, give a notice of the personal data and purpose processed, how to withdraw consent and use the grievance route, and how to complain to the Board. You may continue processing until the Data Principal withdraws consent. | E20: Data Fiduciary | F20: 3 | G20: =IF(F20="","",INDEX(Timeline!$C$8:$C$10,F20)) -> 46520 | H20: DF | I20: =IF(H20="","",IF(H20="ALL","Yes",IF(IFERROR(INDEX('Applicability Screen'!$E$8:$E$20,MATCH(H20,'Applicability Screen'!$G$8:$G$20,0)),"")="","Answer screen",INDEX('Applicability Screen'!$E$8:$E$20,MATCH(H20,'Applicability Screen'!$G$8:$G$20,0))))) -> Answer screen | P20: =IF(OR(O20="",J20="Done",J20="Not applicable"),"",IF(O20<TODAY(),"OVERDUE","")) | Q20: =IF(AND(A20="",D20=""),"",IF(AND(I20="No",J20<>"Not applicable"),"Screen says not triggered - confirm or mark Not applicable. ","")&IF(AND(G20<>"",J20<>"Done",J20<>"Not applicable",G20<=TODAY()),"Duty already in force. ","")&IF(AND(O20<>"",G20<>"",J20<>"Done",J20<>"Not applicable",O20>G20),"Target date is after the duty applies. ","")&IF(AND(N20="High",L20="",J20<>"Done",J20<>"Not applicable"),"High priority with no owner. ","")&IF(AND(J20="Done",K20=""),"Done but no evidence location. ","")&IF(AND(J20="Not applicable",M20=""),"Say why it is not applicable. ","")) | R20: =IF(AND(A20<>"",N20="High",J20<>"Done",J20<>"Not applicable"),COUNTIFS($A$6:A20,"<>",$N$6:N20,"High",$J$6:J20,"<>Done",$J$6:J20,"<>Not applicable"),"")
A21: CON-01 | B21: Consent and withdrawal | C21: s.6(1) | D21: Consent must be free, specific, informed, unconditional and unambiguous, given by a clear affirmative action, for the specified purpose, and limited to the personal data necessary for that purpose. (The Act's illustration: a telemedicine app's consent does not extend to the phone's contact list.) | E21: Data Fiduciary | F21: 3 | G21: =IF(F21="","",INDEX(Timeline!$C$8:$C$10,F21)) -> 46520 | H21: DF | I21: =IF(H21="","",IF(H21="ALL","Yes",IF(IFERROR(INDEX('Applicability Screen'!$E$8:$E$20,MATCH(H21,'Applicability Screen'!$G$8:$G$20,0)),"")="","Answer screen",INDEX('Applicability Screen'!$E$8:$E$20,MATCH(H21,'Applicability Screen'!$G$8:$G$20,0))))) -> Answer screen | P21: =IF(OR(O21="",J21="Done",J21="Not applicable"),"",IF(O21<TODAY(),"OVERDUE","")) | Q21: =IF(AND(A21="",D21=""),"",IF(AND(I21="No",J21<>"Not applicable"),"Screen says not triggered - confirm or mark Not applicable. ","")&IF(AND(G21<>"",J21<>"Done",J21<>"Not applicable",G21<=TODAY()),"Duty already in force. ","")&IF(AND(O21<>"",G21<>"",J21<>"Done",J21<>"Not applicable",O21>G21),"Target date is after the duty applies. ","")&IF(AND(N21="High",L21="",J21<>"Done",J21<>"Not applicable"),"High priority with no owner. ","")&IF(AND(J21="Done",K21=""),"Done but no evidence location. ","")&IF(AND(J21="Not applicable",M21=""),"Say why it is not applicable. ","")) | R21: =IF(AND(A21<>"",N21="High",J21<>"Done",J21<>"Not applicable"),COUNTIFS($A$6:A21,"<>",$N$6:N21,"High",$J$6:J21,"<>Done",$J$6:J21,"<>Not applicable"),"")
A22: CON-02 | B22: Consent and withdrawal | C22: s.6(3) | D22: Present every consent request in clear and plain language, with the option to access it in English or any Eighth Schedule language, and include contact details of the Data Protection Officer (where applicable) or another person you authorise to respond to rights communications. | E22: Data Fiduciary | F22: 3 | G22: =IF(F22="","",INDEX(Timeline!$C$8:$C$10,F22)) -> 46520 | H22: DF | I22: =IF(H22="","",IF(H22="ALL","Yes",IF(IFERROR(INDEX('Applicability Screen'!$E$8:$E$20,MATCH(H22,'Applicability Screen'!$G$8:$G$20,0)),"")="","Answer screen",INDEX('Applicability Screen'!$E$8:$E$20,MATCH(H22,'Applicability Screen'!$G$8:$G$20,0))))) -> Answer screen | P22: =IF(OR(O22="",J22="Done",J22="Not applicable"),"",IF(O22<TODAY(),"OVERDUE","")) | Q22: =IF(AND(A22="",D22=""),"",IF(AND(I22="No",J22<>"Not applicable"),"Screen says not triggered - confirm or mark Not applicable. ","")&IF(AND(G22<>"",J22<>"Done",J22<>"Not applicable",G22<=TODAY()),"Duty already in force. ","")&IF(AND(O22<>"",G22<>"",J22<>"Done",J22<>"Not applicable",O22>G22),"Target date is after the duty applies. ","")&IF(AND(N22="High",L22="",J22<>"Done",J22<>"Not applicable"),"High priority with no owner. ","")&IF(AND(J22="Done",K22=""),"Done but no evidence location. ","")&IF(AND(J22="Not applicable",M22=""),"Say why it is not applicable. ","")) | R22: =IF(AND(A22<>"",N22="High",J22<>"Done",J22<>"Not applicable"),COUNTIFS($A$6:A22,"<>",$N$6:N22,"High",$J$6:J22,"<>Done",$J$6:J22,"<>Not applicable"),"")
A23: CON-03 | B23: Consent and withdrawal | C23: s.6(2) | D23: Review consent wording: any part of a consent that infringes the Act, the Rules or any other law is invalid to that extent. (The Act's illustration: consent to waive the right to complain to the Board is invalid.) | E23: Data Fiduciary | F23: 3 | G23: =IF(F23="","",INDEX(Timeline!$C$8:$C$10,F23)) -> 46520 | H23: DF | I23: =IF(H23="","",IF(H23="ALL","Yes",IF(IFERROR(INDEX('Applicability Screen'!$E$8:$E$20,MATCH(H23,'Applicability Screen'!$G$8:$G$20,0)),"")="","Answer screen",INDEX('Applicability Screen'!$E$8:$E$20,MATCH(H23,'Applicability Screen'!$G$8:$G$20,0))))) -> Answer screen | P23: =IF(OR(O23="",J23="Done",J23="Not applicable"),"",IF(O23<TODAY(),"OVERDUE","")) | Q23: =IF(AND(A23="",D23=""),"",IF(AND(I23="No",J23<>"Not applicable"),"Screen says not triggered - confirm or mark Not applicable. ","")&IF(AND(G23<>"",J23<>"Done",J23<>"Not applicable",G23<=TODAY()),"Duty already in force. ","")&IF(AND(O23<>"",G23<>"",J23<>"Done",J23<>"Not applicable",O23>G23),"Target date is after the duty applies. ","")&IF(AND(N23="High",L23="",J23<>"Done",J23<>"Not applicable"),"High priority with no owner. ","")&IF(AND(J23="Done",K23=""),"Done but no evidence location. ","")&IF(AND(J23="Not applicable",M23=""),"Say why it is not applicable. ","")) | R23: =IF(AND(A23<>"",N23="High",J23<>"Done",J23<>"Not applicable"),COUNTIFS($A$6:A23,"<>",$N$6:N23,"High",$J$6:J23,"<>Done",$J$6:J23,"<>Not applicable"),"")
A24: CON-04 | B24: Consent and withdrawal | C24: s.6(4), r.3(c)(i) | D24: Let Data Principals withdraw consent at any time, with ease comparable to the ease of giving it. Check this in every channel where consent is collected. | E24: Data Fiduciary | F24: 3 | G24: =IF(F24="","",INDEX(Timeline!$C$8:$C$10,F24)) -> 46520 | H24: DF | I24: =IF(H24="","",IF(H24="ALL","Yes",IF(IFERROR(INDEX('Applicability Screen'!$E$8:$E$20,MATCH(H24,'Applicability Screen'!$G$8:$G$20,0)),"")="","Answer screen",INDEX('Applicability Screen'!$E$8:$E$20,MATCH(H24,'Applicability Screen'!$G$8:$G$20,0))))) -> Answer screen | P24: =IF(OR(O24="",J24="Done",J24="Not applicable"),"",IF(O24<TODAY(),"OVERDUE","")) | Q24: =IF(AND(A24="",D24=""),"",IF(AND(I24="No",J24<>"Not applicable"),"Screen says not triggered - confirm or mark Not applicable. ","")&IF(AND(G24<>"",J24<>"Done",J24<>"Not applicable",G24<=TODAY()),"Duty already in force. ","")&IF(AND(O24<>"",G24<>"",J24<>"Done",J24<>"Not applicable",O24>G24),"Target date is after the duty applies. ","")&IF(AND(N24="High",L24="",J24<>"Done",J24<>"Not applicable"),"High priority with no owner. ","")&IF(AND(J24="Done",K24=""),"Done but no evidence location. ","")&IF(AND(J24="Not applicable",M24=""),"Say why it is not applicable. ","")) | R24: =IF(AND(A24<>"",N24="High",J24<>"Done",J24<>"Not applicable"),COUNTIFS($A$6:A24,"<>",$N$6:N24,"High",$J$6:J24,"<>Done",$J$6:J24,"<>Not applicable"),"")
A25: CON-05 | B25: Consent and withdrawal | C25: s.6(5) | D25: Withdrawal does not affect the legality of processing done on consent before it; the consequences of withdrawal are borne by the Data Principal. (The Act's illustration: an e-commerce app may stop new orders but cannot stop processing for goods already ordered and paid for.) | E25: Data Fiduciary | F25: 3 | G25: =IF(F25="","",INDEX(Timeline!$C$8:$C$10,F25)) -> 46520 | H25: DF | I25: =IF(H25="","",IF(H25="ALL","Yes",IF(IFERROR(INDEX('Applicability Screen'!$E$8:$E$20,MATCH(H25,'Applicability Screen'!$G$8:$G$20,0)),"")="","Answer screen",INDEX('Applicability Screen'!$E$8:$E$20,MATCH(H25,'Applicability Screen'!$G$8:$G$20,0))))) -> Answer screen | P25: =IF(OR(O25="",J25="Done",J25="Not applicable"),"",IF(O25<TODAY(),"OVERDUE","")) | Q25: =IF(AND(A25="",D25=""),"",IF(AND(I25="No",J25<>"Not applicable"),"Screen says not triggered - confirm or mark Not applicable. ","")&IF(AND(G25<>"",J25<>"Done",J25<>"Not applicable",G25<=TODAY()),"Duty already in force. ","")&IF(AND(O25<>"",G25<>"",J25<>"Done",J25<>"Not applicable",O25>G25),"Target date is after the duty applies. ","")&IF(AND(N25="High",L25="",J25<>"Done",J25<>"Not applicable"),"High priority with no owner. ","")&IF(AND(J25="Done",K25=""),"Done but no evidence location. ","")&IF(AND(J25="Not applicable",M25=""),"Say why it is not applicable. ","")) | R25: =IF(AND(A25<>"",N25="High",J25<>"Done",J25<>"Not applicable"),COUNTIFS($A$6:A25,"<>",$N$6:N25,"High",$J$6:J25,"<>Done",$J$6:J25,"<>Not applicable"),"")
A26: CON-06 | B26: Consent and withdrawal | C26: s.6(6) | D26: On withdrawal, within a reasonable time stop processing that Data Principal's personal data and make your Data Processors stop - unless processing without consent is required or authorised by the Act, the Rules or other Indian law. | E26: Data Fiduciary (flows to Data Processor via contract) | F26: 3 | G26: =IF(F26="","",INDEX(Timeline!$C$8:$C$10,F26)) -> 46520 | H26: DF | I26: =IF(H26="","",IF(H26="ALL","Yes",IF(IFERROR(INDEX('Applicability Screen'!$E$8:$E$20,MATCH(H26,'Applicability Screen'!$G$8:$G$20,0)),"")="","Answer screen",INDEX('Applicability Screen'!$E$8:$E$20,MATCH(H26,'Applicability Screen'!$G$8:$G$20,0))))) -> Answer screen | P26: =IF(OR(O26="",J26="Done",J26="Not applicable"),"",IF(O26<TODAY(),"OVERDUE","")) | Q26: =IF(AND(A26="",D26=""),"",IF(AND(I26="No",J26<>"Not applicable"),"Screen says not triggered - confirm or mark Not applicable. ","")&IF(AND(G26<>"",J26<>"Done",J26<>"Not applicable",G26<=TODAY()),"Duty already in force. ","")&IF(AND(O26<>"",G26<>"",J26<>"Done",J26<>"Not applicable",O26>G26),"Target date is after the duty applies. ","")&IF(AND(N26="High",L26="",J26<>"Done",J26<>"Not applicable"),"High priority with no owner. ","")&IF(AND(J26="Done",K26=""),"Done but no evidence location. ","")&IF(AND(J26="Not applicable",M26=""),"Say why it is not applicable. ","")) | R26: =IF(AND(A26<>"",N26="High",J26<>"Done",J26<>"Not applicable"),COUNTIFS($A$6:A26,"<>",$N$6:N26,"High",$J$6:J26,"<>Done",$J$6:J26,"<>Not applicable"),"")
A27: CON-07 | B27: Consent and withdrawal | C27: s.6(10) | D27: Keep proof: where consent is the basis and it is questioned in a proceeding, you must prove that notice was given and consent was given in line with the Act and Rules. Keep the notice version shown and the consent record. | E27: Data Fiduciary | F27: 3 | G27: =IF(F27="","",INDEX(Timeline!$C$8:$C$10,F27)) -> 46520 | H27: DF | I27: =IF(H27="","",IF(H27="ALL","Yes",IF(IFERROR(INDEX('Applicability Screen'!$E$8:$E$20,MATCH(H27,'Applicability Screen'!$G$8:$G$20,0)),"")="","Answer screen",INDEX('Applicability Screen'!$E$8:$E$20,MATCH(H27,'Applicability Screen'!$G$8:$G$20,0))))) -> Answer screen | P27: =IF(OR(O27="",J27="Done",J27="Not applicable"),"",IF(O27<TODAY(),"OVERDUE","")) | Q27: =IF(AND(A27="",D27=""),"",IF(AND(I27="No",J27<>"Not applicable"),"Screen says not triggered - confirm or mark Not applicable. ","")&IF(AND(G27<>"",J27<>"Done",J27<>"Not applicable",G27<=TODAY()),"Duty already in force. ","")&IF(AND(O27<>"",G27<>"",J27<>"Done",J27<>"Not applicable",O27>G27),"Target date is after the duty applies. ","")&IF(AND(N27="High",L27="",J27<>"Done",J27<>"Not applicable"),"High priority with no owner. ","")&IF(AND(J27="Done",K27=""),"Done but no evidence location. ","")&IF(AND(J27="Not applicable",M27=""),"Say why it is not applicable. ","")) | R27: =IF(AND(A27<>"",N27="High",J27<>"Done",J27<>"Not applicable"),COUNTIFS($A$6:A27,"<>",$N$6:N27,"High",$J$6:J27,"<>Done",$J$6:J27,"<>Not applicable"),"")
