Workbook

Sheet Start here
B1: AI Vendor Due-Diligence Questionnaire
B2: By John Bommeraveni Joseph | linkedin.com/in/john-bj | Free every weekday: GRC Made Simple Daily
B5: What this is
B6: A due-diligence questionnaire and scoring workbook for buying or renewing any product with AI features - 74 questions in 14 sections covering training use of your data, retention, the model provider behind the product, certifications (scope and period, not the logo), silent model updates, testing, agent permissions, output handling, human oversight, logging, incident notification, regulatory position, IP and exit. Built for CISOs, GRC, procurement and privacy teams; supports third-party AI risk work under ISO/IEC 42001 (Annex A.10 Third-party and customer relationships), the NIST AI RMF and the EU AI Act.
B7: How to use it (one workbook per vendor)
B8: 1. Save a copy for the vendor first. The workbook ships filled with a worked example for a fictional vendor so you can see every formula working. To start a real review, clear the yellow cells on Vendor Profile, the yellow columns F, G, H and O on Questionnaire, and rows 6-7 of Follow-up Tracker.
B9: 2. Vendor Profile: record the product, AI features in scope, model provider(s), data shared and the criticality tier. The sheet suggests a minimum tier from the data and use you describe.
B10: 3. Send the Questionnaire to the vendor (columns A to G). Ask for evidence, not marketing: the 'What good evidence looks like' column tells both sides what will be accepted.
B11: 4. Score every answered question 0-3 on the evidence you received, not on the vendor's answer. Adjust the weight (1-3) and the Critical flag to your risk appetite before scoring, and record that decision.
B12: 5. Scoring Summary gives section scores, the overall rating, red flags and a recommendation using the thresholds shown on that sheet. Change the thresholds there (yellow cells) to match your TPRM policy.
B13: 6. Follow-up Tracker: log every gap, condition or evidence request with an owner and due date. 'Approve with conditions' only makes sense if the conditions are tracked here and in the contract.
B14: 7. Dashboard: the one-page result for the approver or the third-party risk committee.
... B22: Version 1.0 - 27 October 2026. Free to use and share with this credit kept.

Sheet Dashboard
B1: AI Vendor Risk Dashboard
B2: By John Bommeraveni Joseph | linkedin.com/in/john-bj | Free every weekday: GRC Made Simple Daily
B5: Measure | C5: Value | E5: Section | F5: Score % | G5: Red flags
B6: Vendor | C6: =IF('Vendor Profile'!C6="","",'Vendor Profile'!C6) -> Example Vendor Ltd (fictional) | E6: ='Scoring Summary'!B6 -> 1. Training and model improvement | F6: ='Scoring Summary'!I6 -> 0.75 | G6: ='Scoring Summary'!K6 -> 0
B7: Product / plan | C7: =IF('Vendor Profile'!C7="","",'Vendor Profile'!C7) -> Example Support Copilot - Enterprise plan | E7: ='Scoring Summary'!B7 -> 2. Retention of prompts, outputs and logs | F7: ='Scoring Summary'!I7 -> 0.66666667 | G7: ='Scoring Summary'!K7 -> 0
B8: Criticality tier | C8: =IF('Vendor Profile'!C21="","",'Vendor Profile'!C21) -> Tier 2 - High | E8: ='Scoring Summary'!B8 -> 3. Data residency and sub-processors (including the model provider) | F8: ='Scoring Summary'!I8 -> 0.87179487 | G8: ='Scoring Summary'!K8 -> 0
B9: Tier check | C9: ='Vendor Profile'!C22 -> OK | E9: ='Scoring Summary'!B9 -> 4. Security controls and certifications | F9: ='Scoring Summary'!I9 -> 0.76470588 | G9: ='Scoring Summary'!K9 -> 0
B10: RECOMMENDATION | C10: ='Scoring Summary'!$J$30 -> Escalate | E10: ='Scoring Summary'!B10 -> 5. Model change management | F10: ='Scoring Summary'!I10 -> 0.45454545 | G10: ='Scoring Summary'!K10 -> 1
B11: Recommendation on the scores so far | C11: ='Scoring Summary'!$J$29 -> Escalate | E11: ='Scoring Summary'!B11 -> 6. Evaluation and testing | F11: ='Scoring Summary'!I11 -> 0.66666667 | G11: ='Scoring Summary'!K11 -> 0
B12: Overall score | C12: ='Scoring Summary'!$J$24 -> 0.73837209 | E12: ='Scoring Summary'!B12 -> 7. Agent and tool permissions (excessive agency) | F12: ='Scoring Summary'!I12 -> 0.84444444 | G12: ='Scoring Summary'!K12 -> 0
B13: Overall rating | C13: ='Scoring Summary'!$J$25 -> Adequate | E13: ='Scoring Summary'!B13 -> 8. Output handling and hallucination controls | F13: ='Scoring Summary'!I13 -> 0.75 | G13: ='Scoring Summary'!K13 -> 0
B14: Red flags | C14: ='Scoring Summary'!$J$26 -> 1 | E14: ='Scoring Summary'!B14 -> 9. Human oversight | F14: ='Scoring Summary'!I14 -> 0.86666667 | G14: ='Scoring Summary'!K14 -> 0
B15: Lowest section score | C15: ='Scoring Summary'!$J$27 -> 0.45454545 | E15: ='Scoring Summary'!B15 -> 10. Logging and audit trail (customer-accessible) | F15: ='Scoring Summary'!I15 -> 0.7 | G15: ='Scoring Summary'!K15 -> 0
B16: Questions answered | C16: =COUNTIFS(Questionnaire!$A$6:$A$93,"<>",Questionnaire!$F$6:$F$93,"<>")&" of "&COUNTIF(Questionnaire!$B$6:$B$93,"?*") -> 74 of 74 | E16: ='Scoring Summary'!B16 -> 11. Incident response and AI-incident notification | F16: ='Scoring Summary'!I16 -> 0.72222222 | G16: ='Scoring Summary'!K16 -> 0
B17: Answered 'No' | C17: =COUNTIF(Questionnaire!$F$6:$F$93,"No") -> 2 | E17: ='Scoring Summary'!B17 -> 12. Regulatory position (EU AI Act, GDPR, DPDP) | F17: ='Scoring Summary'!I17 -> 0.78571429 | G17: ='Scoring Summary'!K17 -> 0
B18: Yes / Partial without an evidence reference | C18: =COUNTIF(Questionnaire!$N$6:$N$93,"Evidence missing") -> 1 | E18: ='Scoring Summary'!B18 -> 13. IP and indemnity for generated output | F18: ='Scoring Summary'!I18 -> 0.74074074 | G18: ='Scoring Summary'!K18 -> 0
B19: Vendor said Yes but evidence scored 0-1 | C19: =COUNTIF(Questionnaire!$N$6:$N$93,"Claim not supported") -> 0 | E19: ='Scoring Summary'!B19 -> 14. Continuity and exit | F19: ='Scoring Summary'!I19 -> 0.6969697 | G19: ='Scoring Summary'!K19 -> 0
B20: Follow-ups open | C20: =COUNTIFS('Follow-up Tracker'!$A$6:$A$105,"<>",'Follow-up Tracker'!$L$6:$L$105,"<>Closed",'Follow-up Tracker'!$L$6:$L$105,"<>Risk accepted") -> 2
B21: Follow-ups overdue | C21: =COUNTIF('Follow-up Tracker'!$O$6:$O$105,"OVERDUE") -> 1
B22: Open follow-ups that block approval | C22: =COUNTIFS('Follow-up Tracker'!$A$6:$A$105,"<>",'Follow-up Tracker'!$L$6:$L$105,"<>Closed",'Follow-up Tracker'!$L$6:$L$105,"<>Risk accepted",'Follow-up Tracker'!$N$6:$N$105,"Yes") -> 2
B23: Reassessment due | C23: =IF('Vendor Profile'!C29="","",'Vendor Profile'!C29) -> 46680
B25: Red = needs action. The workbook ships with a worked example for a fictional vendor; the figures above are calculated from it until you clear the yellow cells.

Sheet Vendor Profile
B1: Vendor Profile
B2: By John Bommeraveni Joseph | linkedin.com/in/john-bj | Free every weekday: GRC Made Simple Daily
B5: Field | C5: Value | D5: Guidance
B6: Vendor (legal entity) | C6: Example Vendor Ltd (fictional) | D6: The contracting entity, not the brand.
B7: Product / service and plan assessed | C7: Example Support Copilot - Enterprise plan | D7: Terms often differ by plan; record the one you will buy.
B8: AI features in scope | C8: Drafts replies to customer tickets; searches our knowledge base; can update ticket fields | D8: List each AI feature you will switch on. Features left off should stay off by contract or setting.
B9: Our use case and business owner | C9: Customer support - Head of Customer Service | D9: What the business will use it for, and who owns that decision.
B10: Underlying model provider(s) | C10: Third-party hosted LLM API (named in sub-processor list v14) | D10: Every model provider behind the product, including fallbacks (see RES-01).
B11: Hosting and model arrangement | C11: Vendor-hosted, third-party model API
B12: Processing regions (storage and inference) | C12: EU storage; inference EU and US | D12: Where data is stored and where the model runs.
B13: Data categories shared | C13: Customer names, emails, order history, ticket text; internal KB articles | D13: Be specific: this drives the tier and the privacy questions.
B14: Personal data shared? | C14: Yes
B15: Special-category or sensitive personal data shared? | C15: No | D15: Health, biometric, financial account, children's data and similar.
B16: Confidential business data, IP or source code shared? | C16: Yes
B17: Outputs used to make or support decisions about people? | C17: No | D17: Eligibility, hiring, credit, access to services.
B18: Can the AI take actions in our systems (tools / agents)? | C18: Yes | D18: Write, send, delete or execute - not just read.
B19: Our EU AI Act role for this use | C19: Deployer | D19: Check Art. 25 before branding, fine-tuning or repurposing it.
B20: Suggested minimum tier (calculated) | C20: =IF(C14="","",IF(OR(C15="Yes",C17="Yes"),"Tier 1 - Critical",IF(OR(C14="Yes",C18="Yes"),"Tier 2 - High","Tier 3 - Moderate"))) -> Tier 2 - High | D20: Tier 1 if sensitive data or decisions about people; Tier 2 if personal data or actions in our systems; otherwise Tier 3.
B21: Criticality tier (your decision) | C21: Tier 2 - High | D21: Set by the business owner with risk; record the reason if below the suggestion.
B22: Tier check (calculated) | C22: =IF(OR(C21="",C20=""),"Set the tier",IF(VALUE(MID(C21,6,1))>VALUE(MID(C20,6,1)),"Below suggested tier - record the justification","OK")) -> OK
B23: Reviewer (GRC / security) | C23: A. Reviewer
B24: Approver | C24: Head of Third-Party Risk | D24: Someone independent of the business owner.
B25: Questionnaire sent | C25: 46280
B26: Response received | C26: 46301
B27: Vendor response time, days (calculated) | C27: =IF(OR(C25="",C26=""),"",C26-C25) -> 21
B28: Review completed | C28: 46315
B29: Reassessment due (calculated) | C29: =IF(OR(C28="",C21=""),"",IFERROR(DATE(YEAR(C28),MONTH(C28)+INDEX($C$32:$C$35,MATCH(C21,$B$32:$B$35,0)),DAY(C28)),"")) -> 46680 | D29: Review completed + the interval for the tier (table below), or sooner on any material change.
B31: Reassessment interval by tier (months) - edit to match your policy
B32: Tier 1 - Critical | C32: 12
B33: Tier 2 - High | C33: 12
B34: Tier 3 - Moderate | C34: 24
B35: Tier 4 - Low | C35: 36

Sheet Questionnaire
B1: AI Vendor Questionnaire
B2: By John Bommeraveni Joseph | linkedin.com/in/john-bj | Free every weekday: GRC Made Simple Daily
A5: ID | B5: Section | C5: Question | D5: Why it matters | E5: What good evidence looks like | F5: Vendor answer | G5: Evidence reference | H5: Reviewer score 0-3 | I5: Weight 1-3 | J5: Critical? | K5: Weighted score | L5: Max possible | M5: Red flag | N5: Check | O5: Reviewer notes
A6: 1. Training and model improvement
A7: TRN-01 | B7: 1. Training and model improvement | C7: Does the signed contract (not only the privacy policy or a web page) state that our inputs, outputs and files are not used to train, fine-tune or improve any model - the vendor's or its model provider's? | D7: Web-page promises can change without notice; only a contract term binds the vendor. | E7: Clause reference in the MSA, DPA or AI addendum, with document version and date. | F7: Yes | G7: AI Addendum v2.1 cl. 4.2 | H7: 3 | I7: 3 | J7: Yes | K7: =IF(OR(A7="",F7="N/A",H7=""),"",H7*I7) -> 9 | L7: =IF(OR(A7="",F7="N/A",H7=""),"",3*I7) -> 9 | M7: =IF(AND(J7="Yes",OR(F7="No",AND(F7<>"N/A",H7<>"",N(H7)<=1))),"RED FLAG","") | N7: =IF(A7="","",IF(F7="","Awaiting answer",IF(AND(F7<>"N/A",H7=""),"Score it",IF(AND(OR(F7="Yes",F7="Partial"),G7=""),"Evidence missing",IF(AND(F7="N/A",J7="Yes"),"Critical N/A - justify",IF(AND(F7="Yes",H7<>"",N(H7)<=1),"Claim not supported","OK")))))) -> OK
A8: TRN-02 | B8: 1. Training and model improvement | C8: Is 'no training on customer data' the default for our plan, or does it depend on an opt-out setting that an admin must switch on? | D8: Opt-out defaults are easily missed, and new workspaces may start with the setting on. | E8: Plan documentation plus a screenshot of the admin setting showing its default state. | F8: Yes | G8: Admin guide p.12; screenshot SS-01 | H8: 3 | I8: 2 | J8: No | K8: =IF(OR(A8="",F8="N/A",H8=""),"",H8*I8) -> 6 | L8: =IF(OR(A8="",F8="N/A",H8=""),"",3*I8) -> 6 | M8: =IF(AND(J8="Yes",OR(F8="No",AND(F8<>"N/A",H8<>"",N(H8)<=1))),"RED FLAG","") | N8: =IF(A8="","",IF(F8="","Awaiting answer",IF(AND(F8<>"N/A",H8=""),"Score it",IF(AND(OR(F8="Yes",F8="Partial"),G8=""),"Evidence missing",IF(AND(F8="N/A",J8="Yes"),"Critical N/A - justify",IF(AND(F8="Yes",H8<>"",N(H8)<=1),"Claim not supported","OK")))))) -> OK
A9: TRN-03 | B9: 1. Training and model improvement | C9: If data is used for 'service improvement' or abuse monitoring, who reviews it (people or systems), where are reviewers located, and can we opt out of human review? | D9: Your prompts can be read by people even when no model is trained on them. | E9: Written description of the review process, reviewer locations, access controls and opt-out route. | F9: Partial | G9: Trust portal FAQ 3.4 | H9: 2 | I9: 2 | J9: No | K9: =IF(OR(A9="",F9="N/A",H9=""),"",H9*I9) -> 4 | L9: =IF(OR(A9="",F9="N/A",H9=""),"",3*I9) -> 6 | M9: =IF(AND(J9="Yes",OR(F9="No",AND(F9<>"N/A",H9<>"",N(H9)<=1))),"RED FLAG","") | N9: =IF(A9="","",IF(F9="","Awaiting answer",IF(AND(F9<>"N/A",H9=""),"Score it",IF(AND(OR(F9="Yes",F9="Partial"),G9=""),"Evidence missing",IF(AND(F9="N/A",J9="Yes"),"Critical N/A - justify",IF(AND(F9="Yes",H9<>"",N(H9)<=1),"Claim not supported","OK")))))) -> OK
A10: TRN-04 | B10: 1. Training and model improvement | C10: Does the no-training commitment flow down in writing to every model provider and sub-processor that receives our data? | D10: The vendor's promise is worth little if the model provider behind it can use the data. | E10: Model provider's enterprise or API data terms, or the vendor's flow-down clause. | F10: Yes | G10: Sub-processor terms summary SP-2 | H10: 2 | I10: 3 | J10: Yes | K10: =IF(OR(A10="",F10="N/A",H10=""),"",H10*I10) -> 6 | L10: =IF(OR(A10="",F10="N/A",H10=""),"",3*I10) -> 9 | M10: =IF(AND(J10="Yes",OR(F10="No",AND(F10<>"N/A",H10<>"",N(H10)<=1))),"RED FLAG","") | N10: =IF(A10="","",IF(F10="","Awaiting answer",IF(AND(F10<>"N/A",H10=""),"Score it",IF(AND(OR(F10="Yes",F10="Partial"),G10=""),"Evidence missing",IF(AND(F10="N/A",J10="Yes"),"Critical N/A - justify",IF(AND(F10="Yes",H10<>"",N(H10)<=1),"Claim not supported","OK")))))) -> OK
A11: TRN-05 | B11: 1. Training and model improvement | C11: How are derived data - telemetry, embeddings, feedback ratings, aggregated or de-identified data - defined in the contract, and may the vendor keep or use them? | D11: Derived data is often excluded from the contract definition of 'customer data'. | E11: Contract definitions of Customer Data and Usage Data, and the permitted uses of each. | F11: Partial | G11: MSA cl. 1 definitions | H11: 1 | I11: 2 | J11: No | K11: =IF(OR(A11="",F11="N/A",H11=""),"",H11*I11) -> 2 | L11: =IF(OR(A11="",F11="N/A",H11=""),"",3*I11) -> 6 | M11: =IF(AND(J11="Yes",OR(F11="No",AND(F11<>"N/A",H11<>"",N(H11)<=1))),"RED FLAG","") | N11: =IF(A11="","",IF(F11="","Awaiting answer",IF(AND(F11<>"N/A",H11=""),"Score it",IF(AND(OR(F11="Yes",F11="Partial"),G11=""),"Evidence missing",IF(AND(F11="N/A",J11="Yes"),"Critical N/A - justify",IF(AND(F11="Yes",H11<>"",N(H11)<=1),"Claim not supported","OK")))))) -> OK
A12: 2. Retention of prompts, outputs and logs
A13: RET-01 | B13: 2. Retention of prompts, outputs and logs | C13: List the retention period separately for prompts, outputs, uploaded files, conversation history, embeddings or vector stores, caches and backups. | D13: Each data type usually lives in a different store with its own deletion clock. | E13: A retention schedule by data type, referenced in the DPA or security documentation. | F13: Yes | G13: Retention schedule RS-2026 | H13: 2 | I13: 3 | J13: No | K13: =IF(OR(A13="",F13="N/A",H13=""),"",H13*I13) -> 6 | L13: =IF(OR(A13="",F13="N/A",H13=""),"",3*I13) -> 9 | M13: =IF(AND(J13="Yes",OR(F13="No",AND(F13<>"N/A",H13<>"",N(H13)<=1))),"RED FLAG","") | N13: =IF(A13="","",IF(F13="","Awaiting answer",IF(AND(F13<>"N/A",H13=""),"Score it",IF(AND(OR(F13="Yes",F13="Partial"),G13=""),"Evidence missing",IF(AND(F13="N/A",J13="Yes"),"Critical N/A - justify",IF(AND(F13="Yes",H13<>"",N(H13)<=1),"Claim not supported","OK")))))) -> OK
A14: RET-02 | B14: 2. Retention of prompts, outputs and logs | C14: Does the model provider keep prompts or outputs (for example for abuse monitoring), for how long, and is a zero-data-retention or equivalent arrangement contracted for our tenant? | D14: Provider-side retention creates a second copy of your data that you do not control. | E14: Model provider retention terms and written confirmation of the arrangement that applies to us. | F14: Partial | G14: Vendor letter ZDR-03 (pending countersign) | H14: 2 | I14: 3 | J14: Yes | K14: =IF(OR(A14="",F14="N/A",H14=""),"",H14*I14) -> 6 | L14: =IF(OR(A14="",F14="N/A",H14=""),"",3*I14) -> 9 | M14: =IF(AND(J14="Yes",OR(F14="No",AND(F14<>"N/A",H14<>"",N(H14)<=1))),"RED FLAG","") | N14: =IF(A14="","",IF(F14="","Awaiting answer",IF(AND(F14<>"N/A",H14=""),"Score it",IF(AND(OR(F14="Yes",F14="Partial"),G14=""),"Evidence missing",IF(AND(F14="N/A",J14="Yes"),"Critical N/A - justify",IF(AND(F14="Yes",H14<>"",N(H14)<=1),"Claim not supported","OK")))))) -> OK
A15: RET-03 | B15: 2. Retention of prompts, outputs and logs | C15: Can our admins set retention and delete individual conversations or all data on demand, and within what period are backups purged? | D15: You need to act on deletion requests and your own retention rules without raising a ticket. | E15: Admin console documentation and a stated deletion period that includes backups. | F15: Yes | G15: Admin guide p.20 | H15: 3 | I15: 2 | J15: No | K15: =IF(OR(A15="",F15="N/A",H15=""),"",H15*I15) -> 6 | L15: =IF(OR(A15="",F15="N/A",H15=""),"",3*I15) -> 6 | M15: =IF(AND(J15="Yes",OR(F15="No",AND(F15<>"N/A",H15<>"",N(H15)<=1))),"RED FLAG","") | N15: =IF(A15="","",IF(F15="","Awaiting answer",IF(AND(F15<>"N/A",H15=""),"Score it",IF(AND(OR(F15="Yes",F15="Partial"),G15=""),"Evidence missing",IF(AND(F15="N/A",J15="Yes"),"Critical N/A - justify",IF(AND(F15="Yes",H15<>"",N(H15)<=1),"Claim not supported","OK")))))) -> OK
A16: RET-04 | B16: 2. Retention of prompts, outputs and logs | C16: Do prompts or outputs appear in the vendor's application logs, debugging tools or third-party observability services, and how are they redacted and retained there? | D16: Operational logs are where prompt content often stays longest and least controlled. | E16: Logging data-flow description, redaction approach, and the observability vendor on the sub-processor list. | F16: Partial | G16: Security whitepaper s.6 | H16: 1 | I16: 2 | J16: No | K16: =IF(OR(A16="",F16="N/A",H16=""),"",H16*I16) -> 2 | L16: =IF(OR(A16="",F16="N/A",H16=""),"",3*I16) -> 6 | M16: =IF(AND(J16="Yes",OR(F16="No",AND(F16<>"N/A",H16<>"",N(H16)<=1))),"RED FLAG","") | N16: =IF(A16="","",IF(F16="","Awaiting answer",IF(AND(F16<>"N/A",H16=""),"Score it",IF(AND(OR(F16="Yes",F16="Partial"),G16=""),"Evidence missing",IF(AND(F16="N/A",J16="Yes"),"Critical N/A - justify",IF(AND(F16="Yes",H16<>"",N(H16)<=1),"Claim not supported","OK")))))) -> OK
A17: RET-05 | B17: 2. Retention of prompts, outputs and logs | C17: Are cached copies (prompt caching, semantic caches, search indexes) covered by the same retention and deletion commitments? | D17: Caches and indexes are easily left out of deletion processes. | E17: Statement that caches are in scope of the retention schedule, with their time-to-live. | F17: Yes | G17: Retention schedule RS-2026 row 9 | H17: 2 | I17: 1 | J17: No | K17: =IF(OR(A17="",F17="N/A",H17=""),"",H17*I17) -> 2 | L17: =IF(OR(A17="",F17="N/A",H17=""),"",3*I17) -> 3 | M17: =IF(AND(J17="Yes",OR(F17="No",AND(F17<>"N/A",H17<>"",N(H17)<=1))),"RED FLAG","") | N17: =IF(A17="","",IF(F17="","Awaiting answer",IF(AND(F17<>"N/A",H17=""),"Score it",IF(AND(OR(F17="Yes",F17="Partial"),G17=""),"Evidence missing",IF(AND(F17="N/A",J17="Yes"),"Critical N/A - justify",IF(AND(F17="Yes",H17<>"",N(H17)<=1),"Claim not supported","OK")))))) -> OK
A18: 3. Data residency and sub-processors (including the model provider)
A19: RES-01 | B19: 3. Data residency and sub-processors (including the model provider) | C19: Name every model provider behind the product, per feature, including any fallback or routing providers used when the primary is unavailable. | D19: The model provider is your fourth party and receives your data; a hidden fallback is a hidden transfer. | E19: Sub-processor list naming each model provider, its purpose, data processed and region. | F19: Yes | G19: Sub-processor list v14 | H19: 3 | I19: 3 | J19: Yes | K19: =IF(OR(A19="",F19="N/A",H19=""),"",H19*I19) -> 9 | L19: =IF(OR(A19="",F19="N/A",H19=""),"",3*I19) -> 9 | M19: =IF(AND(J19="Yes",OR(F19="No",AND(F19<>"N/A",H19<>"",N(H19)<=1))),"RED FLAG","") | N19: =IF(A19="","",IF(F19="","Awaiting answer",IF(AND(F19<>"N/A",H19=""),"Score it",IF(AND(OR(F19="Yes",F19="Partial"),G19=""),"Evidence missing",IF(AND(F19="N/A",J19="Yes"),"Critical N/A - justify",IF(AND(F19="Yes",H19<>"",N(H19)<=1),"Claim not supported","OK")))))) -> OK
A20: RES-02 | B20: 3. Data residency and sub-processors (including the model provider) | C20: In which countries or regions is our data stored and processed - including model inference, support access and backups - and can we contractually pin it to a region? | D20: Inference and support often run outside the region where data is stored. | E20: Region documentation per data type and processing step, plus a residency clause in the contract. | F20: Partial | G20: Data residency page; no clause yet | H20: 2 | I20: 3 | J20: No | K20: =IF(OR(A20="",F20="N/A",H20=""),"",H20*I20) -> 6 | L20: =IF(OR(A20="",F20="N/A",H20=""),"",3*I20) -> 9 | M20: =IF(AND(J20="Yes",OR(F20="No",AND(F20<>"N/A",H20<>"",N(H20)<=1))),"RED FLAG","") | N20: =IF(A20="","",IF(F20="","Awaiting answer",IF(AND(F20<>"N/A",H20=""),"Score it",IF(AND(OR(F20="Yes",F20="Partial"),G20=""),"Evidence missing",IF(AND(F20="N/A",J20="Yes"),"Critical N/A - justify",IF(AND(F20="Yes",H20<>"",N(H20)<=1),"Claim not supported","OK")))))) -> OK
A21: RES-03 | B21: 3. Data residency and sub-processors (including the model provider) | C21: What transfer mechanism covers each cross-border transfer of personal data (for example standard contractual clauses with a transfer assessment, or an adequacy route)? | D21: Personal data sent abroad needs a lawful transfer mechanism under GDPR and similar laws. | E21: DPA transfer annex, the executed clauses, and a summary of the transfer risk assessment. | F21: Yes | G21: DPA Annex III | H21: 3 | I21: 2 | J21: No | K21: =IF(OR(A21="",F21="N/A",H21=""),"",H21*I21) -> 6 | L21: =IF(OR(A21="",F21="N/A",H21=""),"",3*I21) -> 6 | M21: =IF(AND(J21="Yes",OR(F21="No",AND(F21<>"N/A",H21<>"",N(H21)<=1))),"RED FLAG","") | N21: =IF(A21="","",IF(F21="","Awaiting answer",IF(AND(F21<>"N/A",H21=""),"Score it",IF(AND(OR(F21="Yes",F21="Partial"),G21=""),"Evidence missing",IF(AND(F21="N/A",J21="Yes"),"Critical N/A - justify",IF(AND(F21="Yes",H21<>"",N(H21)<=1),"Claim not supported","OK")))))) -> OK
A22: RES-04 | B22: 3. Data residency and sub-processors (including the model provider) | C22: Will we receive advance written notice of a new sub-processor, including a new or changed model provider, with a right to object or terminate? | D22: A model provider switch changes where your data goes and how outputs behave. | E22: DPA clause stating the notice period, notification channel and objection right. | F22: Yes | G22: DPA cl. 9.2 (30 days) | H22: 3 | I22: 3 | J22: No | K22: =IF(OR(A22="",F22="N/A",H22=""),"",H22*I22) -> 9 | L22: =IF(OR(A22="",F22="N/A",H22=""),"",3*I22) -> 9 | M22: =IF(AND(J22="Yes",OR(F22="No",AND(F22<>"N/A",H22<>"",N(H22)<=1))),"RED FLAG","") | N22: =IF(A22="","",IF(F22="","Awaiting answer",IF(AND(F22<>"N/A",H22=""),"Score it",IF(AND(OR(F22="Yes",F22="Partial"),G22=""),"Evidence missing",IF(AND(F22="N/A",J22="Yes"),"Critical N/A - justify",IF(AND(F22="Yes",H22<>"",N(H22)<=1),"Claim not supported","OK")))))) -> OK
A23: RES-05 | B23: 3. Data residency and sub-processors (including the model provider) | C23: How does the vendor assess and monitor its own sub-processors, and are they bound by terms at least as protective as ours? | D23: Your risk extends to every party the vendor relies on. | E23: Vendor's third-party risk procedure and evidence of flow-down terms. | F23: Partial | G23: TPRM procedure summary | H23: 2 | I23: 2 | J23: No | K23: =IF(OR(A23="",F23="N/A",H23=""),"",H23*I23) -> 4 | L23: =IF(OR(A23="",F23="N/A",H23=""),"",3*I23) -> 6 | M23: =IF(AND(J23="Yes",OR(F23="No",AND(F23<>"N/A",H23<>"",N(H23)<=1))),"RED FLAG","") | N23: =IF(A23="","",IF(F23="","Awaiting answer",IF(AND(F23<>"N/A",H23=""),"Score it",IF(AND(OR(F23="Yes",F23="Partial"),G23=""),"Evidence missing",IF(AND(F23="N/A",J23="Yes"),"Critical N/A - justify",IF(AND(F23="Yes",H23<>"",N(H23)<=1),"Claim not supported","OK")))))) -> OK
A24: 4. Security controls and certifications
A25: SEC-01 | B25: 4. Security controls and certifications | C25: Is there at least one current independent assurance - an ISO/IEC 27001 certificate or a SOC 2 Type II report - whose scope explicitly includes this AI product and its hosting? | D25: A logo on a website proves nothing if the AI product sits outside the audited scope. | E25: Certificate or report with the scope statement or system description naming the product. | F25: Yes | G25: SOC 2 Type II report (2025-10 to 2026-09) | H25: 3 | I25: 3 | J25: Yes | K25: =IF(OR(A25="",F25="N/A",H25=""),"",H25*I25) -> 9 | L25: =IF(OR(A25="",F25="N/A",H25=""),"",3*I25) -> 9 | M25: =IF(AND(J25="Yes",OR(F25="No",AND(F25<>"N/A",H25<>"",N(H25)<=1))),"RED FLAG","") | N25: =IF(A25="","",IF(F25="","Awaiting answer",IF(AND(F25<>"N/A",H25=""),"Score it",IF(AND(OR(F25="Yes",F25="Partial"),G25=""),"Evidence missing",IF(AND(F25="N/A",J25="Yes"),"Critical N/A - justify",IF(AND(F25="Yes",H25<>"",N(H25)<=1),"Claim not supported","OK")))))) -> OK
A26: SEC-02 | B26: 4. Security controls and certifications | C26: ISO/IEC 27001: provide the certificate number, certification body, accreditation, expiry date and scope statement. Does the Statement of Applicability cover the AI services? | D26: Scope and accreditation decide whether the certificate is relevant and verifiable. | E26: Certificate plus scope, checked on the certification body's or accreditation register. | F26: Yes | G26: Cert no. on CB register, checked 2026-10-14 | H26: 3 | I26: 2 | J26: No | K26: =IF(OR(A26="",F26="N/A",H26=""),"",H26*I26) -> 6 | L26: =IF(OR(A26="",F26="N/A",H26=""),"",3*I26) -> 6 | M26: =IF(AND(J26="Yes",OR(F26="No",AND(F26<>"N/A",H26<>"",N(H26)<=1))),"RED FLAG","") | N26: =IF(A26="","",IF(F26="","Awaiting answer",IF(AND(F26<>"N/A",H26=""),"Score it",IF(AND(OR(F26="Yes",F26="Partial"),G26=""),"Evidence missing",IF(AND(F26="N/A",J26="Yes"),"Critical N/A - justify",IF(AND(F26="Yes",H26<>"",N(H26)<=1),"Claim not supported","OK")))))) -> OK
A27: SEC-03 | B27: 4. Security controls and certifications | C27: SOC 2 Type II: what is the report period, which Trust Services Criteria are covered, is the model provider carved out or included, and were there exceptions or a qualified opinion? | D27: Ask for scope and period, not the logo; carve-outs move testing back onto you. | E27: Full report under NDA, the list of complementary user entity controls, and a bridge letter for any gap since period end. | F27: Partial | G27: SOC 2 report s.3; model provider carved out | H27: 2 | I27: 3 | J27: No | K27: =IF(OR(A27="",F27="N/A",H27=""),"",H27*I27) -> 6 | L27: =IF(OR(A27="",F27="N/A",H27=""),"",3*I27) -> 9 | M27: =IF(AND(J27="Yes",OR(F27="No",AND(F27<>"N/A",H27<>"",N(H27)<=1))),"RED FLAG","") | N27: =IF(A27="","",IF(F27="","Awaiting answer",IF(AND(F27<>"N/A",H27=""),"Score it",IF(AND(OR(F27="Yes",F27="Partial"),G27=""),"Evidence missing",IF(AND(F27="N/A",J27="Yes"),"Critical N/A - justify",IF(AND(F27="Yes",H27<>"",N(H27)<=1),"Claim not supported","OK")))))) -> OK
A28: SEC-04 | B28: 4. Security controls and certifications | C28: Does the vendor hold, or plan, ISO/IEC 42001 certification for its AI management system? Give scope, certification body and status. | D28: Shows AI governance is run as a managed system, not only IT security. | E28: Certificate and scope, or a roadmap with a target date and the chosen certification body. | F28: Partial | G28: Roadmap slide: target 2027 | H28: 1 | I28: 2 | J28: No | K28: =IF(OR(A28="",F28="N/A",H28=""),"",H28*I28) -> 2 | L28: =IF(OR(A28="",F28="N/A",H28=""),"",3*I28) -> 6 | M28: =IF(AND(J28="Yes",OR(F28="No",AND(F28<>"N/A",H28<>"",N(H28)<=1))),"RED FLAG","") | N28: =IF(A28="","",IF(F28="","Awaiting answer",IF(AND(F28<>"N/A",H28=""),"Score it",IF(AND(OR(F28="Yes",F28="Partial"),G28=""),"Evidence missing",IF(AND(F28="N/A",J28="Yes"),"Critical N/A - justify",IF(AND(F28="Yes",H28<>"",N(H28)<=1),"Claim not supported","OK")))))) -> OK
A29: SEC-05 | B29: 4. Security controls and certifications | C29: How are our prompts, context, files, vector stores and any fine-tuned models isolated from other customers' data? | D29: Weak tenant isolation in AI pipelines can expose one customer's data in another's answers. | E29: Architecture description of tenant isolation and test evidence (for example penetration test scope). | F29: Yes | G29: Architecture doc A-4; pen test 2026-06 | H29: 2 | I29: 3 | J29: Yes | K29: =IF(OR(A29="",F29="N/A",H29=""),"",H29*I29) -> 6 | L29: =IF(OR(A29="",F29="N/A",H29=""),"",3*I29) -> 9 | M29: =IF(AND(J29="Yes",OR(F29="No",AND(F29<>"N/A",H29<>"",N(H29)<=1))),"RED FLAG","") | N29: =IF(A29="","",IF(F29="","Awaiting answer",IF(AND(F29<>"N/A",H29=""),"Score it",IF(AND(OR(F29="Yes",F29="Partial"),G29=""),"Evidence missing",IF(AND(F29="N/A",J29="Yes"),"Critical N/A - justify",IF(AND(F29="Yes",H29<>"",N(H29)<=1),"Claim not supported","OK")))))) -> OK
A30: SEC-06 | B30: 4. Security controls and certifications | C30: Do the AI features support SSO, MFA, SCIM provisioning and role-based access, so we control who can use which AI capability? | D30: AI features that bypass your identity controls become an unmanaged access path. | E30: Admin documentation and a demonstration of role settings for AI features. | F30: Yes | G30: Admin guide p.5 | H30: 3 | I30: 2 | J30: No | K30: =IF(OR(A30="",F30="N/A",H30=""),"",H30*I30) -> 6 | L30: =IF(OR(A30="",F30="N/A",H30=""),"",3*I30) -> 6 | M30: =IF(AND(J30="Yes",OR(F30="No",AND(F30<>"N/A",H30<>"",N(H30)<=1))),"RED FLAG","") | N30: =IF(A30="","",IF(F30="","Awaiting answer",IF(AND(F30<>"N/A",H30=""),"Score it",IF(AND(OR(F30="Yes",F30="Partial"),G30=""),"Evidence missing",IF(AND(F30="N/A",J30="Yes"),"Critical N/A - justify",IF(AND(F30="Yes",H30<>"",N(H30)<=1),"Claim not supported","OK")))))) -> OK
A31: SEC-07 | B31: 4. Security controls and certifications | C31: How is our data encrypted in transit and at rest across the AI pipeline (including vector stores and the model provider), and is customer-managed key support available? | D31: Data copied into new AI stores often misses the encryption applied to the main database. | E31: Encryption and key management description covering every AI data store. | F31: Yes | G31: Security whitepaper s.4 | H31: 2 | I31: 2 | J31: No | K31: =IF(OR(A31="",F31="N/A",H31=""),"",H31*I31) -> 4 | L31: =IF(OR(A31="",F31="N/A",H31=""),"",3*I31) -> 6 | M31: =IF(AND(J31="Yes",OR(F31="No",AND(F31<>"N/A",H31<>"",N(H31)<=1))),"RED FLAG","") | N31: =IF(A31="","",IF(F31="","Awaiting answer",IF(AND(F31<>"N/A",H31=""),"Score it",IF(AND(OR(F31="Yes",F31="Partial"),G31=""),"Evidence missing",IF(AND(F31="N/A",J31="Yes"),"Critical N/A - justify",IF(AND(F31="Yes",H31<>"",N(H31)<=1),"Claim not supported","OK")))))) -> OK
A32: 5. Model change management
A33: CHG-01 | B33: 5. Model change management | C33: Will the vendor notify us in advance of changes to the underlying model, model version, provider, system prompt or safety settings that can change output behaviour - and with how much notice? | D33: Silent model updates can change accuracy, tone and safety overnight without any action by you. | E33: Contract change-notice clause with a notice period, plus a dated customer changelog. | F33: Partial | G33: Changelog only; no contract clause | H33: 1 | I33: 3 | J33: Yes | K33: =IF(OR(A33="",F33="N/A",H33=""),"",H33*I33) -> 3 | L33: =IF(OR(A33="",F33="N/A",H33=""),"",3*I33) -> 9 | M33: =IF(AND(J33="Yes",OR(F33="No",AND(F33<>"N/A",H33<>"",N(H33)<=1))),"RED FLAG","") -> RED FLAG | N33: =IF(A33="","",IF(F33="","Awaiting answer",IF(AND(F33<>"N/A",H33=""),"Score it",IF(AND(OR(F33="Yes",F33="Partial"),G33=""),"Evidence missing",IF(AND(F33="N/A",J33="Yes"),"Critical N/A - justify",IF(AND(F33="Yes",H33<>"",N(H33)<=1),"Claim not supported","OK")))))) -> OK
A34: CHG-02 | B34: 5. Model change management | C34: Can we pin a model version, and how long is a version supported before it is deprecated? | D34: Pinning lets you re-test before behaviour changes reach your users. | E34: Version support and deprecation policy with stated periods. | F34: No | G34: Not offered | H34: 1 | I34: 2 | J34: No | K34: =IF(OR(A34="",F34="N/A",H34=""),"",H34*I34) -> 2 | L34: =IF(OR(A34="",F34="N/A",H34=""),"",3*I34) -> 6 | M34: =IF(AND(J34="Yes",OR(F34="No",AND(F34<>"N/A",H34<>"",N(H34)<=1))),"RED FLAG","") | N34: =IF(A34="","",IF(F34="","Awaiting answer",IF(AND(F34<>"N/A",H34=""),"Score it",IF(AND(OR(F34="Yes",F34="Partial"),G34=""),"Evidence missing",IF(AND(F34="N/A",J34="Yes"),"Critical N/A - justify",IF(AND(F34="Yes",H34<>"",N(H34)<=1),"Claim not supported","OK")))))) -> OK
A35: CHG-03 | B35: 5. Model change management | C35: Does the vendor regression-test accuracy, safety and bias before releasing a model or prompt change, and will it share the results? | D35: Release testing is the vendor's main control against harmful changes. | E35: Release procedure and an example of a pre-release evaluation summary. | F35: Partial | G35: Release procedure summary | H35: 2 | I35: 3 | J35: No | K35: =IF(OR(A35="",F35="N/A",H35=""),"",H35*I35) -> 6 | L35: =IF(OR(A35="",F35="N/A",H35=""),"",3*I35) -> 9 | M35: =IF(AND(J35="Yes",OR(F35="No",AND(F35<>"N/A",H35<>"",N(H35)<=1))),"RED FLAG","") | N35: =IF(A35="","",IF(F35="","Awaiting answer",IF(AND(F35<>"N/A",H35=""),"Score it",IF(AND(OR(F35="Yes",F35="Partial"),G35=""),"Evidence missing",IF(AND(F35="N/A",J35="Yes"),"Critical N/A - justify",IF(AND(F35="Yes",H35<>"",N(H35)<=1),"Claim not supported","OK")))))) -> OK
A36: CHG-04 | B36: 5. Model change management | C36: Can we test a new model version in a sandbox or staging tenant before it reaches production users? | D36: Your own use-case testing catches failures the vendor's generic tests miss. | E36: Description of the preview or staging channel and its timing relative to release. | F36: Yes | G36: Preview channel, 14 days | H36: 2 | I36: 2 | J36: No | K36: =IF(OR(A36="",F36="N/A",H36=""),"",H36*I36) -> 4 | L36: =IF(OR(A36="",F36="N/A",H36=""),"",3*I36) -> 6 | M36: =IF(AND(J36="Yes",OR(F36="No",AND(F36<>"N/A",H36<>"",N(H36)<=1))),"RED FLAG","") | N36: =IF(A36="","",IF(F36="","Awaiting answer",IF(AND(F36<>"N/A",H36=""),"Score it",IF(AND(OR(F36="Yes",F36="Partial"),G36=""),"Evidence missing",IF(AND(F36="N/A",J36="Yes"),"Critical N/A - justify",IF(AND(F36="Yes",H36<>"",N(H36)<=1),"Claim not supported","OK")))))) -> OK
A37: CHG-05 | B37: 5. Model change management | C37: Can we roll back, or opt out of, a model change that degrades our use case? | D37: Without rollback, a bad update leaves you choosing between degraded output and switching it off. | E37: Rollback or opt-out mechanism and its time limits. | F37: No | G37: Not offered | H37: 0 | I37: 1 | J37: No | K37: =IF(OR(A37="",F37="N/A",H37=""),"",H37*I37) -> 0 | L37: =IF(OR(A37="",F37="N/A",H37=""),"",3*I37) -> 3 | M37: =IF(AND(J37="Yes",OR(F37="No",AND(F37<>"N/A",H37<>"",N(H37)<=1))),"RED FLAG","") | N37: =IF(A37="","",IF(F37="","Awaiting answer",IF(AND(F37<>"N/A",H37=""),"Score it",IF(AND(OR(F37="Yes",F37="Partial"),G37=""),"Evidence missing",IF(AND(F37="N/A",J37="Yes"),"Critical N/A - justify",IF(AND(F37="Yes",H37<>"",N(H37)<=1),"Claim not supported","OK")))))) -> OK
A38: 6. Evaluation and testing
A39: EVL-01 | B39: 6. Evaluation and testing | C39: How is accuracy or quality evaluated for our type of use case - methods, datasets, metrics and the latest results - and will you share them? | D39: Generic benchmark claims say little about performance on your tasks. | E39: Evaluation report with method, test data description, metrics and date. | F39: Partial | G39: Eval summary 2026-Q3 | H39: 2 | I39: 3 | J39: No | K39: =IF(OR(A39="",F39="N/A",H39=""),"",H39*I39) -> 6 | L39: =IF(OR(A39="",F39="N/A",H39=""),"",3*I39) -> 9 | M39: =IF(AND(J39="Yes",OR(F39="No",AND(F39<>"N/A",H39<>"",N(H39)<=1))),"RED FLAG","") | N39: =IF(A39="","",IF(F39="","Awaiting answer",IF(AND(F39<>"N/A",H39=""),"Score it",IF(AND(OR(F39="Yes",F39="Partial"),G39=""),"Evidence missing",IF(AND(F39="N/A",J39="Yes"),"Critical N/A - justify",IF(AND(F39="Yes",H39<>"",N(H39)<=1),"Claim not supported","OK")))))) -> OK
A40: EVL-02 | B40: 6. Evaluation and testing | C40: Has the system been tested for bias or unfair outcomes, which characteristics were tested, and what were the results? | D40: Matters most where outputs affect people's access to jobs, credit, services or support. | E40: Bias testing summary with method, characteristics, results and remediation. | F40: Partial | G40: Statement only | H40: 1 | I40: 2 | J40: No | K40: =IF(OR(A40="",F40="N/A",H40=""),"",H40*I40) -> 2 | L40: =IF(OR(A40="",F40="N/A",H40=""),"",3*I40) -> 6 | M40: =IF(AND(J40="Yes",OR(F40="No",AND(F40<>"N/A",H40<>"",N(H40)<=1))),"RED FLAG","") | N40: =IF(A40="","",IF(F40="","Awaiting answer",IF(AND(F40<>"N/A",H40=""),"Score it",IF(AND(OR(F40="Yes",F40="Partial"),G40=""),"Evidence missing",IF(AND(F40="N/A",J40="Yes"),"Critical N/A - justify",IF(AND(F40="Yes",H40<>"",N(H40)<=1),"Claim not supported","OK")))))) -> OK
A41: EVL-03 | B41: 6. Evaluation and testing | C41: Has independent red teaming or adversarial testing of the AI features been performed in the last 12 months, including sensitive-information disclosure and system-prompt leakage? Were high findings fixed? | D41: Adversarial testing finds abuse paths that functional testing does not. | E41: Tester identity, scope, date, finding counts by severity and remediation status. | F41: Yes | G41: Pen test 2026-06 incl. LLM scope | H41: 2 | I41: 3 | J41: No | K41: =IF(OR(A41="",F41="N/A",H41=""),"",H41*I41) -> 6 | L41: =IF(OR(A41="",F41="N/A",H41=""),"",3*I41) -> 9 | M41: =IF(AND(J41="Yes",OR(F41="No",AND(F41<>"N/A",H41<>"",N(H41)<=1))),"RED FLAG","") | N41: =IF(A41="","",IF(F41="","Awaiting answer",IF(AND(F41<>"N/A",H41=""),"Score it",IF(AND(OR(F41="Yes",F41="Partial"),G41=""),"Evidence missing",IF(AND(F41="N/A",J41="Yes"),"Critical N/A - justify",IF(AND(F41="Yes",H41<>"",N(H41)<=1),"Claim not supported","OK")))))) -> OK
A42: EVL-04 | B42: 6. Evaluation and testing | C42: Is the product tested against direct and indirect prompt injection - instructions hidden in documents, emails, web pages, tickets or tool outputs that the AI reads? | D42: Prompt injection (OWASP LLM01:2025) is the leading attack on AI features that read untrusted content. | E42: Test cases, results and the defences in place (input isolation, output checks, permission limits). | F42: Yes | G42: Pen test 2026-06 s.5 | H42: 2 | I42: 3 | J42: Yes | K42: =IF(OR(A42="",F42="N/A",H42=""),"",H42*I42) -> 6 | L42: =IF(OR(A42="",F42="N/A",H42=""),"",3*I42) -> 9 | M42: =IF(AND(J42="Yes",OR(F42="No",AND(F42<>"N/A",H42<>"",N(H42)<=1))),"RED FLAG","") | N42: =IF(A42="","",IF(F42="","Awaiting answer",IF(AND(F42<>"N/A",H42=""),"Score it",IF(AND(OR(F42="Yes",F42="Partial"),G42=""),"Evidence missing",IF(AND(F42="N/A",J42="Yes"),"Critical N/A - justify",IF(AND(F42="Yes",H42<>"",N(H42)<=1),"Claim not supported","OK")))))) -> OK
...

Sheet Scoring Summary
B1: Scoring Summary and Recommendation
B2: By John Bommeraveni Joseph | linkedin.com/in/john-bj | Free every weekday: GRC Made Simple Daily
B5: Section | C5: Questions | D5: Answered | E5: N/A | F5: Scored | G5: Weighted score | H5: Max possible | I5: Score % | J5: Rating | K5: Red flags | L5: Critical questions
B6: 1. Training and model improvement | C6: =COUNTIF(Questionnaire!$B$6:$B$93,B6) -> 5 | D6: =COUNTIFS(Questionnaire!$B$6:$B$93,B6,Questionnaire!$F$6:$F$93,"<>") -> 5 | E6: =COUNTIFS(Questionnaire!$B$6:$B$93,B6,Questionnaire!$F$6:$F$93,"N/A") -> 0 | F6: =COUNTIFS(Questionnaire!$B$6:$B$93,B6,Questionnaire!$K$6:$K$93,">=0") -> 5 | G6: =SUMIFS(Questionnaire!$K$6:$K$93,Questionnaire!$B$6:$B$93,B6) -> 27 | H6: =SUMIFS(Questionnaire!$L$6:$L$93,Questionnaire!$B$6:$B$93,B6) -> 36 | I6: =IF(H6=0,"",G6/H6) -> 0.75 | J6: =IF(I6="","Not scored",IF(I6>=$C$24,"Strong",IF(I6>=$C$25,"Adequate",IF(I6>=$C$26,"Weak","Poor")))) -> Adequate | K6: =COUNTIFS(Questionnaire!$B$6:$B$93,B6,Questionnaire!$M$6:$M$93,"RED FLAG") -> 0 | L6: =COUNTIFS(Questionnaire!$B$6:$B$93,B6,Questionnaire!$J$6:$J$93,"Yes") -> 2
B7: 2. Retention of prompts, outputs and logs | C7: =COUNTIF(Questionnaire!$B$6:$B$93,B7) -> 5 | D7: =COUNTIFS(Questionnaire!$B$6:$B$93,B7,Questionnaire!$F$6:$F$93,"<>") -> 5 | E7: =COUNTIFS(Questionnaire!$B$6:$B$93,B7,Questionnaire!$F$6:$F$93,"N/A") -> 0 | F7: =COUNTIFS(Questionnaire!$B$6:$B$93,B7,Questionnaire!$K$6:$K$93,">=0") -> 5 | G7: =SUMIFS(Questionnaire!$K$6:$K$93,Questionnaire!$B$6:$B$93,B7) -> 22 | H7: =SUMIFS(Questionnaire!$L$6:$L$93,Questionnaire!$B$6:$B$93,B7) -> 33 | I7: =IF(H7=0,"",G7/H7) -> 0.66666667 | J7: =IF(I7="","Not scored",IF(I7>=$C$24,"Strong",IF(I7>=$C$25,"Adequate",IF(I7>=$C$26,"Weak","Poor")))) -> Adequate | K7: =COUNTIFS(Questionnaire!$B$6:$B$93,B7,Questionnaire!$M$6:$M$93,"RED FLAG") -> 0 | L7: =COUNTIFS(Questionnaire!$B$6:$B$93,B7,Questionnaire!$J$6:$J$93,"Yes") -> 1
B8: 3. Data residency and sub-processors (including the model provider) | C8: =COUNTIF(Questionnaire!$B$6:$B$93,B8) -> 5 | D8: =COUNTIFS(Questionnaire!$B$6:$B$93,B8,Questionnaire!$F$6:$F$93,"<>") -> 5 | E8: =COUNTIFS(Questionnaire!$B$6:$B$93,B8,Questionnaire!$F$6:$F$93,"N/A") -> 0 | F8: =COUNTIFS(Questionnaire!$B$6:$B$93,B8,Questionnaire!$K$6:$K$93,">=0") -> 5 | G8: =SUMIFS(Questionnaire!$K$6:$K$93,Questionnaire!$B$6:$B$93,B8) -> 34 | H8: =SUMIFS(Questionnaire!$L$6:$L$93,Questionnaire!$B$6:$B$93,B8) -> 39 | I8: =IF(H8=0,"",G8/H8) -> 0.87179487 | J8: =IF(I8="","Not scored",IF(I8>=$C$24,"Strong",IF(I8>=$C$25,"Adequate",IF(I8>=$C$26,"Weak","Poor")))) -> Strong | K8: =COUNTIFS(Questionnaire!$B$6:$B$93,B8,Questionnaire!$M$6:$M$93,"RED FLAG") -> 0 | L8: =COUNTIFS(Questionnaire!$B$6:$B$93,B8,Questionnaire!$J$6:$J$93,"Yes") -> 1
B9: 4. Security controls and certifications | C9: =COUNTIF(Questionnaire!$B$6:$B$93,B9) -> 7 | D9: =COUNTIFS(Questionnaire!$B$6:$B$93,B9,Questionnaire!$F$6:$F$93,"<>") -> 7 | E9: =COUNTIFS(Questionnaire!$B$6:$B$93,B9,Questionnaire!$F$6:$F$93,"N/A") -> 0 | F9: =COUNTIFS(Questionnaire!$B$6:$B$93,B9,Questionnaire!$K$6:$K$93,">=0") -> 7 | G9: =SUMIFS(Questionnaire!$K$6:$K$93,Questionnaire!$B$6:$B$93,B9) -> 39 | H9: =SUMIFS(Questionnaire!$L$6:$L$93,Questionnaire!$B$6:$B$93,B9) -> 51 | I9: =IF(H9=0,"",G9/H9) -> 0.76470588 | J9: =IF(I9="","Not scored",IF(I9>=$C$24,"Strong",IF(I9>=$C$25,"Adequate",IF(I9>=$C$26,"Weak","Poor")))) -> Adequate | K9: =COUNTIFS(Questionnaire!$B$6:$B$93,B9,Questionnaire!$M$6:$M$93,"RED FLAG") -> 0 | L9: =COUNTIFS(Questionnaire!$B$6:$B$93,B9,Questionnaire!$J$6:$J$93,"Yes") -> 2
B10: 5. Model change management | C10: =COUNTIF(Questionnaire!$B$6:$B$93,B10) -> 5 | D10: =COUNTIFS(Questionnaire!$B$6:$B$93,B10,Questionnaire!$F$6:$F$93,"<>") -> 5 | E10: =COUNTIFS(Questionnaire!$B$6:$B$93,B10,Questionnaire!$F$6:$F$93,"N/A") -> 0 | F10: =COUNTIFS(Questionnaire!$B$6:$B$93,B10,Questionnaire!$K$6:$K$93,">=0") -> 5 | G10: =SUMIFS(Questionnaire!$K$6:$K$93,Questionnaire!$B$6:$B$93,B10) -> 15 | H10: =SUMIFS(Questionnaire!$L$6:$L$93,Questionnaire!$B$6:$B$93,B10) -> 33 | I10: =IF(H10=0,"",G10/H10) -> 0.45454545 | J10: =IF(I10="","Not scored",IF(I10>=$C$24,"Strong",IF(I10>=$C$25,"Adequate",IF(I10>=$C$26,"Weak","Poor")))) -> Poor | K10: =COUNTIFS(Questionnaire!$B$6:$B$93,B10,Questionnaire!$M$6:$M$93,"RED FLAG") -> 1 | L10: =COUNTIFS(Questionnaire!$B$6:$B$93,B10,Questionnaire!$J$6:$J$93,"Yes") -> 1
B11: 6. Evaluation and testing | C11: =COUNTIF(Questionnaire!$B$6:$B$93,B11) -> 6 | D11: =COUNTIFS(Questionnaire!$B$6:$B$93,B11,Questionnaire!$F$6:$F$93,"<>") -> 6 | E11: =COUNTIFS(Questionnaire!$B$6:$B$93,B11,Questionnaire!$F$6:$F$93,"N/A") -> 0 | F11: =COUNTIFS(Questionnaire!$B$6:$B$93,B11,Questionnaire!$K$6:$K$93,">=0") -> 6 | G11: =SUMIFS(Questionnaire!$K$6:$K$93,Questionnaire!$B$6:$B$93,B11) -> 30 | H11: =SUMIFS(Questionnaire!$L$6:$L$93,Questionnaire!$B$6:$B$93,B11) -> 45 | I11: =IF(H11=0,"",G11/H11) -> 0.66666667 | J11: =IF(I11="","Not scored",IF(I11>=$C$24,"Strong",IF(I11>=$C$25,"Adequate",IF(I11>=$C$26,"Weak","Poor")))) -> Adequate | K11: =COUNTIFS(Questionnaire!$B$6:$B$93,B11,Questionnaire!$M$6:$M$93,"RED FLAG") -> 0 | L11: =COUNTIFS(Questionnaire!$B$6:$B$93,B11,Questionnaire!$J$6:$J$93,"Yes") -> 1
B12: 7. Agent and tool permissions (excessive agency) | C12: =COUNTIF(Questionnaire!$B$6:$B$93,B12) -> 6 | D12: =COUNTIFS(Questionnaire!$B$6:$B$93,B12,Questionnaire!$F$6:$F$93,"<>") -> 6 | E12: =COUNTIFS(Questionnaire!$B$6:$B$93,B12,Questionnaire!$F$6:$F$93,"N/A") -> 0 | F12: =COUNTIFS(Questionnaire!$B$6:$B$93,B12,Questionnaire!$K$6:$K$93,">=0") -> 6 | G12: =SUMIFS(Questionnaire!$K$6:$K$93,Questionnaire!$B$6:$B$93,B12) -> 38 | H12: =SUMIFS(Questionnaire!$L$6:$L$93,Questionnaire!$B$6:$B$93,B12) -> 45 | I12: =IF(H12=0,"",G12/H12) -> 0.84444444 | J12: =IF(I12="","Not scored",IF(I12>=$C$24,"Strong",IF(I12>=$C$25,"Adequate",IF(I12>=$C$26,"Weak","Poor")))) -> Strong | K12: =COUNTIFS(Questionnaire!$B$6:$B$93,B12,Questionnaire!$M$6:$M$93,"RED FLAG") -> 0 | L12: =COUNTIFS(Questionnaire!$B$6:$B$93,B12,Questionnaire!$J$6:$J$93,"Yes") -> 2
B13: 8. Output handling and hallucination controls | C13: =COUNTIF(Questionnaire!$B$6:$B$93,B13) -> 5 | D13: =COUNTIFS(Questionnaire!$B$6:$B$93,B13,Questionnaire!$F$6:$F$93,"<>") -> 5 | E13: =COUNTIFS(Questionnaire!$B$6:$B$93,B13,Questionnaire!$F$6:$F$93,"N/A") -> 0 | F13: =COUNTIFS(Questionnaire!$B$6:$B$93,B13,Questionnaire!$K$6:$K$93,">=0") -> 5 | G13: =SUMIFS(Questionnaire!$K$6:$K$93,Questionnaire!$B$6:$B$93,B13) -> 27 | H13: =SUMIFS(Questionnaire!$L$6:$L$93,Questionnaire!$B$6:$B$93,B13) -> 36 | I13: =IF(H13=0,"",G13/H13) -> 0.75 | J13: =IF(I13="","Not scored",IF(I13>=$C$24,"Strong",IF(I13>=$C$25,"Adequate",IF(I13>=$C$26,"Weak","Poor")))) -> Adequate | K13: =COUNTIFS(Questionnaire!$B$6:$B$93,B13,Questionnaire!$M$6:$M$93,"RED FLAG") -> 0 | L13: =COUNTIFS(Questionnaire!$B$6:$B$93,B13,Questionnaire!$J$6:$J$93,"Yes") -> 1
B14: 9. Human oversight | C14: =COUNTIF(Questionnaire!$B$6:$B$93,B14) -> 4 | D14: =COUNTIFS(Questionnaire!$B$6:$B$93,B14,Questionnaire!$F$6:$F$93,"<>") -> 4 | E14: =COUNTIFS(Questionnaire!$B$6:$B$93,B14,Questionnaire!$F$6:$F$93,"N/A") -> 0 | F14: =COUNTIFS(Questionnaire!$B$6:$B$93,B14,Questionnaire!$K$6:$K$93,">=0") -> 4 | G14: =SUMIFS(Questionnaire!$K$6:$K$93,Questionnaire!$B$6:$B$93,B14) -> 26 | H14: =SUMIFS(Questionnaire!$L$6:$L$93,Questionnaire!$B$6:$B$93,B14) -> 30 | I14: =IF(H14=0,"",G14/H14) -> 0.86666667 | J14: =IF(I14="","Not scored",IF(I14>=$C$24,"Strong",IF(I14>=$C$25,"Adequate",IF(I14>=$C$26,"Weak","Poor")))) -> Strong | K14: =COUNTIFS(Questionnaire!$B$6:$B$93,B14,Questionnaire!$M$6:$M$93,"RED FLAG") -> 0 | L14: =COUNTIFS(Questionnaire!$B$6:$B$93,B14,Questionnaire!$J$6:$J$93,"Yes") -> 1
B15: 10. Logging and audit trail (customer-accessible) | C15: =COUNTIF(Questionnaire!$B$6:$B$93,B15) -> 5 | D15: =COUNTIFS(Questionnaire!$B$6:$B$93,B15,Questionnaire!$F$6:$F$93,"<>") -> 5 | E15: =COUNTIFS(Questionnaire!$B$6:$B$93,B15,Questionnaire!$F$6:$F$93,"N/A") -> 0 | F15: =COUNTIFS(Questionnaire!$B$6:$B$93,B15,Questionnaire!$K$6:$K$93,">=0") -> 5 | G15: =SUMIFS(Questionnaire!$K$6:$K$93,Questionnaire!$B$6:$B$93,B15) -> 21 | H15: =SUMIFS(Questionnaire!$L$6:$L$93,Questionnaire!$B$6:$B$93,B15) -> 30 | I15: =IF(H15=0,"",G15/H15) -> 0.7 | J15: =IF(I15="","Not scored",IF(I15>=$C$24,"Strong",IF(I15>=$C$25,"Adequate",IF(I15>=$C$26,"Weak","Poor")))) -> Adequate | K15: =COUNTIFS(Questionnaire!$B$6:$B$93,B15,Questionnaire!$M$6:$M$93,"RED FLAG") -> 0 | L15: =COUNTIFS(Questionnaire!$B$6:$B$93,B15,Questionnaire!$J$6:$J$93,"Yes") -> 1
B16: 11. Incident response and AI-incident notification | C16: =COUNTIF(Questionnaire!$B$6:$B$93,B16) -> 5 | D16: =COUNTIFS(Questionnaire!$B$6:$B$93,B16,Questionnaire!$F$6:$F$93,"<>") -> 5 | E16: =COUNTIFS(Questionnaire!$B$6:$B$93,B16,Questionnaire!$F$6:$F$93,"N/A") -> 0 | F16: =COUNTIFS(Questionnaire!$B$6:$B$93,B16,Questionnaire!$K$6:$K$93,">=0") -> 5 | G16: =SUMIFS(Questionnaire!$K$6:$K$93,Questionnaire!$B$6:$B$93,B16) -> 26 | H16: =SUMIFS(Questionnaire!$L$6:$L$93,Questionnaire!$B$6:$B$93,B16) -> 36 | I16: =IF(H16=0,"",G16/H16) -> 0.72222222 | J16: =IF(I16="","Not scored",IF(I16>=$C$24,"Strong",IF(I16>=$C$25,"Adequate",IF(I16>=$C$26,"Weak","Poor")))) -> Adequate | K16: =COUNTIFS(Questionnaire!$B$6:$B$93,B16,Questionnaire!$M$6:$M$93,"RED FLAG") -> 0 | L16: =COUNTIFS(Questionnaire!$B$6:$B$93,B16,Questionnaire!$J$6:$J$93,"Yes") -> 1
B17: 12. Regulatory position (EU AI Act, GDPR, DPDP) | C17: =COUNTIF(Questionnaire!$B$6:$B$93,B17) -> 7 | D17: =COUNTIFS(Questionnaire!$B$6:$B$93,B17,Questionnaire!$F$6:$F$93,"<>") -> 7 | E17: =COUNTIFS(Questionnaire!$B$6:$B$93,B17,Questionnaire!$F$6:$F$93,"N/A") -> 1 | F17: =COUNTIFS(Questionnaire!$B$6:$B$93,B17,Questionnaire!$K$6:$K$93,">=0") -> 6 | G17: =SUMIFS(Questionnaire!$K$6:$K$93,Questionnaire!$B$6:$B$93,B17) -> 33 | H17: =SUMIFS(Questionnaire!$L$6:$L$93,Questionnaire!$B$6:$B$93,B17) -> 42 | I17: =IF(H17=0,"",G17/H17) -> 0.78571429 | J17: =IF(I17="","Not scored",IF(I17>=$C$24,"Strong",IF(I17>=$C$25,"Adequate",IF(I17>=$C$26,"Weak","Poor")))) -> Adequate | K17: =COUNTIFS(Questionnaire!$B$6:$B$93,B17,Questionnaire!$M$6:$M$93,"RED FLAG") -> 0 | L17: =COUNTIFS(Questionnaire!$B$6:$B$93,B17,Questionnaire!$J$6:$J$93,"Yes") -> 1
... B19: 14. Continuity and exit | C19: =COUNTIF(Questionnaire!$B$6:$B$93,B19) -> 5 | D19: =COUNTIFS(Questionnaire!$B$6:$B$93,B19,Questionnaire!$F$6:$F$93,"<>") -> 5 | E19: =COUNTIFS(Questionnaire!$B$6:$B$93,B19,Questionnaire!$F$6:$F$93,"N/A") -> 0 | F19: =COUNTIFS(Questionnaire!$B$6:$B$93,B19,Questionnaire!$K$6:$K$93,">=0") -> 5 | G19: =SUMIFS(Questionnaire!$K$6:$K$93,Questionnaire!$B$6:$B$93,B19) -> 23 | H19: =SUMIFS(Questionnaire!$L$6:$L$93,Questionnaire!$B$6:$B$93,B19) -> 33 | I19: =IF(H19=0,"",G19/H19) -> 0.6969697 | J19: =IF(I19="","Not scored",IF(I19>=$C$24,"Strong",IF(I19>=$C$25,"Adequate",IF(I19>=$C$26,"Weak","Poor")))) -> Adequate | K19: =COUNTIFS(Questionnaire!$B$6:$B$93,B19,Questionnaire!$M$6:$M$93,"RED FLAG") -> 0 | L19: =COUNTIFS(Questionnaire!$B$6:$B$93,B19,Questionnaire!$J$6:$J$93,"Yes") -> 1
B20: Overall | C20: =SUM(C6:C19) -> 74 | D20: =SUM(D6:D19) -> 74 | E20: =SUM(E6:E19) -> 1 | F20: =SUM(F6:F19) -> 73 | G20: =SUM(G6:G19) -> 381 | H20: =SUM(H6:H19) -> 516 | I20: =IF(H20=0,"",G20/H20) -> 0.73837209 | J20: =IF(I20="","Not scored",IF(I20>=$C$24,"Strong",IF(I20>=$C$25,"Adequate",IF(I20>=$C$26,"Weak","Poor")))) -> Adequate | K20: =SUM(K6:K19) -> 1 | L20: =SUM(L6:L19) -> 16
B23: Thresholds (edit the yellow cells to match your third-party risk policy) | E23: Result
B24: Rating 'Strong' - score at or above | C24: 0.8 | E24: Overall score | J24: =I20 -> 0.73837209
B25: Rating 'Adequate' - score at or above | C25: 0.65 | E25: Overall rating | J25: =J20 -> Adequate
B26: Rating 'Weak' - score at or above (below this = 'Poor') | C26: 0.5 | E26: Red flags (critical questions answered No or scored 0-1) | J26: =K20 -> 1
B27: Approve - overall score at or above | C27: 0.8 | E27: Lowest section score | J27: =IF(COUNT(I6:I19)=0,"",MIN(I6:I19)) -> 0.45454545
B28: Approve - every section at or above | C28: 0.65 | E28: Questions not yet answered or scored | J28: =COUNTIF(Questionnaire!$N$6:$N$93,"Awaiting answer")+COUNTIF(Questionnaire!$N$6:$N$93,"Score it") -> 0
B29: Approve with conditions - overall score at or above | C29: 0.65 | E29: Recommendation on the scores so far | J29: =IF($J$24="","Not scored",IF(OR($J$26>=$C$31,$J$24<$C$30),"Reject",IF(OR($J$26>0,$J$24<$C$29),"Escalate",IF(AND($J$24>=$C$27,$J$27>=$C$28),"Approve","Approve with conditions")))) -> Escalate
B30: Reject - overall score below | C30: 0.5 | E30: RECOMMENDATION | J30: =IF($J$24="","Not scored",IF($J$28>0,"Incomplete - finish answers and scoring",$J$29)) -> Escalate
B31: Reject - red flags at or above | C31: 3
B33: How the recommendation is decided (rules are applied top to bottom; the first that matches wins)
B34: Reject - red flags at or above the Reject red-flag threshold, OR overall score below the Reject threshold.
B35: Escalate - at least one red flag, OR overall score below the 'Approve with conditions' threshold. The approver decides, with documented compensating controls or risk acceptance.
B36: Approve - overall score at or above the Approve threshold AND every section at or above the section minimum (and no red flags).
B37: Approve with conditions - everything else: no red flags and overall score at or above the conditions threshold. Track each condition on the Follow-up Tracker and in the contract.
B38: While any question is still awaiting an answer or a score, the RECOMMENDATION shows 'Incomplete'; the row above it shows where the scores so far point.
B39: Score % = sum of (score x weight) / sum of (3 x weight) over answered, scored questions. N/A answers are excluded from both.

Sheet Follow-up Tracker
B1: Follow-up Tracker
B2: By John Bommeraveni Joseph | linkedin.com/in/john-bj | Free every weekday: GRC Made Simple Daily
A5: FU ID | B5: Question ID | C5: Section | D5: Question | E5: Gap or issue found | F5: Condition or action required | G5: Type | H5: Our owner | I5: Vendor contact | J5: Raised | K5: Due | L5: Status | M5: Closed on | N5: Blocks approval? | O5: Overdue? | P5: Days open
A6: FU-001 | B6: CHG-01 | C6: =IF(B6="","",IFERROR(INDEX(Questionnaire!$B$6:$B$93,MATCH(B6,Questionnaire!$A$6:$A$93,0)),"ID not in questionnaire")) -> 5. Model change management | D6: =IF(B6="","",IFERROR(INDEX(Questionnaire!$C$6:$C$93,MATCH(B6,Questionnaire!$A$6:$A$93,0)),"")) -> Will the vendor notify us in advance of changes to the underlying model, model version, provider, system prompt or safety settings that can change output behaviour - and with how much notice? | E6: No contractual notice of model, provider or system-prompt changes; changelog only | F6: Add a clause: 30 days' written notice of material model or provider changes, with right to terminate | G6: Contract change | H6: Procurement lead | I6: Vendor account manager | J6: 46315 | K6: 46356 | L6: Open | N6: Yes | O6: =IF(OR(K6="",L6="Closed",L6="Risk accepted"),"",IF(K6<TODAY(),"OVERDUE","")) | P6: =IF(J6="","",IF(M6<>"",M6-J6,TODAY()-J6)) -> 7
A7: FU-002 | B7: RET-02 | C7: =IF(B7="","",IFERROR(INDEX(Questionnaire!$B$6:$B$93,MATCH(B7,Questionnaire!$A$6:$A$93,0)),"ID not in questionnaire")) -> 2. Retention of prompts, outputs and logs | D7: =IF(B7="","",IFERROR(INDEX(Questionnaire!$C$6:$C$93,MATCH(B7,Questionnaire!$A$6:$A$93,0)),"")) -> Does the model provider keep prompts or outputs (for example for abuse monitoring), for how long, and is a zero-data-retention or equivalent arrangement contracted for our tenant? | E7: Zero-data-retention arrangement with the model provider not yet countersigned | F7: Obtain countersigned confirmation before go-live | G7: Evidence requested | H7: A. Reviewer | I7: Vendor security team | J7: 46301 | K7: 46319 | L7: In progress | N7: Yes | O7: =IF(OR(K7="",L7="Closed",L7="Risk accepted"),"",IF(K7<TODAY(),"OVERDUE","")) -> OVERDUE | P7: =IF(J7="","",IF(M7<>"",M7-J7,TODAY()-J7)) -> 21
C8: =IF(B8="","",IFERROR(INDEX(Questionnaire!$B$6:$B$93,MATCH(B8,Questionnaire!$A$6:$A$93,0)),"ID not in questionnaire")) | D8: =IF(B8="","",IFERROR(INDEX(Questionnaire!$C$6:$C$93,MATCH(B8,Questionnaire!$A$6:$A$93,0)),"")) | O8: =IF(OR(K8="",L8="Closed",L8="Risk accepted"),"",IF(K8<TODAY(),"OVERDUE","")) | P8: =IF(J8="","",IF(M8<>"",M8-J8,TODAY()-J8))
C9: =IF(B9="","",IFERROR(INDEX(Questionnaire!$B$6:$B$93,MATCH(B9,Questionnaire!$A$6:$A$93,0)),"ID not in questionnaire")) | D9: =IF(B9="","",IFERROR(INDEX(Questionnaire!$C$6:$C$93,MATCH(B9,Questionnaire!$A$6:$A$93,0)),"")) | O9: =IF(OR(K9="",L9="Closed",L9="Risk accepted"),"",IF(K9<TODAY(),"OVERDUE","")) | P9: =IF(J9="","",IF(M9<>"",M9-J9,TODAY()-J9))
C10: =IF(B10="","",IFERROR(INDEX(Questionnaire!$B$6:$B$93,MATCH(B10,Questionnaire!$A$6:$A$93,0)),"ID not in questionnaire")) | D10: =IF(B10="","",IFERROR(INDEX(Questionnaire!$C$6:$C$93,MATCH(B10,Questionnaire!$A$6:$A$93,0)),"")) | O10: =IF(OR(K10="",L10="Closed",L10="Risk accepted"),"",IF(K10<TODAY(),"OVERDUE","")) | P10: =IF(J10="","",IF(M10<>"",M10-J10,TODAY()-J10))
C11: =IF(B11="","",IFERROR(INDEX(Questionnaire!$B$6:$B$93,MATCH(B11,Questionnaire!$A$6:$A$93,0)),"ID not in questionnaire")) | D11: =IF(B11="","",IFERROR(INDEX(Questionnaire!$C$6:$C$93,MATCH(B11,Questionnaire!$A$6:$A$93,0)),"")) | O11: =IF(OR(K11="",L11="Closed",L11="Risk accepted"),"",IF(K11<TODAY(),"OVERDUE","")) | P11: =IF(J11="","",IF(M11<>"",M11-J11,TODAY()-J11))
C12: =IF(B12="","",IFERROR(INDEX(Questionnaire!$B$6:$B$93,MATCH(B12,Questionnaire!$A$6:$A$93,0)),"ID not in questionnaire")) | D12: =IF(B12="","",IFERROR(INDEX(Questionnaire!$C$6:$C$93,MATCH(B12,Questionnaire!$A$6:$A$93,0)),"")) | O12: =IF(OR(K12="",L12="Closed",L12="Risk accepted"),"",IF(K12<TODAY(),"OVERDUE","")) | P12: =IF(J12="","",IF(M12<>"",M12-J12,TODAY()-J12))
C13: =IF(B13="","",IFERROR(INDEX(Questionnaire!$B$6:$B$93,MATCH(B13,Questionnaire!$A$6:$A$93,0)),"ID not in questionnaire")) | D13: =IF(B13="","",IFERROR(INDEX(Questionnaire!$C$6:$C$93,MATCH(B13,Questionnaire!$A$6:$A$93,0)),"")) | O13: =IF(OR(K13="",L13="Closed",L13="Risk accepted"),"",IF(K13<TODAY(),"OVERDUE","")) | P13: =IF(J13="","",IF(M13<>"",M13-J13,TODAY()-J13))
C14: =IF(B14="","",IFERROR(INDEX(Questionnaire!$B$6:$B$93,MATCH(B14,Questionnaire!$A$6:$A$93,0)),"ID not in questionnaire")) | D14: =IF(B14="","",IFERROR(INDEX(Questionnaire!$C$6:$C$93,MATCH(B14,Questionnaire!$A$6:$A$93,0)),"")) | O14: =IF(OR(K14="",L14="Closed",L14="Risk accepted"),"",IF(K14<TODAY(),"OVERDUE","")) | P14: =IF(J14="","",IF(M14<>"",M14-J14,TODAY()-J14))
C15: =IF(B15="","",IFERROR(INDEX(Questionnaire!$B$6:$B$93,MATCH(B15,Questionnaire!$A$6:$A$93,0)),"ID not in questionnaire")) | D15: =IF(B15="","",IFERROR(INDEX(Questionnaire!$C$6:$C$93,MATCH(B15,Questionnaire!$A$6:$A$93,0)),"")) | O15: =IF(OR(K15="",L15="Closed",L15="Risk accepted"),"",IF(K15<TODAY(),"OVERDUE","")) | P15: =IF(J15="","",IF(M15<>"",M15-J15,TODAY()-J15))
C16: =IF(B16="","",IFERROR(INDEX(Questionnaire!$B$6:$B$93,MATCH(B16,Questionnaire!$A$6:$A$93,0)),"ID not in questionnaire")) | D16: =IF(B16="","",IFERROR(INDEX(Questionnaire!$C$6:$C$93,MATCH(B16,Questionnaire!$A$6:$A$93,0)),"")) | O16: =IF(OR(K16="",L16="Closed",L16="Risk accepted"),"",IF(K16<TODAY(),"OVERDUE","")) | P16: =IF(J16="","",IF(M16<>"",M16-J16,TODAY()-J16))
C17: =IF(B17="","",IFERROR(INDEX(Questionnaire!$B$6:$B$93,MATCH(B17,Questionnaire!$A$6:$A$93,0)),"ID not in questionnaire")) | D17: =IF(B17="","",IFERROR(INDEX(Questionnaire!$C$6:$C$93,MATCH(B17,Questionnaire!$A$6:$A$93,0)),"")) | O17: =IF(OR(K17="",L17="Closed",L17="Risk accepted"),"",IF(K17<TODAY(),"OVERDUE","")) | P17: =IF(J17="","",IF(M17<>"",M17-J17,TODAY()-J17))
C18: =IF(B18="","",IFERROR(INDEX(Questionnaire!$B$6:$B$93,MATCH(B18,Questionnaire!$A$6:$A$93,0)),"ID not in questionnaire")) | D18: =IF(B18="","",IFERROR(INDEX(Questionnaire!$C$6:$C$93,MATCH(B18,Questionnaire!$A$6:$A$93,0)),"")) | O18: =IF(OR(K18="",L18="Closed",L18="Risk accepted"),"",IF(K18<TODAY(),"OVERDUE","")) | P18: =IF(J18="","",IF(M18<>"",M18-J18,TODAY()-J18))
