Workbook

Sheet Start here
B1: Cryptographic Inventory & PQC Migration Workbook
B2: By John Bommeraveni Joseph | linkedin.com/in/john-bj | Free every weekday: GRC Made Simple Daily
B5: What this is
B6: A working inventory of where your organisation uses cryptography, which of those uses a large quantum computer could break, and the plan to move each one to the NIST post-quantum standards (FIPS 203 ML-KEM, FIPS 204 ML-DSA, FIPS 205 SLH-DSA). It applies Mosca's test (X + Y > Z) row by row, flags harvest-now-decrypt-later exposure, scores priority, and tracks the vendors you depend on. Built for CISOs, GRC teams and internal audit.
B7: How to use it (half a day for a first pass on your top 20 systems)
B8: 1. Assumptions: record your planning value Z (years until a cryptographically relevant quantum computer), who approved it and when. It is blank on purpose - nobody knows Z. Until you set it, the Mosca test says 'Set Z'.
B9: 2. Crypto Inventory: one row per system AND use of cryptography. A web portal with TLS to customers and RSA code signing is two rows. Start with internet-facing systems, long-lived confidential data and your PKI.
B10: 3. For each row set X (years the data must stay confidential) and Y (years you estimate the migration will take, including vendor lead time, testing and change windows). Be honest about Y - it is usually longer than hoped.
B11: 4. Fill the yellow cells using the drop-downs. Grey cells are formulas - do not type in them. If you do not know the algorithm, pick Unknown: the workbook treats it as quantum-vulnerable until proven otherwise.
B12: 5. Read the Flags column, then sort by Priority score. The score and its weights are explained on the Assumptions tab and can be tuned to your risk methodology.
B13: 6. Vendor Tracker: ask every supplier in your crypto path for a PQC roadmap with a date, in writing. A verbal 'it is on the roadmap' is recorded as such and keeps the flag red.
B14: 7. Dashboard: the summary for your risk committee. Deadlines & Guidance lists the dates regulators have published, each with its source - check the current text before relying on any of them.
... B23: Version 1.0 - 27 October 2026. Free to use and share with this credit kept.

Sheet Dashboard
B1: PQC Migration Dashboard
B2: By John Bommeraveni Joseph | linkedin.com/in/john-bj | Free every weekday: GRC Made Simple Daily
B5: Measure | C5: Count | E5: Protocol / use | F5: Uses | G5: Vulnerable or unknown | H5: Mosca at risk
B6: Cryptographic uses inventoried | C6: =COUNTA('Crypto Inventory'!$A$6:$A$205) -> 1 | E6: TLS | F6: =COUNTIF('Crypto Inventory'!$H$6:$H$205,E6) -> 1 | G6: =COUNTIFS('Crypto Inventory'!$H$6:$H$205,E6,'Crypto Inventory'!$R$6:$R$205,"<>No") -> 1 | H6: =COUNTIFS('Crypto Inventory'!$H$6:$H$205,E6,'Crypto Inventory'!$T$6:$T$205,"AT RISK*") -> 0
B7: Distinct systems (by name) | C7: =SUMPRODUCT(('Crypto Inventory'!$B$6:$B$205<>"")/COUNTIF('Crypto Inventory'!$B$6:$B$205,'Crypto Inventory'!$B$6:$B$205&"")) -> 1 | E7: SSH | F7: =COUNTIF('Crypto Inventory'!$H$6:$H$205,E7) -> 0 | G7: =COUNTIFS('Crypto Inventory'!$H$6:$H$205,E7,'Crypto Inventory'!$R$6:$R$205,"<>No") -> 0 | H7: =COUNTIFS('Crypto Inventory'!$H$6:$H$205,E7,'Crypto Inventory'!$T$6:$T$205,"AT RISK*") -> 0
B8: Quantum-vulnerable uses | C8: =COUNTIF('Crypto Inventory'!$R$6:$R$205,"Yes") -> 1 | E8: IPsec / VPN | F8: =COUNTIF('Crypto Inventory'!$H$6:$H$205,E8) -> 0 | G8: =COUNTIFS('Crypto Inventory'!$H$6:$H$205,E8,'Crypto Inventory'!$R$6:$R$205,"<>No") -> 0 | H8: =COUNTIFS('Crypto Inventory'!$H$6:$H$205,E8,'Crypto Inventory'!$T$6:$T$205,"AT RISK*") -> 0
B9: Unknown algorithms (investigate) | C9: =COUNTIF('Crypto Inventory'!$R$6:$R$205,"Unknown*") -> 0 | E9: Code signing | F9: =COUNTIF('Crypto Inventory'!$H$6:$H$205,E9) -> 0 | G9: =COUNTIFS('Crypto Inventory'!$H$6:$H$205,E9,'Crypto Inventory'!$R$6:$R$205,"<>No") -> 0 | H9: =COUNTIFS('Crypto Inventory'!$H$6:$H$205,E9,'Crypto Inventory'!$T$6:$T$205,"AT RISK*") -> 0
B10: Internet-facing and quantum-vulnerable (or unknown) | C10: =COUNTIFS('Crypto Inventory'!$F$6:$F$205,"Yes",'Crypto Inventory'!$R$6:$R$205,"<>No",'Crypto Inventory'!$A$6:$A$205,"<>") -> 1 | E10: Document signing | F10: =COUNTIF('Crypto Inventory'!$H$6:$H$205,E10) -> 0 | G10: =COUNTIFS('Crypto Inventory'!$H$6:$H$205,E10,'Crypto Inventory'!$R$6:$R$205,"<>No") -> 0 | H10: =COUNTIFS('Crypto Inventory'!$H$6:$H$205,E10,'Crypto Inventory'!$T$6:$T$205,"AT RISK*") -> 0
B11: Mosca test at risk (X + Y > Z) | C11: =COUNTIF('Crypto Inventory'!$T$6:$T$205,"AT RISK*") -> 0 | E11: PKI / CA | F11: =COUNTIF('Crypto Inventory'!$H$6:$H$205,E11) -> 0 | G11: =COUNTIFS('Crypto Inventory'!$H$6:$H$205,E11,'Crypto Inventory'!$R$6:$R$205,"<>No") -> 0 | H11: =COUNTIFS('Crypto Inventory'!$H$6:$H$205,E11,'Crypto Inventory'!$T$6:$T$205,"AT RISK*") -> 0
B12: Mosca test not yet possible (X, Y or Z missing) | C12: =COUNTIF('Crypto Inventory'!$T$6:$T$205,"Enter*")+COUNTIF('Crypto Inventory'!$T$6:$T$205,"Set Z*") -> 1 | E12: Database / disk encryption | F12: =COUNTIF('Crypto Inventory'!$H$6:$H$205,E12) -> 0 | G12: =COUNTIFS('Crypto Inventory'!$H$6:$H$205,E12,'Crypto Inventory'!$R$6:$R$205,"<>No") -> 0 | H12: =COUNTIFS('Crypto Inventory'!$H$6:$H$205,E12,'Crypto Inventory'!$T$6:$T$205,"AT RISK*") -> 0
B13: Harvest-now-decrypt-later exposure | C13: =COUNTIF('Crypto Inventory'!$U$6:$U$205,"Yes*") -> 1 | E13: HSM | F13: =COUNTIF('Crypto Inventory'!$H$6:$H$205,E13) -> 0 | G13: =COUNTIFS('Crypto Inventory'!$H$6:$H$205,E13,'Crypto Inventory'!$R$6:$R$205,"<>No") -> 0 | H13: =COUNTIFS('Crypto Inventory'!$H$6:$H$205,E13,'Crypto Inventory'!$T$6:$T$205,"AT RISK*") -> 0
B14: High priority uses | C14: =COUNTIF('Crypto Inventory'!$Y$6:$Y$205,"High") -> 0 | E14: API tokens (JWT, OAuth) | F14: =COUNTIF('Crypto Inventory'!$H$6:$H$205,E14) -> 0 | G14: =COUNTIFS('Crypto Inventory'!$H$6:$H$205,E14,'Crypto Inventory'!$R$6:$R$205,"<>No") -> 0 | H14: =COUNTIFS('Crypto Inventory'!$H$6:$H$205,E14,'Crypto Inventory'!$T$6:$T$205,"AT RISK*") -> 0
B15: Vulnerable uses with no target algorithm chosen | C15: =COUNTIFS('Crypto Inventory'!$R$6:$R$205,"<>No",'Crypto Inventory'!$A$6:$A$205,"<>",'Crypto Inventory'!$W$6:$W$205,"")+COUNTIFS('Crypto Inventory'!$R$6:$R$205,"<>No",'Crypto Inventory'!$A$6:$A$205,"<>",'Crypto Inventory'!$W$6:$W$205,"To decide") -> 0 | E15: S/MIME | F15: =COUNTIF('Crypto Inventory'!$H$6:$H$205,E15) -> 0 | G15: =COUNTIFS('Crypto Inventory'!$H$6:$H$205,E15,'Crypto Inventory'!$R$6:$R$205,"<>No") -> 0 | H15: =COUNTIFS('Crypto Inventory'!$H$6:$H$205,E15,'Crypto Inventory'!$T$6:$T$205,"AT RISK*") -> 0
B16: Migrations overdue | C16: =COUNTIF('Crypto Inventory'!$AC$6:$AC$205,"OVERDUE") -> 0 | E16: Other | F16: =COUNTIF('Crypto Inventory'!$H$6:$H$205,E16) -> 0 | G16: =COUNTIFS('Crypto Inventory'!$H$6:$H$205,E16,'Crypto Inventory'!$R$6:$R$205,"<>No") -> 0 | H16: =COUNTIFS('Crypto Inventory'!$H$6:$H$205,E16,'Crypto Inventory'!$T$6:$T$205,"AT RISK*") -> 0
B17: Certificates / keys expiring within the warning window | C17: =COUNTIFS('Crypto Inventory'!$M$6:$M$205,">="&TODAY(),'Crypto Inventory'!$M$6:$M$205,"<="&(TODAY()+Assumptions!$C$25)) -> 0 | E17: Total | F17: =SUM(F6:F16) -> 1 | G17: =SUM(G6:G16) -> 1 | H17: =SUM(H6:H16) -> 0
B18: Uses with hybrid or PQC deployed | C18: =COUNTIF('Crypto Inventory'!$AB$6:$AB$205,"Hybrid deployed")+COUNTIF('Crypto Inventory'!$AB$6:$AB$205,"PQC deployed") -> 0 | E18: Rows with no protocol chosen are not in this table.
B19: Share of vulnerable or unknown uses migrated (hybrid or PQC) | C19: =IFERROR(C18/COUNTIFS('Crypto Inventory'!$R$6:$R$205,"<>No",'Crypto Inventory'!$A$6:$A$205,"<>"),0) -> 0
B20: Vendors tracked | C20: =COUNTA('Vendor Tracker'!$A$6:$A$105) -> 1
B21: Vendors without a written PQC roadmap | C21: =COUNTIFS('Vendor Tracker'!$A$6:$A$105,"<>",'Vendor Tracker'!$H$6:$H$105,"<>Yes",'Vendor Tracker'!$F$6:$F$105,"<>PQC available now",'Vendor Tracker'!$F$6:$F$105,"<>Hybrid available now") -> 0
B22: Vendor follow-ups overdue | C22: =COUNTIF('Vendor Tracker'!$N$6:$N$105,"OVERDUE") -> 0
B24: Planning value Z (years to a CRQC) - from Assumptions | C24: =IF(Assumptions!$C$6="","NOT SET",Assumptions!$C$6) -> NOT SET
B25: Z approved by | C25: =IF(Assumptions!$C$8="","NOT RECORDED",Assumptions!$C$8) -> NOT RECORDED
B27: Red = needs action. The worked examples in row 6 of each register are counted until you delete them. Share migrated counts uses marked 'Hybrid deployed' or 'PQC deployed'.

Sheet Crypto Inventory
B1: Crypto Inventory
B2: By John Bommeraveni Joseph | linkedin.com/in/john-bj | Free every weekday: GRC Made Simple Daily
A5: ID | B5: System / application | C5: Business owner | D5: Technical owner | E5: Environment | F5: Internet-facing? | G5: Data classification | H5: Protocol / use | I5: Crypto function | J5: Algorithm | K5: Key size / parameter set | L5: Library / HSM / vendor product | M5: Certificate / key expiry | N5: Vendor PQC roadmap status | O5: X - years data must stay confidential | P5: Y - estimated migration effort (years) | Q5: Algorithm family | R5: Quantum-vulnerable? | S5: X + Y | T5: Mosca test (X + Y vs Z) | U5: Harvest-now-decrypt-later exposure | V5: Suggested NIST target | W5: Target algorithm (chosen) | X5: Priority score (0-100) | Y5: Priority band | Z5: Migration owner | AA5: Target date | AB5: Status | AC5: Overdue? | AD5: Flags
A6: INV-001 | B6: Customer web portal | C6: Head of Digital | D6: Platform Engineering Lead | E6: Production | F6: Yes | G6: Confidential | H6: TLS | I6: Key establishment / encryption in transit | J6: X25519 | K6: Curve25519 | L6: Example: load balancer TLS stack (vendor appliance) | M6: 46461 | N6: Roadmap date in writing | O6: 7 | P6: 3 | Q6: =IF(A6="","",IF(J6="","Unknown",IFERROR(INDEX('Algorithm Reference'!$C$6:$C$41,MATCH(J6,'Algorithm Reference'!$B$6:$B$41,0)),"Not in reference"))) -> ECDH | R6: =IF(A6="","",IF(J6="","Unknown - investigate",IFERROR(INDEX('Algorithm Reference'!$E$6:$E$41,MATCH(J6,'Algorithm Reference'!$B$6:$B$41,0)),"Unknown - investigate"))) -> Yes | S6: =IF(OR(O6="",P6=""),"",O6+P6) -> 10 | T6: =IF(A6="","",IF(R6="No","N/A - not quantum-vulnerable",IF(OR(O6="",P6=""),"Enter X and Y",IF(Assumptions!$C$6="","Set Z on Assumptions",IF(O6+P6>Assumptions!$C$6,"AT RISK (X+Y > Z)","Within Z (X+Y <= Z)"))))) -> Set Z on Assumptions | U6: =IF(A6="","",IF(AND(R6<>"No",OR(I6="Key establishment / encryption in transit",I6="Key wrapping / key transport",I6="Mixed or unknown",I6=""),OR(N(O6)>0,G6="Confidential",G6="Restricted")),IF(F6="Yes","Yes - internet-facing","Yes"),"No")) -> Yes - internet-facing | V6: =IF(A6="","",IF(R6="No","Keep - not quantum-vulnerable (review key size)",IF(I6="Digital signature / authentication","ML-DSA-65 (FIPS 204); SLH-DSA (FIPS 205) if hash-based is preferred",IF(OR(I6="Key establishment / encryption in transit",I6="Key wrapping / key transport"),"ML-KEM-768 (FIPS 203); hybrid X25519MLKEM768 for TLS 1.3",IF(I6="Mixed or unknown","Both: ML-KEM (FIPS 203) for keys, ML-DSA (FIPS 204) for signatures","Pick the crypto function first"))))) -> ML-KEM-768 (FIPS 203); hybrid X25519MLKEM768 for TLS 1.3 | W6: Hybrid X25519MLKEM768 (RFC 10024) | X6: =IF(A6="","",IF(R6="No",0,IF(LEFT(T6,7)="AT RISK",Assumptions!$C$13,0)+IF(LEFT(U6,3)="Yes",Assumptions!$C$14,0)+IF(F6="Yes",Assumptions!$C$15,0)+IF(G6="Restricted",Assumptions!$C$16,IF(G6="Confidential",Assumptions!$C$17,IF(G6="Internal",Assumptions!$C$18,0)))+IF(OR(N6="Roadmap - verbal only",N6="No roadmap",N6="Not asked yet",N6=""),Assumptions!$C$19,0)+IF(E6="Production",Assumptions!$C$20,0)+IF(AND(ISNUMBER(P6),N(P6)>=Assumptions!$C$22),Assumptions!$C$21,0))) -> 55 | Y6: =IF(X6="","",IF(R6="No","None",IF(X6>=Assumptions!$C$23,"High",IF(X6>=Assumptions!$C$24,"Medium","Low")))) -> Medium | Z6: Network Security Lead | AA6: 46568 | AB6: Planned | AC6: =IF(OR(AA6="",AB6="Hybrid deployed",AB6="PQC deployed",AB6="Not required (not vulnerable)",AB6="Risk accepted"),"",IF(AA6<TODAY(),"OVERDUE","")) | AD6: =IF(A6="","",IF(B6="","Name the system. ","")&IF(LEFT(R6,7)="Unknown","Algorithm unknown - scan or ask the vendor. ","")&IF(AND(R6<>"No",Assumptions!$C$6=""),"Set Z on Assumptions. ","")&IF(AND(R6<>"No",OR(O6="",P6="")),"Enter X and Y. ","")&IF(LEFT(T6,7)="AT RISK","Mosca: X+Y exceeds Z - migration should already be under way. ","")&IF(AND(LEFT(U6,3)="Yes",OR(AB6="",AB6="Not started")),"Harvest-now-decrypt-later exposure and migration not started. ","")&IF(AND(R6<>"No",OR(W6="",W6="To decide")),"Choose a target algorithm. ","")&IF(AND(R6<>"No",W6="Keep - not quantum-vulnerable"),"Target 'Keep' conflicts with a quantum-vulnerable algorithm. ","")&IF(LEFT(J6,5)="SHA-1","SHA-1 is deprecated - replace (NIST IR 8547). ","")&IF(AND(R6<>"No",OR(N6="Roadmap - verbal only",N6="No roadmap",N6="Not asked yet")),"Get a written PQC roadmap from the vendor. ","")&IF(AND(R6<>"No",N6=""),"Record the vendor PQC roadmap status. ","")&IF(ISNUMBER(M6),IF(M6<TODAY(),"Certificate or key expired. ",IF(M6-TODAY()<=Assumptions!$C$25,"Expires soon - use the renewal to revisit the algorithm. ","")),"")&IF(AC6="OVERDUE","Migration overdue. ","")&IF(AND(R6<>"No",Z6=""),"Assign a migration owner. ","")) -> Set Z on Assumptions.
Q7: =IF(A7="","",IF(J7="","Unknown",IFERROR(INDEX('Algorithm Reference'!$C$6:$C$41,MATCH(J7,'Algorithm Reference'!$B$6:$B$41,0)),"Not in reference"))) | R7: =IF(A7="","",IF(J7="","Unknown - investigate",IFERROR(INDEX('Algorithm Reference'!$E$6:$E$41,MATCH(J7,'Algorithm Reference'!$B$6:$B$41,0)),"Unknown - investigate"))) | S7: =IF(OR(O7="",P7=""),"",O7+P7) | T7: =IF(A7="","",IF(R7="No","N/A - not quantum-vulnerable",IF(OR(O7="",P7=""),"Enter X and Y",IF(Assumptions!$C$6="","Set Z on Assumptions",IF(O7+P7>Assumptions!$C$6,"AT RISK (X+Y > Z)","Within Z (X+Y <= Z)"))))) | U7: =IF(A7="","",IF(AND(R7<>"No",OR(I7="Key establishment / encryption in transit",I7="Key wrapping / key transport",I7="Mixed or unknown",I7=""),OR(N(O7)>0,G7="Confidential",G7="Restricted")),IF(F7="Yes","Yes - internet-facing","Yes"),"No")) | V7: =IF(A7="","",IF(R7="No","Keep - not quantum-vulnerable (review key size)",IF(I7="Digital signature / authentication","ML-DSA-65 (FIPS 204); SLH-DSA (FIPS 205) if hash-based is preferred",IF(OR(I7="Key establishment / encryption in transit",I7="Key wrapping / key transport"),"ML-KEM-768 (FIPS 203); hybrid X25519MLKEM768 for TLS 1.3",IF(I7="Mixed or unknown","Both: ML-KEM (FIPS 203) for keys, ML-DSA (FIPS 204) for signatures","Pick the crypto function first"))))) | X7: =IF(A7="","",IF(R7="No",0,IF(LEFT(T7,7)="AT RISK",Assumptions!$C$13,0)+IF(LEFT(U7,3)="Yes",Assumptions!$C$14,0)+IF(F7="Yes",Assumptions!$C$15,0)+IF(G7="Restricted",Assumptions!$C$16,IF(G7="Confidential",Assumptions!$C$17,IF(G7="Internal",Assumptions!$C$18,0)))+IF(OR(N7="Roadmap - verbal only",N7="No roadmap",N7="Not asked yet",N7=""),Assumptions!$C$19,0)+IF(E7="Production",Assumptions!$C$20,0)+IF(AND(ISNUMBER(P7),N(P7)>=Assumptions!$C$22),Assumptions!$C$21,0))) | Y7: =IF(X7="","",IF(R7="No","None",IF(X7>=Assumptions!$C$23,"High",IF(X7>=Assumptions!$C$24,"Medium","Low")))) | AC7: =IF(OR(AA7="",AB7="Hybrid deployed",AB7="PQC deployed",AB7="Not required (not vulnerable)",AB7="Risk accepted"),"",IF(AA7<TODAY(),"OVERDUE","")) | AD7: =IF(A7="","",IF(B7="","Name the system. ","")&IF(LEFT(R7,7)="Unknown","Algorithm unknown - scan or ask the vendor. ","")&IF(AND(R7<>"No",Assumptions!$C$6=""),"Set Z on Assumptions. ","")&IF(AND(R7<>"No",OR(O7="",P7="")),"Enter X and Y. ","")&IF(LEFT(T7,7)="AT RISK","Mosca: X+Y exceeds Z - migration should already be under way. ","")&IF(AND(LEFT(U7,3)="Yes",OR(AB7="",AB7="Not started")),"Harvest-now-decrypt-later exposure and migration not started. ","")&IF(AND(R7<>"No",OR(W7="",W7="To decide")),"Choose a target algorithm. ","")&IF(AND(R7<>"No",W7="Keep - not quantum-vulnerable"),"Target 'Keep' conflicts with a quantum-vulnerable algorithm. ","")&IF(LEFT(J7,5)="SHA-1","SHA-1 is deprecated - replace (NIST IR 8547). ","")&IF(AND(R7<>"No",OR(N7="Roadmap - verbal only",N7="No roadmap",N7="Not asked yet")),"Get a written PQC roadmap from the vendor. ","")&IF(AND(R7<>"No",N7=""),"Record the vendor PQC roadmap status. ","")&IF(ISNUMBER(M7),IF(M7<TODAY(),"Certificate or key expired. ",IF(M7-TODAY()<=Assumptions!$C$25,"Expires soon - use the renewal to revisit the algorithm. ","")),"")&IF(AC7="OVERDUE","Migration overdue. ","")&IF(AND(R7<>"No",Z7=""),"Assign a migration owner. ",""))
Q8: =IF(A8="","",IF(J8="","Unknown",IFERROR(INDEX('Algorithm Reference'!$C$6:$C$41,MATCH(J8,'Algorithm Reference'!$B$6:$B$41,0)),"Not in reference"))) | R8: =IF(A8="","",IF(J8="","Unknown - investigate",IFERROR(INDEX('Algorithm Reference'!$E$6:$E$41,MATCH(J8,'Algorithm Reference'!$B$6:$B$41,0)),"Unknown - investigate"))) | S8: =IF(OR(O8="",P8=""),"",O8+P8) | T8: =IF(A8="","",IF(R8="No","N/A - not quantum-vulnerable",IF(OR(O8="",P8=""),"Enter X and Y",IF(Assumptions!$C$6="","Set Z on Assumptions",IF(O8+P8>Assumptions!$C$6,"AT RISK (X+Y > Z)","Within Z (X+Y <= Z)"))))) | U8: =IF(A8="","",IF(AND(R8<>"No",OR(I8="Key establishment / encryption in transit",I8="Key wrapping / key transport",I8="Mixed or unknown",I8=""),OR(N(O8)>0,G8="Confidential",G8="Restricted")),IF(F8="Yes","Yes - internet-facing","Yes"),"No")) | V8: =IF(A8="","",IF(R8="No","Keep - not quantum-vulnerable (review key size)",IF(I8="Digital signature / authentication","ML-DSA-65 (FIPS 204); SLH-DSA (FIPS 205) if hash-based is preferred",IF(OR(I8="Key establishment / encryption in transit",I8="Key wrapping / key transport"),"ML-KEM-768 (FIPS 203); hybrid X25519MLKEM768 for TLS 1.3",IF(I8="Mixed or unknown","Both: ML-KEM (FIPS 203) for keys, ML-DSA (FIPS 204) for signatures","Pick the crypto function first"))))) | X8: =IF(A8="","",IF(R8="No",0,IF(LEFT(T8,7)="AT RISK",Assumptions!$C$13,0)+IF(LEFT(U8,3)="Yes",Assumptions!$C$14,0)+IF(F8="Yes",Assumptions!$C$15,0)+IF(G8="Restricted",Assumptions!$C$16,IF(G8="Confidential",Assumptions!$C$17,IF(G8="Internal",Assumptions!$C$18,0)))+IF(OR(N8="Roadmap - verbal only",N8="No roadmap",N8="Not asked yet",N8=""),Assumptions!$C$19,0)+IF(E8="Production",Assumptions!$C$20,0)+IF(AND(ISNUMBER(P8),N(P8)>=Assumptions!$C$22),Assumptions!$C$21,0))) | Y8: =IF(X8="","",IF(R8="No","None",IF(X8>=Assumptions!$C$23,"High",IF(X8>=Assumptions!$C$24,"Medium","Low")))) | AC8: =IF(OR(AA8="",AB8="Hybrid deployed",AB8="PQC deployed",AB8="Not required (not vulnerable)",AB8="Risk accepted"),"",IF(AA8<TODAY(),"OVERDUE","")) | AD8: =IF(A8="","",IF(B8="","Name the system. ","")&IF(LEFT(R8,7)="Unknown","Algorithm unknown - scan or ask the vendor. ","")&IF(AND(R8<>"No",Assumptions!$C$6=""),"Set Z on Assumptions. ","")&IF(AND(R8<>"No",OR(O8="",P8="")),"Enter X and Y. ","")&IF(LEFT(T8,7)="AT RISK","Mosca: X+Y exceeds Z - migration should already be under way. ","")&IF(AND(LEFT(U8,3)="Yes",OR(AB8="",AB8="Not started")),"Harvest-now-decrypt-later exposure and migration not started. ","")&IF(AND(R8<>"No",OR(W8="",W8="To decide")),"Choose a target algorithm. ","")&IF(AND(R8<>"No",W8="Keep - not quantum-vulnerable"),"Target 'Keep' conflicts with a quantum-vulnerable algorithm. ","")&IF(LEFT(J8,5)="SHA-1","SHA-1 is deprecated - replace (NIST IR 8547). ","")&IF(AND(R8<>"No",OR(N8="Roadmap - verbal only",N8="No roadmap",N8="Not asked yet")),"Get a written PQC roadmap from the vendor. ","")&IF(AND(R8<>"No",N8=""),"Record the vendor PQC roadmap status. ","")&IF(ISNUMBER(M8),IF(M8<TODAY(),"Certificate or key expired. ",IF(M8-TODAY()<=Assumptions!$C$25,"Expires soon - use the renewal to revisit the algorithm. ","")),"")&IF(AC8="OVERDUE","Migration overdue. ","")&IF(AND(R8<>"No",Z8=""),"Assign a migration owner. ",""))
Q9: =IF(A9="","",IF(J9="","Unknown",IFERROR(INDEX('Algorithm Reference'!$C$6:$C$41,MATCH(J9,'Algorithm Reference'!$B$6:$B$41,0)),"Not in reference"))) | R9: =IF(A9="","",IF(J9="","Unknown - investigate",IFERROR(INDEX('Algorithm Reference'!$E$6:$E$41,MATCH(J9,'Algorithm Reference'!$B$6:$B$41,0)),"Unknown - investigate"))) | S9: =IF(OR(O9="",P9=""),"",O9+P9) | T9: =IF(A9="","",IF(R9="No","N/A - not quantum-vulnerable",IF(OR(O9="",P9=""),"Enter X and Y",IF(Assumptions!$C$6="","Set Z on Assumptions",IF(O9+P9>Assumptions!$C$6,"AT RISK (X+Y > Z)","Within Z (X+Y <= Z)"))))) | U9: =IF(A9="","",IF(AND(R9<>"No",OR(I9="Key establishment / encryption in transit",I9="Key wrapping / key transport",I9="Mixed or unknown",I9=""),OR(N(O9)>0,G9="Confidential",G9="Restricted")),IF(F9="Yes","Yes - internet-facing","Yes"),"No")) | V9: =IF(A9="","",IF(R9="No","Keep - not quantum-vulnerable (review key size)",IF(I9="Digital signature / authentication","ML-DSA-65 (FIPS 204); SLH-DSA (FIPS 205) if hash-based is preferred",IF(OR(I9="Key establishment / encryption in transit",I9="Key wrapping / key transport"),"ML-KEM-768 (FIPS 203); hybrid X25519MLKEM768 for TLS 1.3",IF(I9="Mixed or unknown","Both: ML-KEM (FIPS 203) for keys, ML-DSA (FIPS 204) for signatures","Pick the crypto function first"))))) | X9: =IF(A9="","",IF(R9="No",0,IF(LEFT(T9,7)="AT RISK",Assumptions!$C$13,0)+IF(LEFT(U9,3)="Yes",Assumptions!$C$14,0)+IF(F9="Yes",Assumptions!$C$15,0)+IF(G9="Restricted",Assumptions!$C$16,IF(G9="Confidential",Assumptions!$C$17,IF(G9="Internal",Assumptions!$C$18,0)))+IF(OR(N9="Roadmap - verbal only",N9="No roadmap",N9="Not asked yet",N9=""),Assumptions!$C$19,0)+IF(E9="Production",Assumptions!$C$20,0)+IF(AND(ISNUMBER(P9),N(P9)>=Assumptions!$C$22),Assumptions!$C$21,0))) | Y9: =IF(X9="","",IF(R9="No","None",IF(X9>=Assumptions!$C$23,"High",IF(X9>=Assumptions!$C$24,"Medium","Low")))) | AC9: =IF(OR(AA9="",AB9="Hybrid deployed",AB9="PQC deployed",AB9="Not required (not vulnerable)",AB9="Risk accepted"),"",IF(AA9<TODAY(),"OVERDUE","")) | AD9: =IF(A9="","",IF(B9="","Name the system. ","")&IF(LEFT(R9,7)="Unknown","Algorithm unknown - scan or ask the vendor. ","")&IF(AND(R9<>"No",Assumptions!$C$6=""),"Set Z on Assumptions. ","")&IF(AND(R9<>"No",OR(O9="",P9="")),"Enter X and Y. ","")&IF(LEFT(T9,7)="AT RISK","Mosca: X+Y exceeds Z - migration should already be under way. ","")&IF(AND(LEFT(U9,3)="Yes",OR(AB9="",AB9="Not started")),"Harvest-now-decrypt-later exposure and migration not started. ","")&IF(AND(R9<>"No",OR(W9="",W9="To decide")),"Choose a target algorithm. ","")&IF(AND(R9<>"No",W9="Keep - not quantum-vulnerable"),"Target 'Keep' conflicts with a quantum-vulnerable algorithm. ","")&IF(LEFT(J9,5)="SHA-1","SHA-1 is deprecated - replace (NIST IR 8547). ","")&IF(AND(R9<>"No",OR(N9="Roadmap - verbal only",N9="No roadmap",N9="Not asked yet")),"Get a written PQC roadmap from the vendor. ","")&IF(AND(R9<>"No",N9=""),"Record the vendor PQC roadmap status. ","")&IF(ISNUMBER(M9),IF(M9<TODAY(),"Certificate or key expired. ",IF(M9-TODAY()<=Assumptions!$C$25,"Expires soon - use the renewal to revisit the algorithm. ","")),"")&IF(AC9="OVERDUE","Migration overdue. ","")&IF(AND(R9<>"No",Z9=""),"Assign a migration owner. ",""))
Q10: =IF(A10="","",IF(J10="","Unknown",IFERROR(INDEX('Algorithm Reference'!$C$6:$C$41,MATCH(J10,'Algorithm Reference'!$B$6:$B$41,0)),"Not in reference"))) | R10: =IF(A10="","",IF(J10="","Unknown - investigate",IFERROR(INDEX('Algorithm Reference'!$E$6:$E$41,MATCH(J10,'Algorithm Reference'!$B$6:$B$41,0)),"Unknown - investigate"))) | S10: =IF(OR(O10="",P10=""),"",O10+P10) | T10: =IF(A10="","",IF(R10="No","N/A - not quantum-vulnerable",IF(OR(O10="",P10=""),"Enter X and Y",IF(Assumptions!$C$6="","Set Z on Assumptions",IF(O10+P10>Assumptions!$C$6,"AT RISK (X+Y > Z)","Within Z (X+Y <= Z)"))))) | U10: =IF(A10="","",IF(AND(R10<>"No",OR(I10="Key establishment / encryption in transit",I10="Key wrapping / key transport",I10="Mixed or unknown",I10=""),OR(N(O10)>0,G10="Confidential",G10="Restricted")),IF(F10="Yes","Yes - internet-facing","Yes"),"No")) | V10: =IF(A10="","",IF(R10="No","Keep - not quantum-vulnerable (review key size)",IF(I10="Digital signature / authentication","ML-DSA-65 (FIPS 204); SLH-DSA (FIPS 205) if hash-based is preferred",IF(OR(I10="Key establishment / encryption in transit",I10="Key wrapping / key transport"),"ML-KEM-768 (FIPS 203); hybrid X25519MLKEM768 for TLS 1.3",IF(I10="Mixed or unknown","Both: ML-KEM (FIPS 203) for keys, ML-DSA (FIPS 204) for signatures","Pick the crypto function first"))))) | X10: =IF(A10="","",IF(R10="No",0,IF(LEFT(T10,7)="AT RISK",Assumptions!$C$13,0)+IF(LEFT(U10,3)="Yes",Assumptions!$C$14,0)+IF(F10="Yes",Assumptions!$C$15,0)+IF(G10="Restricted",Assumptions!$C$16,IF(G10="Confidential",Assumptions!$C$17,IF(G10="Internal",Assumptions!$C$18,0)))+IF(OR(N10="Roadmap - verbal only",N10="No roadmap",N10="Not asked yet",N10=""),Assumptions!$C$19,0)+IF(E10="Production",Assumptions!$C$20,0)+IF(AND(ISNUMBER(P10),N(P10)>=Assumptions!$C$22),Assumptions!$C$21,0))) | Y10: =IF(X10="","",IF(R10="No","None",IF(X10>=Assumptions!$C$23,"High",IF(X10>=Assumptions!$C$24,"Medium","Low")))) | AC10: =IF(OR(AA10="",AB10="Hybrid deployed",AB10="PQC deployed",AB10="Not required (not vulnerable)",AB10="Risk accepted"),"",IF(AA10<TODAY(),"OVERDUE","")) | AD10: =IF(A10="","",IF(B10="","Name the system. ","")&IF(LEFT(R10,7)="Unknown","Algorithm unknown - scan or ask the vendor. ","")&IF(AND(R10<>"No",Assumptions!$C$6=""),"Set Z on Assumptions. ","")&IF(AND(R10<>"No",OR(O10="",P10="")),"Enter X and Y. ","")&IF(LEFT(T10,7)="AT RISK","Mosca: X+Y exceeds Z - migration should already be under way. ","")&IF(AND(LEFT(U10,3)="Yes",OR(AB10="",AB10="Not started")),"Harvest-now-decrypt-later exposure and migration not started. ","")&IF(AND(R10<>"No",OR(W10="",W10="To decide")),"Choose a target algorithm. ","")&IF(AND(R10<>"No",W10="Keep - not quantum-vulnerable"),"Target 'Keep' conflicts with a quantum-vulnerable algorithm. ","")&IF(LEFT(J10,5)="SHA-1","SHA-1 is deprecated - replace (NIST IR 8547). ","")&IF(AND(R10<>"No",OR(N10="Roadmap - verbal only",N10="No roadmap",N10="Not asked yet")),"Get a written PQC roadmap from the vendor. ","")&IF(AND(R10<>"No",N10=""),"Record the vendor PQC roadmap status. ","")&IF(ISNUMBER(M10),IF(M10<TODAY(),"Certificate or key expired. ",IF(M10-TODAY()<=Assumptions!$C$25,"Expires soon - use the renewal to revisit the algorithm. ","")),"")&IF(AC10="OVERDUE","Migration overdue. ","")&IF(AND(R10<>"No",Z10=""),"Assign a migration owner. ",""))
Q11: =IF(A11="","",IF(J11="","Unknown",IFERROR(INDEX('Algorithm Reference'!$C$6:$C$41,MATCH(J11,'Algorithm Reference'!$B$6:$B$41,0)),"Not in reference"))) | R11: =IF(A11="","",IF(J11="","Unknown - investigate",IFERROR(INDEX('Algorithm Reference'!$E$6:$E$41,MATCH(J11,'Algorithm Reference'!$B$6:$B$41,0)),"Unknown - investigate"))) | S11: =IF(OR(O11="",P11=""),"",O11+P11) | T11: =IF(A11="","",IF(R11="No","N/A - not quantum-vulnerable",IF(OR(O11="",P11=""),"Enter X and Y",IF(Assumptions!$C$6="","Set Z on Assumptions",IF(O11+P11>Assumptions!$C$6,"AT RISK (X+Y > Z)","Within Z (X+Y <= Z)"))))) | U11: =IF(A11="","",IF(AND(R11<>"No",OR(I11="Key establishment / encryption in transit",I11="Key wrapping / key transport",I11="Mixed or unknown",I11=""),OR(N(O11)>0,G11="Confidential",G11="Restricted")),IF(F11="Yes","Yes - internet-facing","Yes"),"No")) | V11: =IF(A11="","",IF(R11="No","Keep - not quantum-vulnerable (review key size)",IF(I11="Digital signature / authentication","ML-DSA-65 (FIPS 204); SLH-DSA (FIPS 205) if hash-based is preferred",IF(OR(I11="Key establishment / encryption in transit",I11="Key wrapping / key transport"),"ML-KEM-768 (FIPS 203); hybrid X25519MLKEM768 for TLS 1.3",IF(I11="Mixed or unknown","Both: ML-KEM (FIPS 203) for keys, ML-DSA (FIPS 204) for signatures","Pick the crypto function first"))))) | X11: =IF(A11="","",IF(R11="No",0,IF(LEFT(T11,7)="AT RISK",Assumptions!$C$13,0)+IF(LEFT(U11,3)="Yes",Assumptions!$C$14,0)+IF(F11="Yes",Assumptions!$C$15,0)+IF(G11="Restricted",Assumptions!$C$16,IF(G11="Confidential",Assumptions!$C$17,IF(G11="Internal",Assumptions!$C$18,0)))+IF(OR(N11="Roadmap - verbal only",N11="No roadmap",N11="Not asked yet",N11=""),Assumptions!$C$19,0)+IF(E11="Production",Assumptions!$C$20,0)+IF(AND(ISNUMBER(P11),N(P11)>=Assumptions!$C$22),Assumptions!$C$21,0))) | Y11: =IF(X11="","",IF(R11="No","None",IF(X11>=Assumptions!$C$23,"High",IF(X11>=Assumptions!$C$24,"Medium","Low")))) | AC11: =IF(OR(AA11="",AB11="Hybrid deployed",AB11="PQC deployed",AB11="Not required (not vulnerable)",AB11="Risk accepted"),"",IF(AA11<TODAY(),"OVERDUE","")) | AD11: =IF(A11="","",IF(B11="","Name the system. ","")&IF(LEFT(R11,7)="Unknown","Algorithm unknown - scan or ask the vendor. ","")&IF(AND(R11<>"No",Assumptions!$C$6=""),"Set Z on Assumptions. ","")&IF(AND(R11<>"No",OR(O11="",P11="")),"Enter X and Y. ","")&IF(LEFT(T11,7)="AT RISK","Mosca: X+Y exceeds Z - migration should already be under way. ","")&IF(AND(LEFT(U11,3)="Yes",OR(AB11="",AB11="Not started")),"Harvest-now-decrypt-later exposure and migration not started. ","")&IF(AND(R11<>"No",OR(W11="",W11="To decide")),"Choose a target algorithm. ","")&IF(AND(R11<>"No",W11="Keep - not quantum-vulnerable"),"Target 'Keep' conflicts with a quantum-vulnerable algorithm. ","")&IF(LEFT(J11,5)="SHA-1","SHA-1 is deprecated - replace (NIST IR 8547). ","")&IF(AND(R11<>"No",OR(N11="Roadmap - verbal only",N11="No roadmap",N11="Not asked yet")),"Get a written PQC roadmap from the vendor. ","")&IF(AND(R11<>"No",N11=""),"Record the vendor PQC roadmap status. ","")&IF(ISNUMBER(M11),IF(M11<TODAY(),"Certificate or key expired. ",IF(M11-TODAY()<=Assumptions!$C$25,"Expires soon - use the renewal to revisit the algorithm. ","")),"")&IF(AC11="OVERDUE","Migration overdue. ","")&IF(AND(R11<>"No",Z11=""),"Assign a migration owner. ",""))
Q12: =IF(A12="","",IF(J12="","Unknown",IFERROR(INDEX('Algorithm Reference'!$C$6:$C$41,MATCH(J12,'Algorithm Reference'!$B$6:$B$41,0)),"Not in reference"))) | R12: =IF(A12="","",IF(J12="","Unknown - investigate",IFERROR(INDEX('Algorithm Reference'!$E$6:$E$41,MATCH(J12,'Algorithm Reference'!$B$6:$B$41,0)),"Unknown - investigate"))) | S12: =IF(OR(O12="",P12=""),"",O12+P12) | T12: =IF(A12="","",IF(R12="No","N/A - not quantum-vulnerable",IF(OR(O12="",P12=""),"Enter X and Y",IF(Assumptions!$C$6="","Set Z on Assumptions",IF(O12+P12>Assumptions!$C$6,"AT RISK (X+Y > Z)","Within Z (X+Y <= Z)"))))) | U12: =IF(A12="","",IF(AND(R12<>"No",OR(I12="Key establishment / encryption in transit",I12="Key wrapping / key transport",I12="Mixed or unknown",I12=""),OR(N(O12)>0,G12="Confidential",G12="Restricted")),IF(F12="Yes","Yes - internet-facing","Yes"),"No")) | V12: =IF(A12="","",IF(R12="No","Keep - not quantum-vulnerable (review key size)",IF(I12="Digital signature / authentication","ML-DSA-65 (FIPS 204); SLH-DSA (FIPS 205) if hash-based is preferred",IF(OR(I12="Key establishment / encryption in transit",I12="Key wrapping / key transport"),"ML-KEM-768 (FIPS 203); hybrid X25519MLKEM768 for TLS 1.3",IF(I12="Mixed or unknown","Both: ML-KEM (FIPS 203) for keys, ML-DSA (FIPS 204) for signatures","Pick the crypto function first"))))) | X12: =IF(A12="","",IF(R12="No",0,IF(LEFT(T12,7)="AT RISK",Assumptions!$C$13,0)+IF(LEFT(U12,3)="Yes",Assumptions!$C$14,0)+IF(F12="Yes",Assumptions!$C$15,0)+IF(G12="Restricted",Assumptions!$C$16,IF(G12="Confidential",Assumptions!$C$17,IF(G12="Internal",Assumptions!$C$18,0)))+IF(OR(N12="Roadmap - verbal only",N12="No roadmap",N12="Not asked yet",N12=""),Assumptions!$C$19,0)+IF(E12="Production",Assumptions!$C$20,0)+IF(AND(ISNUMBER(P12),N(P12)>=Assumptions!$C$22),Assumptions!$C$21,0))) | Y12: =IF(X12="","",IF(R12="No","None",IF(X12>=Assumptions!$C$23,"High",IF(X12>=Assumptions!$C$24,"Medium","Low")))) | AC12: =IF(OR(AA12="",AB12="Hybrid deployed",AB12="PQC deployed",AB12="Not required (not vulnerable)",AB12="Risk accepted"),"",IF(AA12<TODAY(),"OVERDUE","")) | AD12: =IF(A12="","",IF(B12="","Name the system. ","")&IF(LEFT(R12,7)="Unknown","Algorithm unknown - scan or ask the vendor. ","")&IF(AND(R12<>"No",Assumptions!$C$6=""),"Set Z on Assumptions. ","")&IF(AND(R12<>"No",OR(O12="",P12="")),"Enter X and Y. ","")&IF(LEFT(T12,7)="AT RISK","Mosca: X+Y exceeds Z - migration should already be under way. ","")&IF(AND(LEFT(U12,3)="Yes",OR(AB12="",AB12="Not started")),"Harvest-now-decrypt-later exposure and migration not started. ","")&IF(AND(R12<>"No",OR(W12="",W12="To decide")),"Choose a target algorithm. ","")&IF(AND(R12<>"No",W12="Keep - not quantum-vulnerable"),"Target 'Keep' conflicts with a quantum-vulnerable algorithm. ","")&IF(LEFT(J12,5)="SHA-1","SHA-1 is deprecated - replace (NIST IR 8547). ","")&IF(AND(R12<>"No",OR(N12="Roadmap - verbal only",N12="No roadmap",N12="Not asked yet")),"Get a written PQC roadmap from the vendor. ","")&IF(AND(R12<>"No",N12=""),"Record the vendor PQC roadmap status. ","")&IF(ISNUMBER(M12),IF(M12<TODAY(),"Certificate or key expired. ",IF(M12-TODAY()<=Assumptions!$C$25,"Expires soon - use the renewal to revisit the algorithm. ","")),"")&IF(AC12="OVERDUE","Migration overdue. ","")&IF(AND(R12<>"No",Z12=""),"Assign a migration owner. ",""))
Q13: =IF(A13="","",IF(J13="","Unknown",IFERROR(INDEX('Algorithm Reference'!$C$6:$C$41,MATCH(J13,'Algorithm Reference'!$B$6:$B$41,0)),"Not in reference"))) | R13: =IF(A13="","",IF(J13="","Unknown - investigate",IFERROR(INDEX('Algorithm Reference'!$E$6:$E$41,MATCH(J13,'Algorithm Reference'!$B$6:$B$41,0)),"Unknown - investigate"))) | S13: =IF(OR(O13="",P13=""),"",O13+P13) | T13: =IF(A13="","",IF(R13="No","N/A - not quantum-vulnerable",IF(OR(O13="",P13=""),"Enter X and Y",IF(Assumptions!$C$6="","Set Z on Assumptions",IF(O13+P13>Assumptions!$C$6,"AT RISK (X+Y > Z)","Within Z (X+Y <= Z)"))))) | U13: =IF(A13="","",IF(AND(R13<>"No",OR(I13="Key establishment / encryption in transit",I13="Key wrapping / key transport",I13="Mixed or unknown",I13=""),OR(N(O13)>0,G13="Confidential",G13="Restricted")),IF(F13="Yes","Yes - internet-facing","Yes"),"No")) | V13: =IF(A13="","",IF(R13="No","Keep - not quantum-vulnerable (review key size)",IF(I13="Digital signature / authentication","ML-DSA-65 (FIPS 204); SLH-DSA (FIPS 205) if hash-based is preferred",IF(OR(I13="Key establishment / encryption in transit",I13="Key wrapping / key transport"),"ML-KEM-768 (FIPS 203); hybrid X25519MLKEM768 for TLS 1.3",IF(I13="Mixed or unknown","Both: ML-KEM (FIPS 203) for keys, ML-DSA (FIPS 204) for signatures","Pick the crypto function first"))))) | X13: =IF(A13="","",IF(R13="No",0,IF(LEFT(T13,7)="AT RISK",Assumptions!$C$13,0)+IF(LEFT(U13,3)="Yes",Assumptions!$C$14,0)+IF(F13="Yes",Assumptions!$C$15,0)+IF(G13="Restricted",Assumptions!$C$16,IF(G13="Confidential",Assumptions!$C$17,IF(G13="Internal",Assumptions!$C$18,0)))+IF(OR(N13="Roadmap - verbal only",N13="No roadmap",N13="Not asked yet",N13=""),Assumptions!$C$19,0)+IF(E13="Production",Assumptions!$C$20,0)+IF(AND(ISNUMBER(P13),N(P13)>=Assumptions!$C$22),Assumptions!$C$21,0))) | Y13: =IF(X13="","",IF(R13="No","None",IF(X13>=Assumptions!$C$23,"High",IF(X13>=Assumptions!$C$24,"Medium","Low")))) | AC13: =IF(OR(AA13="",AB13="Hybrid deployed",AB13="PQC deployed",AB13="Not required (not vulnerable)",AB13="Risk accepted"),"",IF(AA13<TODAY(),"OVERDUE","")) | AD13: =IF(A13="","",IF(B13="","Name the system. ","")&IF(LEFT(R13,7)="Unknown","Algorithm unknown - scan or ask the vendor. ","")&IF(AND(R13<>"No",Assumptions!$C$6=""),"Set Z on Assumptions. ","")&IF(AND(R13<>"No",OR(O13="",P13="")),"Enter X and Y. ","")&IF(LEFT(T13,7)="AT RISK","Mosca: X+Y exceeds Z - migration should already be under way. ","")&IF(AND(LEFT(U13,3)="Yes",OR(AB13="",AB13="Not started")),"Harvest-now-decrypt-later exposure and migration not started. ","")&IF(AND(R13<>"No",OR(W13="",W13="To decide")),"Choose a target algorithm. ","")&IF(AND(R13<>"No",W13="Keep - not quantum-vulnerable"),"Target 'Keep' conflicts with a quantum-vulnerable algorithm. ","")&IF(LEFT(J13,5)="SHA-1","SHA-1 is deprecated - replace (NIST IR 8547). ","")&IF(AND(R13<>"No",OR(N13="Roadmap - verbal only",N13="No roadmap",N13="Not asked yet")),"Get a written PQC roadmap from the vendor. ","")&IF(AND(R13<>"No",N13=""),"Record the vendor PQC roadmap status. ","")&IF(ISNUMBER(M13),IF(M13<TODAY(),"Certificate or key expired. ",IF(M13-TODAY()<=Assumptions!$C$25,"Expires soon - use the renewal to revisit the algorithm. ","")),"")&IF(AC13="OVERDUE","Migration overdue. ","")&IF(AND(R13<>"No",Z13=""),"Assign a migration owner. ",""))
Q14: =IF(A14="","",IF(J14="","Unknown",IFERROR(INDEX('Algorithm Reference'!$C$6:$C$41,MATCH(J14,'Algorithm Reference'!$B$6:$B$41,0)),"Not in reference"))) | R14: =IF(A14="","",IF(J14="","Unknown - investigate",IFERROR(INDEX('Algorithm Reference'!$E$6:$E$41,MATCH(J14,'Algorithm Reference'!$B$6:$B$41,0)),"Unknown - investigate"))) | S14: =IF(OR(O14="",P14=""),"",O14+P14) | T14: =IF(A14="","",IF(R14="No","N/A - not quantum-vulnerable",IF(OR(O14="",P14=""),"Enter X and Y",IF(Assumptions!$C$6="","Set Z on Assumptions",IF(O14+P14>Assumptions!$C$6,"AT RISK (X+Y > Z)","Within Z (X+Y <= Z)"))))) | U14: =IF(A14="","",IF(AND(R14<>"No",OR(I14="Key establishment / encryption in transit",I14="Key wrapping / key transport",I14="Mixed or unknown",I14=""),OR(N(O14)>0,G14="Confidential",G14="Restricted")),IF(F14="Yes","Yes - internet-facing","Yes"),"No")) | V14: =IF(A14="","",IF(R14="No","Keep - not quantum-vulnerable (review key size)",IF(I14="Digital signature / authentication","ML-DSA-65 (FIPS 204); SLH-DSA (FIPS 205) if hash-based is preferred",IF(OR(I14="Key establishment / encryption in transit",I14="Key wrapping / key transport"),"ML-KEM-768 (FIPS 203); hybrid X25519MLKEM768 for TLS 1.3",IF(I14="Mixed or unknown","Both: ML-KEM (FIPS 203) for keys, ML-DSA (FIPS 204) for signatures","Pick the crypto function first"))))) | X14: =IF(A14="","",IF(R14="No",0,IF(LEFT(T14,7)="AT RISK",Assumptions!$C$13,0)+IF(LEFT(U14,3)="Yes",Assumptions!$C$14,0)+IF(F14="Yes",Assumptions!$C$15,0)+IF(G14="Restricted",Assumptions!$C$16,IF(G14="Confidential",Assumptions!$C$17,IF(G14="Internal",Assumptions!$C$18,0)))+IF(OR(N14="Roadmap - verbal only",N14="No roadmap",N14="Not asked yet",N14=""),Assumptions!$C$19,0)+IF(E14="Production",Assumptions!$C$20,0)+IF(AND(ISNUMBER(P14),N(P14)>=Assumptions!$C$22),Assumptions!$C$21,0))) | Y14: =IF(X14="","",IF(R14="No","None",IF(X14>=Assumptions!$C$23,"High",IF(X14>=Assumptions!$C$24,"Medium","Low")))) | AC14: =IF(OR(AA14="",AB14="Hybrid deployed",AB14="PQC deployed",AB14="Not required (not vulnerable)",AB14="Risk accepted"),"",IF(AA14<TODAY(),"OVERDUE","")) | AD14: =IF(A14="","",IF(B14="","Name the system. ","")&IF(LEFT(R14,7)="Unknown","Algorithm unknown - scan or ask the vendor. ","")&IF(AND(R14<>"No",Assumptions!$C$6=""),"Set Z on Assumptions. ","")&IF(AND(R14<>"No",OR(O14="",P14="")),"Enter X and Y. ","")&IF(LEFT(T14,7)="AT RISK","Mosca: X+Y exceeds Z - migration should already be under way. ","")&IF(AND(LEFT(U14,3)="Yes",OR(AB14="",AB14="Not started")),"Harvest-now-decrypt-later exposure and migration not started. ","")&IF(AND(R14<>"No",OR(W14="",W14="To decide")),"Choose a target algorithm. ","")&IF(AND(R14<>"No",W14="Keep - not quantum-vulnerable"),"Target 'Keep' conflicts with a quantum-vulnerable algorithm. ","")&IF(LEFT(J14,5)="SHA-1","SHA-1 is deprecated - replace (NIST IR 8547). ","")&IF(AND(R14<>"No",OR(N14="Roadmap - verbal only",N14="No roadmap",N14="Not asked yet")),"Get a written PQC roadmap from the vendor. ","")&IF(AND(R14<>"No",N14=""),"Record the vendor PQC roadmap status. ","")&IF(ISNUMBER(M14),IF(M14<TODAY(),"Certificate or key expired. ",IF(M14-TODAY()<=Assumptions!$C$25,"Expires soon - use the renewal to revisit the algorithm. ","")),"")&IF(AC14="OVERDUE","Migration overdue. ","")&IF(AND(R14<>"No",Z14=""),"Assign a migration owner. ",""))
Q15: =IF(A15="","",IF(J15="","Unknown",IFERROR(INDEX('Algorithm Reference'!$C$6:$C$41,MATCH(J15,'Algorithm Reference'!$B$6:$B$41,0)),"Not in reference"))) | R15: =IF(A15="","",IF(J15="","Unknown - investigate",IFERROR(INDEX('Algorithm Reference'!$E$6:$E$41,MATCH(J15,'Algorithm Reference'!$B$6:$B$41,0)),"Unknown - investigate"))) | S15: =IF(OR(O15="",P15=""),"",O15+P15) | T15: =IF(A15="","",IF(R15="No","N/A - not quantum-vulnerable",IF(OR(O15="",P15=""),"Enter X and Y",IF(Assumptions!$C$6="","Set Z on Assumptions",IF(O15+P15>Assumptions!$C$6,"AT RISK (X+Y > Z)","Within Z (X+Y <= Z)"))))) | U15: =IF(A15="","",IF(AND(R15<>"No",OR(I15="Key establishment / encryption in transit",I15="Key wrapping / key transport",I15="Mixed or unknown",I15=""),OR(N(O15)>0,G15="Confidential",G15="Restricted")),IF(F15="Yes","Yes - internet-facing","Yes"),"No")) | V15: =IF(A15="","",IF(R15="No","Keep - not quantum-vulnerable (review key size)",IF(I15="Digital signature / authentication","ML-DSA-65 (FIPS 204); SLH-DSA (FIPS 205) if hash-based is preferred",IF(OR(I15="Key establishment / encryption in transit",I15="Key wrapping / key transport"),"ML-KEM-768 (FIPS 203); hybrid X25519MLKEM768 for TLS 1.3",IF(I15="Mixed or unknown","Both: ML-KEM (FIPS 203) for keys, ML-DSA (FIPS 204) for signatures","Pick the crypto function first"))))) | X15: =IF(A15="","",IF(R15="No",0,IF(LEFT(T15,7)="AT RISK",Assumptions!$C$13,0)+IF(LEFT(U15,3)="Yes",Assumptions!$C$14,0)+IF(F15="Yes",Assumptions!$C$15,0)+IF(G15="Restricted",Assumptions!$C$16,IF(G15="Confidential",Assumptions!$C$17,IF(G15="Internal",Assumptions!$C$18,0)))+IF(OR(N15="Roadmap - verbal only",N15="No roadmap",N15="Not asked yet",N15=""),Assumptions!$C$19,0)+IF(E15="Production",Assumptions!$C$20,0)+IF(AND(ISNUMBER(P15),N(P15)>=Assumptions!$C$22),Assumptions!$C$21,0))) | Y15: =IF(X15="","",IF(R15="No","None",IF(X15>=Assumptions!$C$23,"High",IF(X15>=Assumptions!$C$24,"Medium","Low")))) | AC15: =IF(OR(AA15="",AB15="Hybrid deployed",AB15="PQC deployed",AB15="Not required (not vulnerable)",AB15="Risk accepted"),"",IF(AA15<TODAY(),"OVERDUE","")) | AD15: =IF(A15="","",IF(B15="","Name the system. ","")&IF(LEFT(R15,7)="Unknown","Algorithm unknown - scan or ask the vendor. ","")&IF(AND(R15<>"No",Assumptions!$C$6=""),"Set Z on Assumptions. ","")&IF(AND(R15<>"No",OR(O15="",P15="")),"Enter X and Y. ","")&IF(LEFT(T15,7)="AT RISK","Mosca: X+Y exceeds Z - migration should already be under way. ","")&IF(AND(LEFT(U15,3)="Yes",OR(AB15="",AB15="Not started")),"Harvest-now-decrypt-later exposure and migration not started. ","")&IF(AND(R15<>"No",OR(W15="",W15="To decide")),"Choose a target algorithm. ","")&IF(AND(R15<>"No",W15="Keep - not quantum-vulnerable"),"Target 'Keep' conflicts with a quantum-vulnerable algorithm. ","")&IF(LEFT(J15,5)="SHA-1","SHA-1 is deprecated - replace (NIST IR 8547). ","")&IF(AND(R15<>"No",OR(N15="Roadmap - verbal only",N15="No roadmap",N15="Not asked yet")),"Get a written PQC roadmap from the vendor. ","")&IF(AND(R15<>"No",N15=""),"Record the vendor PQC roadmap status. ","")&IF(ISNUMBER(M15),IF(M15<TODAY(),"Certificate or key expired. ",IF(M15-TODAY()<=Assumptions!$C$25,"Expires soon - use the renewal to revisit the algorithm. ","")),"")&IF(AC15="OVERDUE","Migration overdue. ","")&IF(AND(R15<>"No",Z15=""),"Assign a migration owner. ",""))
Q16: =IF(A16="","",IF(J16="","Unknown",IFERROR(INDEX('Algorithm Reference'!$C$6:$C$41,MATCH(J16,'Algorithm Reference'!$B$6:$B$41,0)),"Not in reference"))) | R16: =IF(A16="","",IF(J16="","Unknown - investigate",IFERROR(INDEX('Algorithm Reference'!$E$6:$E$41,MATCH(J16,'Algorithm Reference'!$B$6:$B$41,0)),"Unknown - investigate"))) | S16: =IF(OR(O16="",P16=""),"",O16+P16) | T16: =IF(A16="","",IF(R16="No","N/A - not quantum-vulnerable",IF(OR(O16="",P16=""),"Enter X and Y",IF(Assumptions!$C$6="","Set Z on Assumptions",IF(O16+P16>Assumptions!$C$6,"AT RISK (X+Y > Z)","Within Z (X+Y <= Z)"))))) | U16: =IF(A16="","",IF(AND(R16<>"No",OR(I16="Key establishment / encryption in transit",I16="Key wrapping / key transport",I16="Mixed or unknown",I16=""),OR(N(O16)>0,G16="Confidential",G16="Restricted")),IF(F16="Yes","Yes - internet-facing","Yes"),"No")) | V16: =IF(A16="","",IF(R16="No","Keep - not quantum-vulnerable (review key size)",IF(I16="Digital signature / authentication","ML-DSA-65 (FIPS 204); SLH-DSA (FIPS 205) if hash-based is preferred",IF(OR(I16="Key establishment / encryption in transit",I16="Key wrapping / key transport"),"ML-KEM-768 (FIPS 203); hybrid X25519MLKEM768 for TLS 1.3",IF(I16="Mixed or unknown","Both: ML-KEM (FIPS 203) for keys, ML-DSA (FIPS 204) for signatures","Pick the crypto function first"))))) | X16: =IF(A16="","",IF(R16="No",0,IF(LEFT(T16,7)="AT RISK",Assumptions!$C$13,0)+IF(LEFT(U16,3)="Yes",Assumptions!$C$14,0)+IF(F16="Yes",Assumptions!$C$15,0)+IF(G16="Restricted",Assumptions!$C$16,IF(G16="Confidential",Assumptions!$C$17,IF(G16="Internal",Assumptions!$C$18,0)))+IF(OR(N16="Roadmap - verbal only",N16="No roadmap",N16="Not asked yet",N16=""),Assumptions!$C$19,0)+IF(E16="Production",Assumptions!$C$20,0)+IF(AND(ISNUMBER(P16),N(P16)>=Assumptions!$C$22),Assumptions!$C$21,0))) | Y16: =IF(X16="","",IF(R16="No","None",IF(X16>=Assumptions!$C$23,"High",IF(X16>=Assumptions!$C$24,"Medium","Low")))) | AC16: =IF(OR(AA16="",AB16="Hybrid deployed",AB16="PQC deployed",AB16="Not required (not vulnerable)",AB16="Risk accepted"),"",IF(AA16<TODAY(),"OVERDUE","")) | AD16: =IF(A16="","",IF(B16="","Name the system. ","")&IF(LEFT(R16,7)="Unknown","Algorithm unknown - scan or ask the vendor. ","")&IF(AND(R16<>"No",Assumptions!$C$6=""),"Set Z on Assumptions. ","")&IF(AND(R16<>"No",OR(O16="",P16="")),"Enter X and Y. ","")&IF(LEFT(T16,7)="AT RISK","Mosca: X+Y exceeds Z - migration should already be under way. ","")&IF(AND(LEFT(U16,3)="Yes",OR(AB16="",AB16="Not started")),"Harvest-now-decrypt-later exposure and migration not started. ","")&IF(AND(R16<>"No",OR(W16="",W16="To decide")),"Choose a target algorithm. ","")&IF(AND(R16<>"No",W16="Keep - not quantum-vulnerable"),"Target 'Keep' conflicts with a quantum-vulnerable algorithm. ","")&IF(LEFT(J16,5)="SHA-1","SHA-1 is deprecated - replace (NIST IR 8547). ","")&IF(AND(R16<>"No",OR(N16="Roadmap - verbal only",N16="No roadmap",N16="Not asked yet")),"Get a written PQC roadmap from the vendor. ","")&IF(AND(R16<>"No",N16=""),"Record the vendor PQC roadmap status. ","")&IF(ISNUMBER(M16),IF(M16<TODAY(),"Certificate or key expired. ",IF(M16-TODAY()<=Assumptions!$C$25,"Expires soon - use the renewal to revisit the algorithm. ","")),"")&IF(AC16="OVERDUE","Migration overdue. ","")&IF(AND(R16<>"No",Z16=""),"Assign a migration owner. ",""))
Q17: =IF(A17="","",IF(J17="","Unknown",IFERROR(INDEX('Algorithm Reference'!$C$6:$C$41,MATCH(J17,'Algorithm Reference'!$B$6:$B$41,0)),"Not in reference"))) | R17: =IF(A17="","",IF(J17="","Unknown - investigate",IFERROR(INDEX('Algorithm Reference'!$E$6:$E$41,MATCH(J17,'Algorithm Reference'!$B$6:$B$41,0)),"Unknown - investigate"))) | S17: =IF(OR(O17="",P17=""),"",O17+P17) | T17: =IF(A17="","",IF(R17="No","N/A - not quantum-vulnerable",IF(OR(O17="",P17=""),"Enter X and Y",IF(Assumptions!$C$6="","Set Z on Assumptions",IF(O17+P17>Assumptions!$C$6,"AT RISK (X+Y > Z)","Within Z (X+Y <= Z)"))))) | U17: =IF(A17="","",IF(AND(R17<>"No",OR(I17="Key establishment / encryption in transit",I17="Key wrapping / key transport",I17="Mixed or unknown",I17=""),OR(N(O17)>0,G17="Confidential",G17="Restricted")),IF(F17="Yes","Yes - internet-facing","Yes"),"No")) | V17: =IF(A17="","",IF(R17="No","Keep - not quantum-vulnerable (review key size)",IF(I17="Digital signature / authentication","ML-DSA-65 (FIPS 204); SLH-DSA (FIPS 205) if hash-based is preferred",IF(OR(I17="Key establishment / encryption in transit",I17="Key wrapping / key transport"),"ML-KEM-768 (FIPS 203); hybrid X25519MLKEM768 for TLS 1.3",IF(I17="Mixed or unknown","Both: ML-KEM (FIPS 203) for keys, ML-DSA (FIPS 204) for signatures","Pick the crypto function first"))))) | X17: =IF(A17="","",IF(R17="No",0,IF(LEFT(T17,7)="AT RISK",Assumptions!$C$13,0)+IF(LEFT(U17,3)="Yes",Assumptions!$C$14,0)+IF(F17="Yes",Assumptions!$C$15,0)+IF(G17="Restricted",Assumptions!$C$16,IF(G17="Confidential",Assumptions!$C$17,IF(G17="Internal",Assumptions!$C$18,0)))+IF(OR(N17="Roadmap - verbal only",N17="No roadmap",N17="Not asked yet",N17=""),Assumptions!$C$19,0)+IF(E17="Production",Assumptions!$C$20,0)+IF(AND(ISNUMBER(P17),N(P17)>=Assumptions!$C$22),Assumptions!$C$21,0))) | Y17: =IF(X17="","",IF(R17="No","None",IF(X17>=Assumptions!$C$23,"High",IF(X17>=Assumptions!$C$24,"Medium","Low")))) | AC17: =IF(OR(AA17="",AB17="Hybrid deployed",AB17="PQC deployed",AB17="Not required (not vulnerable)",AB17="Risk accepted"),"",IF(AA17<TODAY(),"OVERDUE","")) | AD17: =IF(A17="","",IF(B17="","Name the system. ","")&IF(LEFT(R17,7)="Unknown","Algorithm unknown - scan or ask the vendor. ","")&IF(AND(R17<>"No",Assumptions!$C$6=""),"Set Z on Assumptions. ","")&IF(AND(R17<>"No",OR(O17="",P17="")),"Enter X and Y. ","")&IF(LEFT(T17,7)="AT RISK","Mosca: X+Y exceeds Z - migration should already be under way. ","")&IF(AND(LEFT(U17,3)="Yes",OR(AB17="",AB17="Not started")),"Harvest-now-decrypt-later exposure and migration not started. ","")&IF(AND(R17<>"No",OR(W17="",W17="To decide")),"Choose a target algorithm. ","")&IF(AND(R17<>"No",W17="Keep - not quantum-vulnerable"),"Target 'Keep' conflicts with a quantum-vulnerable algorithm. ","")&IF(LEFT(J17,5)="SHA-1","SHA-1 is deprecated - replace (NIST IR 8547). ","")&IF(AND(R17<>"No",OR(N17="Roadmap - verbal only",N17="No roadmap",N17="Not asked yet")),"Get a written PQC roadmap from the vendor. ","")&IF(AND(R17<>"No",N17=""),"Record the vendor PQC roadmap status. ","")&IF(ISNUMBER(M17),IF(M17<TODAY(),"Certificate or key expired. ",IF(M17-TODAY()<=Assumptions!$C$25,"Expires soon - use the renewal to revisit the algorithm. ","")),"")&IF(AC17="OVERDUE","Migration overdue. ","")&IF(AND(R17<>"No",Z17=""),"Assign a migration owner. ",""))
Q18: =IF(A18="","",IF(J18="","Unknown",IFERROR(INDEX('Algorithm Reference'!$C$6:$C$41,MATCH(J18,'Algorithm Reference'!$B$6:$B$41,0)),"Not in reference"))) | R18: =IF(A18="","",IF(J18="","Unknown - investigate",IFERROR(INDEX('Algorithm Reference'!$E$6:$E$41,MATCH(J18,'Algorithm Reference'!$B$6:$B$41,0)),"Unknown - investigate"))) | S18: =IF(OR(O18="",P18=""),"",O18+P18) | T18: =IF(A18="","",IF(R18="No","N/A - not quantum-vulnerable",IF(OR(O18="",P18=""),"Enter X and Y",IF(Assumptions!$C$6="","Set Z on Assumptions",IF(O18+P18>Assumptions!$C$6,"AT RISK (X+Y > Z)","Within Z (X+Y <= Z)"))))) | U18: =IF(A18="","",IF(AND(R18<>"No",OR(I18="Key establishment / encryption in transit",I18="Key wrapping / key transport",I18="Mixed or unknown",I18=""),OR(N(O18)>0,G18="Confidential",G18="Restricted")),IF(F18="Yes","Yes - internet-facing","Yes"),"No")) | V18: =IF(A18="","",IF(R18="No","Keep - not quantum-vulnerable (review key size)",IF(I18="Digital signature / authentication","ML-DSA-65 (FIPS 204); SLH-DSA (FIPS 205) if hash-based is preferred",IF(OR(I18="Key establishment / encryption in transit",I18="Key wrapping / key transport"),"ML-KEM-768 (FIPS 203); hybrid X25519MLKEM768 for TLS 1.3",IF(I18="Mixed or unknown","Both: ML-KEM (FIPS 203) for keys, ML-DSA (FIPS 204) for signatures","Pick the crypto function first"))))) | X18: =IF(A18="","",IF(R18="No",0,IF(LEFT(T18,7)="AT RISK",Assumptions!$C$13,0)+IF(LEFT(U18,3)="Yes",Assumptions!$C$14,0)+IF(F18="Yes",Assumptions!$C$15,0)+IF(G18="Restricted",Assumptions!$C$16,IF(G18="Confidential",Assumptions!$C$17,IF(G18="Internal",Assumptions!$C$18,0)))+IF(OR(N18="Roadmap - verbal only",N18="No roadmap",N18="Not asked yet",N18=""),Assumptions!$C$19,0)+IF(E18="Production",Assumptions!$C$20,0)+IF(AND(ISNUMBER(P18),N(P18)>=Assumptions!$C$22),Assumptions!$C$21,0))) | Y18: =IF(X18="","",IF(R18="No","None",IF(X18>=Assumptions!$C$23,"High",IF(X18>=Assumptions!$C$24,"Medium","Low")))) | AC18: =IF(OR(AA18="",AB18="Hybrid deployed",AB18="PQC deployed",AB18="Not required (not vulnerable)",AB18="Risk accepted"),"",IF(AA18<TODAY(),"OVERDUE","")) | AD18: =IF(A18="","",IF(B18="","Name the system. ","")&IF(LEFT(R18,7)="Unknown","Algorithm unknown - scan or ask the vendor. ","")&IF(AND(R18<>"No",Assumptions!$C$6=""),"Set Z on Assumptions. ","")&IF(AND(R18<>"No",OR(O18="",P18="")),"Enter X and Y. ","")&IF(LEFT(T18,7)="AT RISK","Mosca: X+Y exceeds Z - migration should already be under way. ","")&IF(AND(LEFT(U18,3)="Yes",OR(AB18="",AB18="Not started")),"Harvest-now-decrypt-later exposure and migration not started. ","")&IF(AND(R18<>"No",OR(W18="",W18="To decide")),"Choose a target algorithm. ","")&IF(AND(R18<>"No",W18="Keep - not quantum-vulnerable"),"Target 'Keep' conflicts with a quantum-vulnerable algorithm. ","")&IF(LEFT(J18,5)="SHA-1","SHA-1 is deprecated - replace (NIST IR 8547). ","")&IF(AND(R18<>"No",OR(N18="Roadmap - verbal only",N18="No roadmap",N18="Not asked yet")),"Get a written PQC roadmap from the vendor. ","")&IF(AND(R18<>"No",N18=""),"Record the vendor PQC roadmap status. ","")&IF(ISNUMBER(M18),IF(M18<TODAY(),"Certificate or key expired. ",IF(M18-TODAY()<=Assumptions!$C$25,"Expires soon - use the renewal to revisit the algorithm. ","")),"")&IF(AC18="OVERDUE","Migration overdue. ","")&IF(AND(R18<>"No",Z18=""),"Assign a migration owner. ",""))
... Q205: =IF(A205="","",IF(J205="","Unknown",IFERROR(INDEX('Algorithm Reference'!$C$6:$C$41,MATCH(J205,'Algorithm Reference'!$B$6:$B$41,0)),"Not in reference"))) | R205: =IF(A205="","",IF(J205="","Unknown - investigate",IFERROR(INDEX('Algorithm Reference'!$E$6:$E$41,MATCH(J205,'Algorithm Reference'!$B$6:$B$41,0)),"Unknown - investigate"))) | S205: =IF(OR(O205="",P205=""),"",O205+P205) | T205: =IF(A205="","",IF(R205="No","N/A - not quantum-vulnerable",IF(OR(O205="",P205=""),"Enter X and Y",IF(Assumptions!$C$6="","Set Z on Assumptions",IF(O205+P205>Assumptions!$C$6,"AT RISK (X+Y > Z)","Within Z (X+Y <= Z)"))))) | U205: =IF(A205="","",IF(AND(R205<>"No",OR(I205="Key establishment / encryption in transit",I205="Key wrapping / key transport",I205="Mixed or unknown",I205=""),OR(N(O205)>0,G205="Confidential",G205="Restricted")),IF(F205="Yes","Yes - internet-facing","Yes"),"No")) | V205: =IF(A205="","",IF(R205="No","Keep - not quantum-vulnerable (review key size)",IF(I205="Digital signature / authentication","ML-DSA-65 (FIPS 204); SLH-DSA (FIPS 205) if hash-based is preferred",IF(OR(I205="Key establishment / encryption in transit",I205="Key wrapping / key transport"),"ML-KEM-768 (FIPS 203); hybrid X25519MLKEM768 for TLS 1.3",IF(I205="Mixed or unknown","Both: ML-KEM (FIPS 203) for keys, ML-DSA (FIPS 204) for signatures","Pick the crypto function first"))))) | X205: =IF(A205="","",IF(R205="No",0,IF(LEFT(T205,7)="AT RISK",Assumptions!$C$13,0)+IF(LEFT(U205,3)="Yes",Assumptions!$C$14,0)+IF(F205="Yes",Assumptions!$C$15,0)+IF(G205="Restricted",Assumptions!$C$16,IF(G205="Confidential",Assumptions!$C$17,IF(G205="Internal",Assumptions!$C$18,0)))+IF(OR(N205="Roadmap - verbal only",N205="No roadmap",N205="Not asked yet",N205=""),Assumptions!$C$19,0)+IF(E205="Production",Assumptions!$C$20,0)+IF(AND(ISNUMBER(P205),N(P205)>=Assumptions!$C$22),Assumptions!$C$21,0))) | Y205: =IF(X205="","",IF(R205="No","None",IF(X205>=Assumptions!$C$23,"High",IF(X205>=Assumptions!$C$24,"Medium","Low")))) | AC205: =IF(OR(AA205="",AB205="Hybrid deployed",AB205="PQC deployed",AB205="Not required (not vulnerable)",AB205="Risk accepted"),"",IF(AA205<TODAY(),"OVERDUE","")) | AD205: =IF(A205="","",IF(B205="","Name the system. ","")&IF(LEFT(R205,7)="Unknown","Algorithm unknown - scan or ask the vendor. ","")&IF(AND(R205<>"No",Assumptions!$C$6=""),"Set Z on Assumptions. ","")&IF(AND(R205<>"No",OR(O205="",P205="")),"Enter X and Y. ","")&IF(LEFT(T205,7)="AT RISK","Mosca: X+Y exceeds Z - migration should already be under way. ","")&IF(AND(LEFT(U205,3)="Yes",OR(AB205="",AB205="Not started")),"Harvest-now-decrypt-later exposure and migration not started. ","")&IF(AND(R205<>"No",OR(W205="",W205="To decide")),"Choose a target algorithm. ","")&IF(AND(R205<>"No",W205="Keep - not quantum-vulnerable"),"Target 'Keep' conflicts with a quantum-vulnerable algorithm. ","")&IF(LEFT(J205,5)="SHA-1","SHA-1 is deprecated - replace (NIST IR 8547). ","")&IF(AND(R205<>"No",OR(N205="Roadmap - verbal only",N205="No roadmap",N205="Not asked yet")),"Get a written PQC roadmap from the vendor. ","")&IF(AND(R205<>"No",N205=""),"Record the vendor PQC roadmap status. ","")&IF(ISNUMBER(M205),IF(M205<TODAY(),"Certificate or key expired. ",IF(M205-TODAY()<=Assumptions!$C$25,"Expires soon - use the renewal to revisit the algorithm. ","")),"")&IF(AC205="OVERDUE","Migration overdue. ","")&IF(AND(R205<>"No",Z205=""),"Assign a migration owner. ",""))

Sheet Vendor Tracker
B1: Vendor PQC Tracker
B2: By John Bommeraveni Joseph | linkedin.com/in/john-bj | Free every weekday: GRC Made Simple Daily
A5: Vendor ID | B5: Vendor | C5: Product / service | D5: Inventory IDs that depend on it | E5: Crypto the vendor controls (protocols, algorithms, keys) | F5: PQC support today | G5: Roadmap date the vendor gave | H5: Roadmap date in writing? | I5: Evidence (document, link, ticket) | J5: Date last asked | K5: Next follow-up date | L5: Owner | M5: Status | N5: Follow-up overdue? | O5: Flags
A6: V-001 | B6: Example load balancer vendor | C6: Application delivery controller (TLS termination) | D6: INV-001 | E6: TLS key exchange and server certificates | F6: Hybrid available now | G6: 46477 | H6: Yes | I6: Vendor PQC statement saved to evidence folder | J6: 46296 | K6: 46357 | L6: Third-Party Risk Lead | M6: Open | N6: =IF(OR(K6="",M6="Closed"),"",IF(K6<TODAY(),"OVERDUE","")) | O6: =IF(A6="","",IF(AND(H6<>"Yes",F6<>"PQC available now",F6<>"Hybrid available now"),"No written PQC roadmap - ask for a dated commitment. ","")&IF(AND(ISNUMBER(G6),F6<>"PQC available now"),IF(G6<TODAY(),"Roadmap date has passed - re-check delivery. ",""),"")&IF(AND(H6="Yes",I6=""),"Record where the written evidence is kept. ","")&IF(AND(F6="Hybrid available now",H6<>"Yes"),"Hybrid only - ask for the pure-PQC date. ","")&IF(OR(F6="Unknown",F6=""),"PQC support unknown. ","")&IF(N6="OVERDUE","Follow-up overdue. ","")&IF(AND(M6<>"Closed",K6=""),"Set a follow-up date. ",""))
N7: =IF(OR(K7="",M7="Closed"),"",IF(K7<TODAY(),"OVERDUE","")) | O7: =IF(A7="","",IF(AND(H7<>"Yes",F7<>"PQC available now",F7<>"Hybrid available now"),"No written PQC roadmap - ask for a dated commitment. ","")&IF(AND(ISNUMBER(G7),F7<>"PQC available now"),IF(G7<TODAY(),"Roadmap date has passed - re-check delivery. ",""),"")&IF(AND(H7="Yes",I7=""),"Record where the written evidence is kept. ","")&IF(AND(F7="Hybrid available now",H7<>"Yes"),"Hybrid only - ask for the pure-PQC date. ","")&IF(OR(F7="Unknown",F7=""),"PQC support unknown. ","")&IF(N7="OVERDUE","Follow-up overdue. ","")&IF(AND(M7<>"Closed",K7=""),"Set a follow-up date. ",""))
N8: =IF(OR(K8="",M8="Closed"),"",IF(K8<TODAY(),"OVERDUE","")) | O8: =IF(A8="","",IF(AND(H8<>"Yes",F8<>"PQC available now",F8<>"Hybrid available now"),"No written PQC roadmap - ask for a dated commitment. ","")&IF(AND(ISNUMBER(G8),F8<>"PQC available now"),IF(G8<TODAY(),"Roadmap date has passed - re-check delivery. ",""),"")&IF(AND(H8="Yes",I8=""),"Record where the written evidence is kept. ","")&IF(AND(F8="Hybrid available now",H8<>"Yes"),"Hybrid only - ask for the pure-PQC date. ","")&IF(OR(F8="Unknown",F8=""),"PQC support unknown. ","")&IF(N8="OVERDUE","Follow-up overdue. ","")&IF(AND(M8<>"Closed",K8=""),"Set a follow-up date. ",""))
N9: =IF(OR(K9="",M9="Closed"),"",IF(K9<TODAY(),"OVERDUE","")) | O9: =IF(A9="","",IF(AND(H9<>"Yes",F9<>"PQC available now",F9<>"Hybrid available now"),"No written PQC roadmap - ask for a dated commitment. ","")&IF(AND(ISNUMBER(G9),F9<>"PQC available now"),IF(G9<TODAY(),"Roadmap date has passed - re-check delivery. ",""),"")&IF(AND(H9="Yes",I9=""),"Record where the written evidence is kept. ","")&IF(AND(F9="Hybrid available now",H9<>"Yes"),"Hybrid only - ask for the pure-PQC date. ","")&IF(OR(F9="Unknown",F9=""),"PQC support unknown. ","")&IF(N9="OVERDUE","Follow-up overdue. ","")&IF(AND(M9<>"Closed",K9=""),"Set a follow-up date. ",""))
